Workbook

Sheet Lisez_moi
A1: Base de données e-fuels liquides — Sherpa Engineering (prototype Maroc)
A2: Décarbonation énergétique du Maroc : PV, éolien, stockage, dessalement, électrolyse, carburants de synthèse — module e-fuels
A4: Élément | B4: Description
A5: Objet | B5: Base condensée sur les carburants électro-synthétiques liquides (e-kérosène, e-diesel, e-méthanol, e-DME, e-essence, e-ammoniac) pour aider à la décision d'investissement d'une entreprise au Maroc.
A6: Source principale [ART] | B6: Colelli L., Dell'Aversano S., Bassano C., Vanga G., Gallucci K., Vilardi G. (2026). Liquid e-fuels for a sustainable future: a comprehensive review of production, regulation, and technological innovation. Energy Conversion and Management. doi:10.1016/j.enconman.2025.120529
A7: [HYP] | B7: Hypothèse Sherpa / connaissance générale, NON issue de l'article. Cellules jaunes. À valider avec des données Maroc (devis, PPA, mesures de site) avant toute décision.
A8: [CALC] | B8: Valeur calculée par formule dans ce classeur (recalcule si les entrées changent).
A9: Code couleur | B9: Texte bleu = entrée modifiable · texte noir = formule ou donnée de référence · texte vert = lien vers une autre feuille · fond jaune = hypothèse clé à valider.
A10: Avertissement | B10: Le calculateur est un modèle simplifié de pré-faisabilité (±30–50 %). Il ne remplace ni une étude de faisabilité ni un devis fournisseur. Les coûts de l'article proviennent de sources hétérogènes (hypothèses ACV et limites de système différentes).
A11: Mise à jour | B11: Les chiffres de l'article datent de 2024-2025. Les coûts d'électrolyseurs, de captage CO2 et la réglementation évoluent vite : revérifier avant usage.
A13: Index des feuilles
A14: Feuille | B14: Contenu
A15: Synthese_cles | B15: 27 messages clés chiffrés de l'article.
A16: Voies_procedes | B16: Réactions, T/P, catalyseurs, réacteurs : électrolyse, FT, méthanol, DME, MTG, Haber–Bosch.
A17: Produits | B17: Fiche des 6 e-fuels : coûts, CAPEX, rendements, usages.
A18: Electrolyse | B18: Table 4 de l'article (AEL/PEM/SOEC) + paramètres numériques pour les formules.
A19: Capture_CO2 | B19: Coûts, TRL, technologies de captage, énergie DAC.
A20: Azote_H2_Eau_Elec | B20: Besoins en N2, H2, eau et électricité.
A21: Projets_35 | B21: 35 projets mondiaux (Table 5) + statistiques par formules.
A22: LCOE_pays | B22: Hypothèses LCOE par pays (Table 6) et comparaison avec le Maroc [HYP].
A23: Politiques_regl | B23: UE, USA, Australie, Chine, ASTM/SAF, certification.
A24: Barrieres_Risques | B24: Barrières, risques et mesures d'atténuation.
A25: Maroc_Contexte | B25: Contexte marocain [HYP] avec niveau de confiance et données à collecter.
... A32: Sources | B32: Références clés de l'article.

Sheet Synthese_cles
A1: Synthèse — messages clés de l'article
A2: Chaque ligne renvoie à une section de l'article [ART].
A4: Thème | B4: Message clé | C4: Chiffre clé | D4: Source
A5: Contexte | B5: Les combustibles fossiles représentaient près de 80 % de l'énergie primaire mondiale en 2023. | C5: ~80 % | D5: [ART] §1
A6: Contexte | B6: Les e-fuels (H2 vert + CO2/N2 capté + électricité renouvelable) sont des carburants « drop-in » pour aviation, maritime et poids lourds, secteurs difficiles à électrifier. | C6: 6 e-fuels liquides | D6: [ART] §1, §4
A7: Voies | B7: Trois procédés industriels : Fischer–Tropsch (e-kérosène, e-diesel, e-essence via RWGS), méthanol (e-méthanol, e-DME, e-essence via MTG) et Haber–Bosch (e-ammoniac). | C7: 3 procédés | D7: [ART] §4
A8: Performance | B8: Rendements de procédé revus : 59 % à 89 % (attention : rendement de la conversion, pas du chaînage électricité→carburant). | C8: 59–89 % | D8: [ART] résumé
A9: Coût actuel | B9: Coût de production du kérosène/méthanol de synthèse : 1 200 à 4 200 €/t selon voie et maturité. | C9: 1 200–4 200 €/t | D9: [ART] résumé
A10: Coût e-kérosène | B10: Aujourd'hui : 3 062–4 100 €/t (voie méthanol) et 3 245–4 215 €/t (voie FT). 2050 : 1 206–1 719 €/t (méthanol) et 1 352–1 841 €/t (FT). Rendement 59–78 %. | C10: 3 062–4 215 €/t → 1 206–1 841 €/t | D10: [ART] §4.4.1 (réf. [247])
A11: Coût e-diesel | B11: Prix de vente minimal estimé 3 400–3 520 €/t ; rendement 59–78 %. | C11: 3 400–3 520 €/t | D11: [ART] §4.4.2
A12: Coût e-méthanol | B12: Prix moyen ~3 208 €/t, coût total de production 3 409 €/t ; CAPEX 300–1 200 €/kW_fuel (proche terme) → 200–650 (long terme) ; rendement 69–89 %. | C12: 3 208–3 409 €/t | D12: [ART] §4.4.3
A13: Coût e-essence | B13: Prix de vente minimal 3,24 USD/L ; CAPEX MTG 600 €/kW_fuel → 250–370 ; rendement ~86 %. | C13: 3,24 USD/L | D13: [ART] §4.4.5
A14: Coût e-ammoniac | B14: CAPEX 1 300–2 200 €/kW_fuel → 580–1 100 €/kW_fuel (long terme) ; rendement 61–79 %. | C14: 1 300–2 200 €/kW | D14: [ART] §4.4.6
A15: Hydrogène | B15: Electrolyse : 45–73 kWh/kg H2 ; coût H2 3–6 €/kg selon électrolyseur et prix de l'électricité. | C15: 45–73 kWh/kg | D15: [ART] §3.5, §5
... A31: Pour le Maroc | B31: Ressource PV/éolien et position logistique favorables (hypothèse Sherpa) ; l'article cite l'Afrique du Nord comme région potentiellement à coûts plus bas. | C31: voir Maroc_Contexte | D31: [ART] §3.5 + [HYP]

Sheet Voies_procedes
A1: Voies de production et procédés
A2: Conditions opératoires, catalyseurs et réacteurs (article §3.3, §4).
A4: Voie | B4: Étape | C4: Équation | D4: ΔH298 (kJ/mol) | E4: T (°C) | F4: P (bar) | G4: Catalyseurs | H4: Réacteur | I4: Produits | J4: Remarques | K4: Source
A5: Électrolyse | B5: Production de H2 | C5: H2O ⇆ 0,5 O2 + H2 | D5: +285,8 (ΔH, éq. 1) | E5: AEL 60–90 ; PEM 50–80 ; SOEC 700–900 | F5: AEL 10–30 ; PEM 20–50 ; SOEC 1–15 | G5: AEL : KOH/NaOH ; PEM : Pt/Ir ; SOEC : céramiques | H5: Stacks AEL/PEM/SOEC | I5: H2 vert + O2 | J5: PEM flexible et réactif ; SOEC permet la co-électrolyse CO2+vapeur → syngas. | K5: [ART] §3.3
A6: Fischer–Tropsch indirect | B6: 1) RWGS | C6: CO2 + H2 ⇆ CO + H2O | D6: +41 | E6: n.d. | F6: n.d. | G6: Ni, Fe ou Cu | H6: — | I6: CO + H2O | J6: Étape préalable : CO2 → CO. | K6: [ART] §4.1 éq. 2
A7: Fischer–Tropsch indirect | B7: 2) Synthèse FT | C7: n CO + 2n H2 ⇆ (−CH2−)n + n H2O | D7: −166 | E7: 200–350 | F7: 20–30 (plus possible) | G7: Co (préféré, longues chaînes) ou Fe | H7: Slurry bubble column (optimal grande échelle) ; lit fixe ; lit fluidisé | I7: Hydrocarbures linéaires → hydrocraquage/reforming/hydrotraitement → kérosène, diesel, essence | J7: Très exothermique : contrôle de température critique. | K7: [ART] §4.1 éq. 3
A8: Fischer–Tropsch direct | B8: Une étape | C8: CO2 + H2 → hydrocarbures | D8: n.d. | E8: n.d. | F8: n.d. | G8: Fe complexes (RWGS + FT dans un réacteur) | H8: — | I8: Hydrocarbures | J8: Supprime l'étape RWGS mais catalyseurs plus complexes. | K8: [ART] §4.1
A9: Méthanol | B9: Synthèse | C9: CO + 2 H2 ⇆ CH3OH | D9: −90,77 | E9: 250–300 | F9: 50–100 | G9: CuO–ZnO–Al2O3 (CZA) ; CZZA (plus résistant à la vapeur) | H9: Multitubulaire lit fixe avec refroidissement inter-étages (référence industrielle) | I9: e-méthanol | J9: Éq. 4. | K9: [ART] §4.2
A10: Méthanol | B10: RWGS (côté méthanol) | C10: CO2 + H2 ⇆ CO + H2O | D10: +41,21 | E10: 250–300 | F10: 50–100 | G10: CZA/CZZA | H10: — | I10: — | J10: Éq. 5. | K10: [ART] §4.2
A11: Méthanol | B11: Hydrogénation CO2 | C11: CO2 + 3 H2 ⇆ CH3OH + H2O | D11: −49,16 | E11: 250–300 | F11: 50–100 | G11: CZA/CZZA | H11: Multitubulaire lit fixe | I11: e-méthanol | J11: Éq. 6 (réaction globale utile). | K11: [ART] §4.2
A12: Méthanol → liquides (MtL) indirect | B12: 2 étapes | C12: Méthanol → hydrocarbures (catalyseur acide) | D12: n.d. | E12: >300 (conversion oléfines) | F12: n.d. | G12: Métallique puis zéolithe ZSM-5 | H12: — | I12: Essence / kérosène / diesel | J12: Étapes additionnelles : oléfines, oligomérisation. | K12: [ART] §4.2
A13: Méthanol → liquides (MtL) direct | B13: 1 étape | C13: CO2 + H2 → hydrocarbures | D13: n.d. | E13: n.d. | F13: n.d. | G13: SAPO-34 + métaux nobles/transition | H13: — | I13: Hydrocarbures | J13: Stade précoce ; catalyseurs Cu incompatibles avec zéolithes >300 °C (sauf DME). | K13: [ART] §4.2
A14: DME | B14: Synthèse directe | C14: 2 CO2 + 6 H2 → CH3OCH3 + 3 H2O (stœchiométrie) | D14: n.d. | E14: 250–350 | F14: 30–70 | G14: Bifonctionnels : Cu (hydrogénation) + alumine/zéolithe (déshydratation) | H14: Lit fixe, fluidisé, slurry (fluidisé/slurry préférés grande échelle) | I14: e-DME | J14: Voie directe préférée à la déshydratation du méthanol (moins d'énergie, moins de complexité). | K14: [ART] §4.4.4
A15: MTG (méthanol → essence) | B15: Conversion catalytique | C15: Méthanol → alcanes + cycloalcanes | D15: n.d. | E15: 300–400 | F15: 10–30 | G15: Zéolithe ZSM-5 (sélectivité, résistance au coke) | H15: Lit fixe ; lit fluidisé grande échelle | I15: e-essence | J15: Désactivation par coke/gaz légers. | K15: [ART] §4.4.5
A16: Haber–Bosch | B16: Synthèse NH3 | C16: N2 + 3 H2 ⇆ 2 NH3 | D16: −92,28 | E16: 400–500 | F16: 150–300 | G16: Fe promu K/Al (standard) ; Ru (plus efficace, plus coûteux) | H16: Lit fixe adiabatique multi-lits avec refroidissement inter-étages | I16: e-ammoniac | J16: N2 par distillation cryogénique (ASU) ; O2 résiduel désactive Fe : PSA/membranes plutôt pour voies électrochimiques bas TRL. | K16: [ART] §4.3, §3.1

Sheet Produits
A1: Fiches produits — e-fuels liquides
A2: Coûts en €/t (fourchettes de l'article). Min/max numériques utilisés pour la comparaison avec le Calculateur.
A4: Produit | B4: Voie | C4: Usage cible | D4: Compatibilité | E4: Coût (texte) | F4: Coût min (€/t) | G4: Coût max (€/t) | H4: CAPEX proche terme | I4: CAPEX long terme | J4: Rendement procédé | K4: Notes | L4: Source
A5: e-kérosène | B5: FT (RWGS+FT) ou méthanol+MtL | C5: Aviation long-courrier | D5: Substitut direct du Jet A-1 ; infrastructure existante | E5: Actuel 3 062–4 215 €/t ; 2050 : 1 206–1 841 €/t | F5: 3062 | G5: 4215 | H5: n.d. dans l'article | I5: n.d. | J5: 59–78 % | K5: Voie FT plus flexible ; voie méthanol : désactivation catalyseur. Coût de 460–1 435 €/bbl (indirect) et 752–2 364 €/bbl (direct) selon scénarios (réf. [230]). | L5: [ART] §4.4.1
A6: e-diesel | B6: FT ou méthanol | C6: Transport routier/lourd | D6: Drop-in ; moteurs et chaîne logistique existants | E6: 3 400–3 520 €/t (prix de vente minimal) | F6: 3400 | G6: 3520 | H6: n.d. | I6: n.d. | J6: 59–78 % | K6: Réductions de coût dépendent de l'électrolyse, du captage CO2 et du réacteur. | L6: [ART] §4.4.2
A7: e-méthanol | B7: Hydrogénation du CO2 (CZA) | C7: Maritime, chimie, piles à combustible, moteurs modifiés | D7: Moteurs/infra à adapter ; carburant ou intermédiaire | E7: Prix moyen 3 208 €/t ; coût total 3 409 €/t | F7: 3208 | G7: 3409 | H7: 300–1 200 €/kW_fuel | I7: 200–650 €/kW_fuel | J7: 69–89 % | K7: Voie la plus mature (George Olah, TRL 8). | L7: [ART] §4.4.3
A8: e-DME | B8: Synthèse directe CO2+H2 ou déshydratation méthanol | C8: Remplacement du diesel (cétane élevé) | D8: Moteurs diesel avec modifications minimes ; moins de particules/NOx/SOx | E8: n.d. dans l'article | H8: 300–1 200 €/kW_fuel | I8: 200–650 €/kW_fuel | J8: 69–89 % | K8: Un seul projet DME dans Table 5 (H2V Chile, TRL 5–6). | L8: [ART] §4.4.4
A9: e-essence | B9: Méthanol → essence (MTG, ZSM-5) | C9: Véhicules essence existants | D9: Drop-in ; stations/stockage existants | E9: 3,24 USD/L (prix de vente minimal) | H9: 600 €/kW_fuel | I9: 250–370 €/kW_fuel | J9: ~86 % | K9: Projets : Haru Oni (Chili), Texas HIF (630 kt/an). | L9: [ART] §4.4.5
A10: e-ammoniac | B10: Haber–Bosch (H2 vert + N2 ASU) | C10: Engrais, maritime, stockage H2, production d'électricité | D10: Besoin de nouvelles règles de sécurité/manutention ; pas de CO2 | E10: n.d. (CAPEX uniquement) | H10: 1 300–2 200 €/kW_fuel | I10: 580–1 100 €/kW_fuel | J10: 61–79 % | K10: Projets de grande échelle : MadoquaPower2X (500 kt/an). | L10: [ART] §4.4.6
A12: Conversion indicative e-essence : 3,24 USD/L → €/t [CALC]
A13: Prix (USD/L) | B13: 3.24
A14: Densité essence (kg/L) [HYP] | B14: 0.745
A15: Taux €/USD [HYP] | B15: 0.92
A16: Coût (€/t) | B16: =B13/B14*1000*B15 -> 4001.0738
A17: Les coûts de l'e-DME et de l'e-ammoniac ne sont pas chiffrés en €/t dans l'article (CAPEX uniquement).

Sheet Electrolyse
A1: Électrolyseurs — Table 4 de l'article
A2: Sources : [ART] Table 4 (réfs [184]–[188]).
A4: Paramètre | B4: AEL | C4: PEM | D4: SOEC | E4: Catégorie
A5: Température cellule (°C) | B5: 60–90 | C5: 50–80 | D5: 700–900 | E5: Paramètres opératoires
A6: Pression typique (bar) | B6: 10–30 | C6: 20–50 | D6: 1–15 | E6: Paramètres opératoires
A7: Densité de courant (A/cm²) | B7: 0,25–0,45 | C7: 1,0–2,0 | D7: 0,3–1,0 | E7: Paramètres opératoires
A8: Charge nominale (%) | B8: 20–100 | C8: 0–100 | D8: −100/+100 | E8: Flexibilité
A9: Démarrage à froid | B9: 12 h | C9: 5–10 min | D9: − | E9: Flexibilité
A10: Démarrage à chaud | B10: 1–5 min | C10: < 10 s | D10: 15 min | E10: Flexibilité
A11: TRL | B11: 8–9 | C11: 8–9 | D11: 6–7 | E11: Maturité (* TRL inférieur = PEM/AEL avec médiateur redox)
A12: Rendement stack nominal (PCI) | B12: 63–71 % | C12: 60–68 % | D12: 100 % | E12: Efficacité (SOEC 100 % = valeur du tableau, à interpréter)
A13: Consommation stack (kWh/Nm³) | B13: 4,2–4,8 | C13: 4,4–5,0 | D13: 3 | E13: Efficacité
A14: Rendement système nominal (PCI) | B14: 51–60 % | C14: 46–60 % | D14: 76–81 % | E14: Efficacité
A15: Consommation système (kWh/Nm³) | B15: 5,0–5,9 | C15: 5,0–5,6 | D15: 3,7–3,9 | E15: Efficacité
... A21: Coût opératoire (% du coût/an) | B21: 2–3 | C21: 3–5 | D21: − | E21: Économie
A23: Paramètres numériques utilisés par les formules (min / max)
A24: Technologie | B24: CAPEX min (€/kW) | C24: CAPEX max (€/kW) | D24: kWh/Nm³ min | E24: kWh/Nm³ max | F24: OPEX min (%/an) | G24: OPEX max (%/an) | H24: Vie min (kh) | I24: Vie max (kh) | J24: Note
A25: AEL | B25: 800 | C25: 1500 | D25: 5 | E25: 5.9 | F25: 2 | G25: 3 | H25: 55 | I25: 120 | J25: [ART] Table 4
A26: PEM | B26: 1400 | C26: 2100 | D26: 5 | E26: 5.6 | F26: 3 | G26: 5 | H26: 60 | I26: 100 | J26: [ART] Table 4
A27: SOEC | B27: 2000 | C27: 2500 | D27: 3.7 | E27: 3.9 | F27: 3 | G27: 5 | H27: 8 | I27: 20 | J27: Capex max 2 500 et opex 3–5 % = [HYP] (article : « > 2 000 » et « − »)
A28: Jaune = [HYP] (SOEC : l'article donne « > 2 000 €/kW » et « − » pour l'OPEX). Les valeurs SOEC excluent le coût de la vapeur/chaleur.

Sheet Capture_CO2
A1: Captage du CO2 — coûts, maturité et technologies
A2: [ART] §3.2, Tables 2 et 3.
A4: Méthode | B4: Coût min ($/tCO2) | C4: Coût max ($/tCO2) | D4: TRL | E4: Remarques | F4: Type de source
A5: Absorption chimique (amines) | B5: 50 | C5: 100 | D5: 9 | E5: Plus mature ; coût énergétique de régénération élevé, dégradation du solvant | F5: Point source
A6: Adsorption physique (PSA/TSA…) | B6: 30 | C6: 80 | D6: 7 | E6: Efficace pour flux concentrés ; baisse d'efficacité si CO2 dilué ou T élevée | F6: Point source
A7: Séparation membranaire | B7: 60 | C7: 120 | D7: 6 | E7: Compact, modulaire ; membranes polymères sensibles aux conditions extrêmes | F7: Point source
A8: Captage cryogénique | B8: 70 | C8: 150 | D8: 5 | E8: Liquéfaction CO2 à −56,6 °C / 5,18 bar ; efficace si CO2 concentré mais énergivore | F8: Point source
A9: Direct Air Capture (DAC) | B9: 235 | C9: 600 | D9: 5 | E9: CO2 à ~400 ppm ; très énergivore (≈80 % thermique) ; permet émissions négatives | F9: DAC
A10: Source : [ART] Table 2 (réfs [163]–[167]) et Table 3 (réfs [164],[168]). Le coût DAC ne descend généralement pas sous 235 $/t ; 100–150 $/t seulement avec fortes incitations.
A12: Technologies de captage (sources ponctuelles et DAC)
A13: Technologie | B13: Principe | C13: Type | D13: Points d'attention
A14: Pré-combustion | B14: Syngas + water-gas shift → CO2 haute pression (IGCC) | C14: Source ponctuelle | D14: CO2 concentré, séparation plus efficace
A15: Post-combustion | B15: Capture dans fumées (cimenterie, acier, électricité), CO2 3–14 % | C15: Source ponctuelle | D15: Adapté au rétrofit ; impuretés SOx/NOx
A16: Oxy-combustion | B16: Combustion en O2 pur → CO2 85–95 % | C16: Source ponctuelle | D16: Production d'O2 énergivore (synergie possible avec l'O2 de l'électrolyse)
A17: Chemical looping | B17: Oxydes métalliques porteurs d'O2 → CO2 quasi pur | C17: Source ponctuelle | D17: Complexité/échelle
A18: Calcium looping | B18: CaO comme sorbant (cimenteries, centrales) | C18: Source ponctuelle | D18: Désactivation de CaO sur cycles
A19: DAC solvant liquide (KOH) | B19: KOH → K2CO3 → CaCO3 → calcination à ~900 °C → CO2 pur | C19: DAC | D19: Chaleur haute T (gaz naturel + O2 souvent) ; 5,25–8 GJ/tCO2 thermique + 1,2–1,8 GJ/tCO2 électrique (§3.2.2) ou 6–8 GJ chaleur + 0,4–0,6 MWh élec (§3.5)
A20: DAC sorbant solide (MOF, zéolithe, charbon actif, silice) | B20: Cycle adsorption/désorption (TVSA) | C20: DAC | D20: 6 GJ/tCO2 thermique + 1,5 GJ/tCO2 électrique (§3.2.2) ; 1,5–2,5 MWh chaleur (80–120 °C) + 0,5–1 MWh élec (§3.5)
A21: DAC émergents | B21: Électrochimique, TPSA, systèmes hybrides | C21: DAC | D21: TRL bas ; potentiel d'efficacité si électricité renouvelable
A23: Énergie du DAC
A24: Technologie | B24: Besoin énergétique | C24: Source
A25: Sorbant solide (Climeworks) | B25: Chaleur basse T 80–120 °C : 1,5–2,5 MWh/tCO2 ; électricité 0,5–1 MWh/tCO2 | C25: [ART] §3.5 (réf. [207])
A26: Solvant liquide (Carbon Engineering) | B26: Chaleur ~900 °C : 6–8 GJ/tCO2 ; électricité 0,4–0,6 MWh/tCO2 | C26: [ART] §3.5 (réf. [200])
A27: Répartition énergie DAC | B27: ≈80 % thermique / 20 % mécanique (ventilateurs, compresseurs, pompes) | C27: [ART] §3.2.2
A28: Efficacité de retrait du CO2 (ACV) | B28: De < 10 % à > 95 % selon l'intensité carbone de l'énergie et la configuration | C28: [ART] §3.5

Sheet Azote_H2_Eau_Elec
A1: Azote, hydrogène, eau et électricité
A2: [ART] §3.1, §3.3–3.5.
A4: Méthode (azote) | B4: Principe | C4: Pureté | D4: Application
A5: Distillation cryogénique (ASU) | B5: Air comprimé, pré-refroidi (~10 °C), purifié puis liquéfié < −195,8 °C, distillation haute pression | C5: Haute pureté ; référence grande échelle | D5: Mature, économies d'échelle ; référence pour e-ammoniac
A6: Séparation membranaire | B6: Fibres creuses : O2 et H2O diffusent, N2 passe | C6: 95–99,5 % | D6: Petite/moyenne échelle ; compact
A7: PSA (tamis moléculaires carbone) | B7: 5–10 bar, deux colonnes alternées | C7: jusqu'à 99,999 % | D7: Jusqu'à quelques milliers de Nm³/h ; grande échelle peu courante
A9: Hydrogène, eau, électricité — repères
A10: Repère | B10: Valeur | C10: Source
A11: Densité énergétique massique | B11: 120 MJ/kg | C11: [ART] §3.3
A12: Densité énergétique volumique | B12: 10,8 MJ/Nm³ (stockage/transport difficiles) | C12: [ART] §3.3
A13: Électricité pour H2 (électrolyse) | B13: 45–73 kWh/kg H2 selon électrolyseur | C13: [ART] §3.5 (réf. [205])
A14: Électricité azote (cryogénique) | B14: 0,11 kWh/kg N2 | C14: [ART] §3.5 (réf. [206])
A15: Électricité synthèse FT | B15: 0,50 kWh/kg de produit | C15: [ART] §3.5 (réf. [107])
A16: Eau électrolyse (stœchiométrique) | B16: 8,92 L/kg H2 ; consommation réelle ≈ +25 % | C16: [ART] §3.4
A17: Eau SMR vs électrolyse | B17: SMR ≈ 11,7 kg/kg H2 ; électrolyse jusqu'à 30 kg/kg (gate-to-grave) | C17: [ART] §3.4
A18: Eau e-kérosène (DAC-FT) | B18: −0,8 à 8 kg/kg (cradle-to-grave) vs Jet A-1 ≈ 0,53 kg/kg | C18: [ART] §3.4
A19: H2 nucléaire + électrolyse haute T | B19: Rendement jusqu'à 90 %, émissions cycle de vie 0,28 kgCO2/kg H2 | C19: [ART] §3.5
A20: Hydrogène biomasse | B20: Gazéification, reformage biogaz/bioéthanol, fermentation : TRL bas, intégrables au concept « H2 vert » élargi | C20: [ART] §3.3
A21: Heures pleine charge ENR | B21: Beaucoup de régions n'atteignent pas 3 000–4 000 h/an | C21: [ART] §3.5
A22: CCS sur gaz (comparaison) | B22: 22–62 kgCO2eq/MWh (comparable à éolien/solaire en ACV) | C22: [ART] §3.5 (réf. [212])

Sheet Projets_35
A1: 35 projets e-fuels mondiaux (Table 5)
A2: Capacité en kt/an (« ~ » dans l'article). TRL min–max. Statistiques calculées plus bas.
A4: # | B4: Projet | C4: Pays | D4: E-fuel | E4: Source CO2 / N2 | F4: Énergie renouvelable | G4: Capacité (kt/an) | H4: TRL min | I4: TRL max | J4: Financement | K4: Développeurs | L4: Réf.
A5: 1 | B5: George Olah Plant | C5: Islande | D5: e-methanol | E5: Centrale électrique | F5: Géothermie | G5: 4 | H5: 8 | I5: 8 | J5: Fonds privés | K5: Carbon Recycle International (CRI) | L5: [272]
A6: 2 | B6: Sunfire PtL Plant | C6: Allemagne | D6: e-diesel, e-kerosene | E6: CO2 industriel et DAC | F6: Photovoltaïque | G6: 20 | H6: 6 | I6: 7 | J6: Public + privé | K6: Sunfire GmbH | L6: [273]
A7: 3 | B7: Nordic Blue Crude | C7: Norvège | D7: e-diesel, e-kerosene | E7: Sources carbone industrielles mixtes | F7: Hydroélectricité | G7: 10 | H7: 6 | I7: 7 | J7: Privé + public | K7: Nordic Blue Crude, Sunfire, Siemens | L7: [274]
A8: 4 | B8: MefCO2 | C8: Allemagne | D8: e-methanol | E8: Centrale électrique | F8: Photovoltaïque | G8: 0.35 | H8: 7 | I8: 7 | J8: EU Horizon 2020 | K8: MHPS Europe, Univ. Duisburg-Essen, CRI, RWE Power | L8: [275]
A9: 5 | B9: FReSMe | C9: Suède | D9: e-methanol | E9: Aciérie | F9: Réseau renouvelable | G9: 0.3 | H9: 7 | I9: 7 | J9: EU Horizon 2020 | K9: Swerim, Tata Steel, CRI, SSAB, Johnson Matthey, Mitsubishi | L9: [276]
A10: 6 | B10: H2V Projects | C10: Chili | D10: e-methanol, e-DME | E10: CO2 biogénique et industriel | F10: Éolien et PV | G10: 0.6 | H10: 5 | I10: 6 | J10: n.d. | K10: n.d. | L10: [277]
A11: 7 | B11: KEROSyN100 | C11: Allemagne | D11: e-kerosene | E11: Raffinerie | F11: Éolien | G11: 0.3 | H11: 6 | I11: 6 | J11: Public + privé | K11: Lufthansa Group, Raffinerie Heide, Univ. Bremen | L11: [278]
A12: 8 | B12: HIF Asia Pacific E-Fuel Plant | C12: Australie | D12: e-methanol | E12: CO2 biogénique | F12: Photovoltaïque | G12: 330 | H12: 6 | I12: 6 | J12: Fonds privés | K12: HIF Global, Porsche, Redflow | L12: [279]
A13: 9 | B13: Breogan Project | C13: Espagne | D13: e-kerosene, e-diesel | E13: CO2 biogénique | F13: Photovoltaïque | G13: 20 | H13: 6 | I13: 7 | J13: Fonds privés | K13: Greenalia, P2X-Europe | L13: [280]
A14: 10 | B14: SARAS | C14: Italie | D14: e-kerosene | E14: Raffinerie | F14: Éolien | G14: 0.3 | H14: 5 | I14: 6 | J14: n.d. | K14: n.d. | L14: [281]
A15: 11 | B15: SAF+ Consortium | C15: Canada | D15: e-kerosene | E15: Sources carbone industrielles mixtes | F15: Réseau renouvelable | G15: 70 | H15: 6 | I15: 7 | J15: Fonds privés | K15: Aéroports de Montréal, Airbus, Schneider, eFuel Alliance | L15: [282]
A16: 12 | B16: Dimensional Energy | C16: USA | D16: e-kerosene, e-diesel | E16: Cimenterie | F16: Réseau renouvelable | G16: 10 | H16: 6 | I16: 7 | J16: Série A | K16: Dimensional Energy + investisseurs | L16: [283]
... A39: 35 | B39: Yara Herøya (H2 renouvelable) | C39: Norvège | D39: e-ammonia | E39: N2 par ASU cryogénique | F39: Réseau renouvelable | G39: 20.5 | H39: 7 | I39: 8 | J39: n.d. | K39: n.d. | L39: [306]
A42: Statistiques [CALC]
B43: Nombre de projets | G43: =COUNTA(B5:B39) -> 35
B44: Capacité totale annoncée (kt/an) | G44: =SUM(G5:G39) -> 3765.3
B45: Capacité médiane (kt/an) | G45: =MEDIAN(G5:G39) -> 20
B46: Projets avec e-kérosène | G46: =COUNTIF(D5:D39,"*kerosene*") -> 23
B47: Projets avec e-méthanol | G47: =COUNTIF(D5:D39,"*methanol*") -> 10
B48: Projets avec e-ammoniac | G48: =COUNTIF(D5:D39,"*ammonia*") -> 3
B49: Projets avec e-diesel | G49: =COUNTIF(D5:D39,"*diesel*") -> 8
B50: Projets avec e-essence | G50: =COUNTIF(D5:D39,"*gasoline*") -> 3
B51: Projets avec e-DME | G51: =COUNTIF(D5:D39,"*DME*") -> 1
B52: Projets avec CO2 biogénique | G52: =COUNTIF(E5:E39,"*biogénique*") -> 14
B53: Projets avec DAC | G53: =COUNTIF(E5:E39,"*DAC*") -> 4
B54: Projets avec éolien | G54: =COUNTIF(F5:F39,"*olien*") -> 12
B55: Projets avec photovoltaïque | G55: =COUNTIF(F5:F39,"*hotovolta*")+COUNTIF(F5:F39,"*PV*") -> 13
B56: Projets en Allemagne | G56: =COUNTIF(C5:C39,"Allemagne") -> 11
B57: TRL max moyen | G57: =AVERAGE(I5:I39) -> 6.9714286
B58: Projets TRL ≥ 7 (TRL max) | G58: =COUNTIF(I5:I39,">=7") -> 27
B59: Capacité projets ≥ 100 kt/an (kt/an) | G59: =SUMIF(G5:G39,">=100") -> 3170
A61: Note : « Projets avec PV » compte les mentions « Photovoltaïque » et « PV » (ex. « Éolien et PV »). Les capacités sont celles annoncées, pas nécessairement installées.

Sheet LCOE_pays
A1: LCOE : hypothèses par pays (Table 6) et position du Maroc [HYP]
A2: Source [ART] Table 6 (réfs [216],[319]–[322]). Les valeurs LCOE de la Fig. 20 ne sont pas chiffrées dans le texte.
A4: Pays | B4: Source d'électricité | C4: Prix élec. min (€/MWh) | D4: Prix élec. max (€/MWh) | E4: Source CO2 | F4: Voie H2 | G4: Notes
A5: Norvège | B5: Hydroélectricité + pilote DAC | C5: 30 | D5: 45 | E5: DAC (80 %), industriel biogénique (20 %) | F5: Électrolyse PEM | G5: Hydro stable et bon marché ; DAC pour décarboner ammoniac & carburants aviation
A6: Brésil | B6: Cogénération biomasse + réseau | C6: 40 | D6: 50 | E6: CO2 biogénique (industrie éthanol) | F6: Électrolyse AEL | G6: CO2 biogénique bon marché ; intermittence compensée par biomasse
A7: Chili | B7: Solaire + éolien | C7: 45 | D7: 65 | E7: DAC (50 %), sources ponctuelles (50 %) | F7: Électrolyse PEM | G7: Fort potentiel solaire ; besoins de stockage augmentent le LCOE
A8: Japon | B8: Nucléaire + mix solaire/éolien | C8: 50 | D8: 70 | E8: DAC (60 %), industriel (40 %) | F8: SOEC + PEM hybride | G8: Nucléaire = base stable ; SOEC pour intégration haute température
A9: Allemagne | B9: Éolien + mix réseau | C9: 50 | D9: 80 | E9: Sources ponctuelles (raffineries, acier) | F9: Électrolyse PEM | G9: Mix réseau ; politiques incitant au CCS sur sources ponctuelles
A10: USA | B10: Gaz + renouvelables | C10: 40 | D10: 70 | E10: Sources ponctuelles + pilote DAC | F10: Électrolyse PEM | G10: Sourcing CO2 hybride ; IRA/BIL influencent l'économie
A11: Australie | B11: Solaire + éolien + sortie du charbon | C11: 45 | D11: 70 | E11: DAC (30 %), sources ponctuelles (70 %) | F11: AEL & PEM | G11: Grandes fermes solaires ; DAC plus coûteux en phase actuelle
A12: Arabie saoudite | B12: Solaire (PV désertique) | C12: 25 | D12: 40 | E12: DAC | F12: Électrolyse PEM | G12: PV ultra bon marché ; focus export d'ammoniac
A13: Maroc [HYP] | B13: PV + éolien hybride (sud/Atlantique) | C13: 22 | D13: 45 | E13: Point source (cimenteries, chimie, charbon) / biogénique ; DAC en option | F13: PEM (ou AEL) | G13: Hypothèse Sherpa : plage à valider par PPA/appels d'offres et profils de site
A15: Statistiques [CALC]
A16: Prix élec. moyen (milieu de fourchette, 8 pays) | C16: =AVERAGE(C5:D12) -> 50.9375
A17: Maroc [HYP] milieu de fourchette | C17: =AVERAGE(C13:D13) -> 33.5
A18: Écart Maroc vs moyenne (%) | C18: =C17/C16-1 -> -0.34233129

Sheet Politiques_regl
A1: Politiques, réglementation et certification
A2: [ART] §2.
A4: Région | B4: Catégorie | C4: Instrument / mesure | D4: Détail | E4: Chiffre clé | F4: Pertinence pour e-fuels / Maroc | G4: Source
A5: Europe | B5: Cibles | C5: European Green Deal (2019) / Loi Climat (2021) | D5: Neutralité 2050 ; −55 % GES en 2030 vs 1990 | E5: 2050 / 2030 | F5: Cadre de demande pour e-fuels | G5: [ART] §2.1
A6: Europe | B6: Financement | C6: NextGenerationEU / Recovery & Resilience Facility | D6: Programme de relance de 800 Md€ | E6: 800 Md€ | F6: Soutien transition et infrastructures | G6: [ART] §2.1
A7: Europe | B7: Paquet législatif | C7: Fit for 55 | D7: Extension ETS au maritime et routier ; CBAM ; Fonds social pour le climat | E7: — | F7: Prix du carbone sur le maritime ; protection des industriels UE | G7: [ART] §2.1
A8: Europe | B8: Énergie | C8: RePowerEU (2022) | D8: Réduire la dépendance au gaz fossile ; 10 Mt H2 renouvelable (production + imports) en 2030 | E8: 10 Mt H2 | F8: Opportunité d'import d'H2/e-fuels (Maroc potentiel exportateur) | G8: [ART] §2.1
A9: Europe | B9: Directive | C9: RED (EU 2018/2001, 2023/2413) | D9: Cibles RFNBO contraignantes | E9: — | F9: Définit ce qu'est un RFNBO | G9: [ART] §2.1
A10: Europe | B10: Aviation | C10: ReFuelEU Aviation (EU 2023/2405) | D10: Mandat SAF : 2 % en 2025 → 63 % en 2050 | E10: 2 % → 63 % | F10: Demande garantie d'e-kérosène/SAF | G10: [ART] §2.1
A11: Europe | B11: Maritime | C11: FuelEU Maritime (EU 2023/1805) | D11: Promeut e-méthanol et e-ammoniac | E11: — | F11: Demande maritime (soutage) | G11: [ART] §2.1
A12: Europe | B12: Infrastructure | C12: AFIR (EU 2023/1804) | D12: Déploiement des infrastructures H2/électriques | E12: — | F12: Infrastructure | G12: [ART] §2.1
A13: Europe | B13: Instruments financiers | C13: CFD, PPA, Innovation Fund, Banque européenne de l'hydrogène | D13: Réduire l'écart de coût avec le fossile | E13: — | F13: Modèles de financement pour projets Maroc-export | G13: [ART] §2.1
A14: USA | B14: Lois | C14: IRA + BIL (2021) | D14: BIL : 1 200 Md$ d'infrastructures, hubs H2 régionaux ; IRA : crédits 45Z (carburants bas carbone, SAF), 45V (H2) | E14: 1,2 Tn$ | F14: Crédits d'impôt — fortement réduits/gelés en 2025 selon l'article | G14: [ART] §2.2
A15: USA | B15: Normes | C15: RFS et LCFS (Californie, Oregon, Washington) | D15: Mandats de mélange et intensité carbone ; génèrent des crédits | E15: — | F15: Marchés de crédits pour SAF/e-fuels | G15: [ART] §2.2
... A23: Chine | B23: Scénario AIE | C23: H2 et e-fuels | D23: 3 % des réductions cumulatives de CO2 d'ici 2060 ; 26 % de la demande en carburant aviation | E23: 26 % aviation | F23: — | G23: [ART] §2.4
A25: Voies SAF approuvées ASTM (Table 1)
A26: Référence ASTM | B26: Procédé | C26: Charge | D26: Mélange max (% vol.)
A27: ASTM D7566 (A1) | B27: FT-SPK | C27: Syngas (gaz naturel, charbon, biomasse) | D27: 50
A28: ASTM D7566 (A2) | B28: HEFA | C28: Huiles biologiques, graisses animales, huiles recyclées | D28: 50
A29: ASTM D7566 (A3) | B29: SIP | C29: Biomasse pour sucres fermentés | D29: 10
A30: ASTM D7566 (A4) | B30: FT-SKA | C30: Syngas (gaz naturel, charbon, biomasse) | D30: 50
A31: ASTM D7566 (A5) | B31: ATJ-SPK | C31: Éthanol ou isobutanol | D31: 50
A32: ASTM D7566 (A6) | B32: CHJ | C32: Triglycérides (soja, jatropha, caméline…) | D32: 50
A33: ASTM D7566 (A7) | B33: HC-HEFA-SPK | C33: Algues | D33: 10
A34: ASTM D1655 (A1) | B34: Co-traitement FT | C34: Biocrude FT comme charge dans raffinerie | D34: 5
A36: Certification, documentation et durabilité
A37: Élément | B37: Détail | C37: Source
A38: ASTM D1655 | B38: Spécification du Jet A / Jet A-1 conventionnel | C38: [ART] §2.5.1
A39: ASTM D7566 | B39: Carburéacteur contenant des hydrocarbures de synthèse (mélange autorisé) | C39: [ART] §2.5.1
A40: ASTM D4054 | B40: Qualification et approbation de nouveaux carburants (4 niveaux, 3 phases) | C40: [ART] §2.5.1
A41: Durée / coût | B41: 3 à 5 ans et jusqu'à 15 M$ par voie | C41: [ART] §2.5.1
A42: Fast Track (2020) | B42: Procédure simplifiée mais mélange ≤ 10 % avec Jet A/A-1 | C42: [ART] §2.5.1
A43: Limite actuelle | B43: Aucune voie certifiée pour 100 % de SAF en aviation commerciale | C43: [ART] §2.5.1
A44: Documents | B44: RCQ (certificat qualité raffinerie), CoA (analyse labo), RTC (recertification) | C44: [ART] §2.5.2
A45: Mélange SAF/Jet A | B45: Réservoir dédié ou injection directe lors de la livraison ; nouveau CoA puis reclassification ASTM D1655 | C45: [ART] §2.5.2
A46: Durabilité | B46: CORSIA (OACI), RSB, ISCC : réduction GES cycle de vie, changement d'usage des sols, eau/air/sol/déchets | C46: [ART] §2.5.2
A47: Lacunes pour e-fuels | B47: Normes insuffisantes, critères de durabilité incohérents, intégration infra et traçabilité insuffisantes | C47: [ART] §2.5.1

Sheet Barrieres_Risques
A1: Barrières, risques et atténuation
A2: Barrières issues de l'article [ART] ; ajouts Maroc [HYP].
A4: Catégorie | B4: Barrière / risque | C4: Gravité (qualitative) | D4: Référence | E4: Mesure d'atténuation proposée | F4: Statut source
A5: Technique | B5: Rendement global faible vs électrification directe (pertes électricité→H2→carburant) | C5: Élevé | D5: Article §6, §3 | E5: Réserver les e-fuels aux usages non électrifiables (aviation, maritime) ; optimiser intégration thermique ; viser SOEC/co-électrolyse à terme | F5: [ART]
A6: Technique | B6: Désactivation des catalyseurs (voie méthanol/MtL, CZA/CZZA, coke ZSM-5) | C6: Moyen | D6: Article §4.2, §4.4 | E6: Choisir voies éprouvées ; plan de maintenance catalyseur ; garanties fournisseurs | F6: [ART]
A7: Technique | B7: Intermittence ENR et heures pleine charge insuffisantes (3 000–4 000 h/an) | C7: Élevé | D7: Article §3.5 | E7: Hybridation PV+éolien, stockage H2/batteries, électrolyseurs flexibles (PEM), sites à >5 000 h | F7: [ART]/[HYP]
A8: Technique | B8: Durabilité SOEC (8–20 kh, dégradation 3–50 %/an) | C8: Moyen | D8: Article Table 4 | E8: Attendre TRL ≥ 8 ; pilotes seulement | F8: [ART]
A9: Économique | B9: CAPEX électrolyseurs et captage CO2 élevés ; coût H2 3–6 €/kg | C9: Élevé | D9: Article §6 | E9: Appels d'offres compétitifs ; standardisation modulaire ; financements climat/CFD | F9: [ART]
A10: Économique | B10: Écart de coût avec le fossile (e-kérosène 3 062–4 215 €/t aujourd'hui) | C10: Élevé | D10: Article §4.4.1 | E10: Contrats d'achat à long terme avec compagnies (mandats UE), primes vertes, CBAM | F10: [ART]/[HYP]
A11: Économique | B11: Coût du CO2 (DAC ≥ 235 $/t) | C11: Élevé | D11: Article §3.2.3 | E11: Privilégier sources ponctuelles/biogéniques ; DAC seulement si valeur eau/émissions négatives | F11: [ART]
A12: Réglementaire | B12: Cadre RFNBO fragmenté (comptabilité carbone, durabilité hétérogènes) | C12: Élevé | D12: Article §1.1, §6 | E12: Veille réglementaire UE ; certification ISCC/RSB dès la conception | F12: [ART]
A13: Réglementaire | B13: Certification ASTM longue (3–5 ans, jusqu'à 15 M$) ; pas de voie 100 % SAF | C13: Moyen | D13: Article §2.5.1 | E13: S'appuyer sur voies déjà approuvées (FT-SPK 50 %) et partenaires OEM | F13: [ART]
A14: Réglementaire | B14: Incertitude politique (ex. retraits USA 2025) | C14: Moyen | D14: Article §2.2 | E14: Ne pas dépendre d'un seul marché ; contrats indexés ; diversifier (UE, maritime, local) | F14: [ART]
A15: Infrastructure | B15: Infrastructure limitée et matériaux critiques | C15: Moyen | D15: Article §3, §6 | E15: Co-localiser production/ports ; sécuriser chaîne d'approvisionnement électrolyseurs (Pt, Ir pour PEM) | F15: [ART]
... A21: Maroc [HYP] | B21: Compétences locales (exploitation PtX) et chaîne d'approvisionnement | C21: Moyen | D21: — | E21: Partenariats technologiques ; formation (UM6P, IRESEN — à valider) | F21: [HYP]

Sheet Maroc_Contexte
A1: Contexte Maroc — éléments à valider [HYP]
A2: NON issu de l'article : connaissance générale de Sherpa. Chaque ligne a un niveau de confiance et la source de validation recommandée.
A4: Thème | B4: Élément | C4: Confiance | D4: Où valider / collecter
A5: Ressource ENR | B5: Fort potentiel solaire (sud) et éolien (Atlantique : Dakhla, Laâyoune, Tarfaya, Essaouira) ; facteurs de charge éoliens souvent 40–55 % sur sites côtiers du sud | C5: Moyenne | D5: Données de site (mât de mesure, ERA5, Global Wind/Solar Atlas) ; ONEE/MASEN
A6: Prix électricité ENR | B6: Hypothèse 22–45 €/MWh pour PV+éolien hybride (milieu 30) — à confronter aux PPA/appels d'offres récents | C6: Faible | D6: MASEN, ONEE, appels d'offres, développeurs privés
A7: Stratégie hydrogène | B7: Feuille de route hydrogène vert (2021) et « Offre Maroc » (2023) mobilisant du foncier pour projets PtX ; statut des projets/consortia à vérifier (évolutions 2025–2026) | C7: Moyenne | D7: Ministère de la Transition énergétique, Agence des Énergies Renouvelables, presse spécialisée
A8: Demande locale ammoniac | B8: OCP (phosphates/engrais, Jorf Lasfar) : gros consommateur d'ammoniac ; ambitions d'ammoniac vert annoncées (volumes/calendrier à vérifier) | C8: Moyenne | D8: OCP, rapports annuels
A9: Sources de CO2 | B9: Cimenteries, centrales à charbon (Jorf Lasfar, Safi), sites chimiques, sources biogéniques (sucreries, biogaz, fermentation) — volumes et concentrations à cartographier | C9: Moyenne | D9: Inventaire GES national, industriels
A10: Eau | B10: Stress hydrique national → électrolyse alimentée par dessalement dédié ; besoin ≈ 11 L/kg H2 (voir calculateur) ; gestion de la saumure | C10: Moyenne | D10: ONEE-Branche eau, projets de dessalement existants
A11: Ports et logistique | B11: Ports d'exportation potentiels : Tanger Med, Nador West Med, Jorf Lasfar, Dakhla Atlantique ; proximité de l'Europe (soutage maritime, export e-fuels) | C11: Moyenne | D11: Tanger Med Authority, ANP
A12: Marché export UE | B12: ReFuelEU (SAF 2 % en 2025 → 63 % en 2050 [ART]) et FuelEU Maritime créent une demande ; conditions RFNBO (additionnalité, corrélation temporelle/géographique) à intégrer — détails à vérifier dans les actes délégués de l'UE | C12: Moyenne | D12: Commission européenne, DG ENER
A13: CBAM | B13: Mécanisme d'ajustement carbone aux frontières de l'UE (cité par l'article) — couvre notamment hydrogène, engrais ; impacte export d'ammoniac/engrais carbonés | C13: Moyenne | D13: Règlement (UE) 2023/956 [ART réf. 34]
A14: Réseau et interconnexion | B14: Interconnexions avec l'Espagne ; réseau marocain à renforcer pour grands électrolyseurs | C14: Faible | D14: ONEE
A15: Cadre SAF marocain | B15: Existence d'un mandat national SAF/maritime : non vérifiée ici | C15: Faible | D15: ONDA, ministère des Transports
A16: Financement | B16: Banques de développement et fonds climat ; mécanismes de type CFD absents localement (hypothèse) | C16: Faible | D16: BEI, KfW, BAD, Masen Financial
A18: Données à collecter en priorité (checklist)
A19: # | B19: Donnée
A20: 1 | B20: Profils horaires PV et éolien par site (1 an complet minimum) → heures pleine charge réalistes pour l'électrolyseur
A21: 2 | B21: Offres de prix ENR (PPA) et tarif de réseau pour auto-consommation / wheeling
A22: 3 | B22: Devis électrolyseur (AEL/PEM) et captage CO2, installation locale, délais, droits de douane
A23: 4 | B23: Inventaire des sources CO2 (t/an, concentration, pureté, distance)
A24: 5 | B24: Disponibilité d'eau dessalée (m³/j) et coût marginal (€/m³) ; gestion saumure
A25: 6 | B25: Contrats d'achat potentiels (compagnies aériennes, armateurs, OCP, traders)
A26: 7 | B26: Conformité RFNBO/ISCC : audit préliminaire, calendrier

Sheet Opportunites_Innovation
A1: Pistes d'innovation pour Sherpa Engineering
A2: Ancrées dans l'article ; l'évaluation qualitative (valeur, risque) est un jugement Sherpa [HYP].
A4: ID | B4: Idée | C4: Justification (article) | D4: Valeur potentielle | E4: Risque technique | F4: Risque marché | G4: Prochaine étape
A5: O1 | B5: Électrolyse PEM flexible couplée PV + éolien + stockage | C5: PEM : réponse < 10 s, charge 0–100 %, TRL 8–9 ; maximise les heures pleine charge malgré l'intermittence (problème §3.5) | D5: Haut | E5: Moyen | F5: Élevé | G5: Étude de dispatch horaire (simulation) + dimensionnement stockage H2/batteries
A6: O2 | B6: Co-électrolyse SOEC + intégration thermique (chaleur fatale cimenterie/OCP) | C6: SOEC : rendement système 76–81 %, co-électrolyse CO2+vapeur → syngas ; durabilité à prouver (8–20 kh) | D6: Haut | E6: Élevé | F6: Faible-Moyen | G6: Pilote < 1 MW ; veille technologique fournisseurs
A7: O3 | B7: Cimenterie + oxy-combustion avec l'O2 de l'électrolyse → CO2 quasi pur | C7: L'oxy-combustion donne 85–95 % de CO2 mais l'O2 coûte cher (§3.2.1) ; l'électrolyse fournit ~8 kg O2 par kg H2 gratuitement | D7: Haut | E7: Moyen | F7: Moyen | G7: Bilan matière/énergie d'un site cimentier pilote
A8: O4 | B8: Ammoniac vert pour OCP / export (sans besoin de CO2) | C8: e-NH3 : TRL 6–8 ; projets de 500 kt/an (MadoquaPower2X) ; Haber–Bosch dynamique (Ramme) pour suivre l'ENR | D8: Haut | E8: Faible | F8: Faible-Moyen | G8: Étude de faisabilité couplée à la demande OCP (à valider)
A9: O5 | B9: Haber–Bosch dynamique (flexibilité de charge) | C9: Projet Ramme (5 kt/an, TRL 6–7) : opération suivant le vent/PV ; réduit le besoin de stockage H2 | D9: Moyen | E9: Moyen | F9: Moyen | G9: Spécification de rampes avec fournisseur (Topsoe)
A10: O6 | B10: E-méthanol maritime pour soutage (Tanger Med, Dakhla) | C10: e-méthanol : technologie mature (TRL 8), CAPEX bas 300–1 200 €/kW ; demande FuelEU Maritime | D10: Haut | E10: Faible | F10: Moyen | G10: Contrats d'intention armateurs ; analyse du cycle de vie
A11: O7 | B11: FT modulaire pour e-SAF (type INERATEC) | C11: Unités modulaires 2,5 kt/an (TRL 7–8) ; déploiement par étapes réduit le risque | D11: Moyen | E11: Moyen | F11: Moyen | G11: Benchmark fournisseurs modulaires ; plan de montée en échelle
A12: O8 | B12: DAC + récupération d'eau en zone aride | C12: DAC-FT : consommation d'eau nette de −0,8 à 8 kg/kg ; coûts élevés (235–600 $/t) | D12: Moyen | E12: Élevé | F12: Élevé | G12: Évaluer uniquement si sources ponctuelles insuffisantes ; DAC basse température
A13: O9 | B13: Dessalement et électrolyse co-localisés (eau ≈ 11 L/kg H2) | C13: Consommation d'eau modeste devant l'énergie ; saumure à gérer ; partage d'infrastructure ENR | D13: Haut | E13: Faible | F13: Faible | G13: Intégrer au module dessalement du prototype
A14: O10 | B14: Plateforme MRV/traçabilité RFNBO | C14: Lacune identifiée : traçabilité insuffisante de la chaîne (§2.5.1) ; certifications ISCC/RSB | D14: Haut | E14: Faible | F14: Faible | G14: Prototype de registre numérique (compteurs horaires, garanties d'origine)
A15: O11 | B15: Hybridation biomasse + H2 vert (CO2 biogénique) | C15: H2 de biomasse = composante du H2 vert élargi (§3.3) ; CO2 biogénique parmi les sources les plus utilisées dans les projets | D15: Moyen | E15: Moyen | F15: Moyen | G15: Cartographie biomasse/biogaz au Maroc
... A18: O14 | B18: Cartographie SIG des sites PtX (ENR, eau, CO2, port, réseau) | C18: Pfennig et al. [307] : analyse SIG globale PtX 2050 citée par l'article | D18: Haut | E18: Moyen | F18: Faible | G18: Couches SIG + score multicritère

Sheet Calculateur_LCOE
A1: Calculateur de coût de production des e-fuels (pré-faisabilité)
A2: Bleu = entrée · noir = formule · vert = lien · jaune = hypothèse clé. Modifiez les cellules bleues ; tout se recalcule.
A4: A. Paramètres généraux
A5: Paramètre | B5: Valeur | C5: Unité | D5: Source / note
A6: Prix de l'électricité renouvelable | B6: 30 | C6: €/MWh | D6: [HYP] Maroc PV+éolien hybride ; plage 22–45
A7: Heures pleine charge de l'électrolyseur | B7: 5000 | C7: h/an | D7: [HYP] article : régions typiques 3 000–4 000 h/an
A8: Technologie d'électrolyse | B8: PEM | C8: AEL / PEM / SOEC | D8: [ART] PEM la plus utilisée
A9: Type de source de CO2 | B9: Point source | C9: Point source / DAC | D9: [ART] Table 2
A10: Taux d'actualisation (WACC) | B10: 0.08 | C10: % | D10: [HYP] plage 6–12 %
A11: Durée de vie / amortissement | B11: 20 | C11: ans | D11: [HYP]
A12: Facteur de recouvrement du capital (CRF) | B12: =IF($B$10=0,1/$B$11,$B$10*(1+$B$10)^$B$11/((1+$B$10)^$B$11-1)) -> 0.10185221 | C12: 1/an | D12: [CALC]
A13: Taux de change €/USD | B13: 0.92 | C13: € par $ | D13: [HYP]
A14: Prix de l'eau dessalée | B14: 2 | C14: €/m³ | D14: [HYP] plage 1–3
A15: Eau stœchiométrique électrolyse | B15: 8.92 | C15: L/kg H2 | D15: [ART] §3.4
A16: Surconsommation d'eau réelle | B16: 0.25 | C16: % | D16: [ART] §3.4 (≈ +25 %)
A17: Eau réelle par kg d'H2 | B17: =$B$15*(1+$B$16) -> 11.15 | C17: L/kg H2 | D17: [CALC]
A18: Densité de l'hydrogène | B18: 0.08988 | C18: kg/Nm³ | D18: Constante physique (0 °C, 1 atm)
A19: Taux d'utilisation de l'unité de synthèse | B19: 0.9 | C19: % | D19: [HYP]
A20: OPEX unité de synthèse | B20: 0.04 | C20: % CAPEX/an | D20: [HYP]
A21: Rendement matière (conversion réelle) | B21: 0.95 | C21: % | D21: [HYP]
A22: Électricité pour l'azote (cryogénique) | B22: 0.11 | C22: kWh/kg N2 | D22: [ART] §3.5
A23: Masse molaire H2 | B23: 2.016 | C23: g/mol | D23: Constante
A24: Masse molaire CO2 | B24: 44.01 | C24: g/mol | D24: Constante
A25: Masse molaire N2 | B25: 28.014 | C25: g/mol | D25: Constante
A26: Masse molaire méthanol | B26: 32.04 | C26: g/mol | D26: Constante
A27: Masse molaire DME | B27: 46.07 | C27: g/mol | D27: Constante
A28: Masse molaire NH3 | B28: 17.031 | C28: g/mol | D28: Constante
A29: Masse molaire unité CH2 (hydrocarbures FT/MTG) | B29: 14.027 | C29: g/mol | D29: Constante (approximation (CH2)n)
A31: B. Tables de référence (liens vers feuilles de données)
A32: Électrolyseur | B32: CAPEX min | C32: CAPEX max | D32: kWh/Nm³ min | E32: kWh/Nm³ max | F32: OPEX min % | G32: OPEX max %
A33: =Electrolyse!A25 -> AEL | B33: =Electrolyse!B25 -> 800 | C33: =Electrolyse!C25 -> 1500 | D33: =Electrolyse!D25 -> 5 | E33: =Electrolyse!E25 -> 5.9 | F33: =Electrolyse!F25 -> 2 | G33: =Electrolyse!G25 -> 3
A34: =Electrolyse!A26 -> PEM | B34: =Electrolyse!B26 -> 1400 | C34: =Electrolyse!C26 -> 2100 | D34: =Electrolyse!D26 -> 5 | E34: =Electrolyse!E26 -> 5.6 | F34: =Electrolyse!F26 -> 3 | G34: =Electrolyse!G26 -> 5
A35: =Electrolyse!A27 -> SOEC | B35: =Electrolyse!B27 -> 2000 | C35: =Electrolyse!C27 -> 2500 | D35: =Electrolyse!D27 -> 3.7 | E35: =Electrolyse!E27 -> 3.9 | F35: =Electrolyse!F27 -> 3 | G35: =Electrolyse!G27 -> 5
A37: Source de CO2 | B37: Coût min ($/t) | C37: Coût max ($/t) | D37: Énergie capture (MWh/t)
A38: Point source | B38: =Capture_CO2!B5 -> 50 | C38: =Capture_CO2!C5 -> 100 | D38: 0.25 | E38: [HYP] chaleur souvent fatale ; sert au calcul d'efficacité seulement
A39: DAC | B39: =Capture_CO2!B9 -> 235 | C39: =Capture_CO2!C9 -> 600 | D39: =(1.5+2.5)/2+(0.5+1)/2 -> 2.75 | E39: [ART] §3.5 : chaleur 1,5–2,5 + élec 0,5–1 MWh/t (milieux)
A40: Le coût du CO2 en $/t (Table 2) intègre déjà énergie et capital : l'énergie de capture n'est utilisée que pour l'efficacité globale (pas de double comptage du coût).
A42: C. Paramètres dérivés de l'électrolyseur et du CO2
A43: Paramètre | B43: Valeur | C43: Unité | D43: Source / note
A44: Consommation système électrolyseur | B44: =AVERAGE(INDEX($D$33:$D$35,MATCH($B$8,$A$33:$A$35,0)),INDEX($E$33:$E$35,MATCH($B$8,$A$33:$A$35,0))) -> 5.3 | C44: kWh/Nm³ | D44: [CALC] milieu fourchette Table 4
...

Sheet Sensibilite
A1: Analyses de sensibilité [CALC]
A2: Toutes les cellules sont des formules liées au Calculateur_LCOE.
A4: 1. LCOH (€/kg H2) selon le prix de l'électricité (lignes) et les heures pleine charge (colonnes)
A5: €/MWh \ h/an | B5: 3000 | C5: 4000 | D5: 5000 | E5: 6000 | F5: 7000 | G5: 8000
A6: 15 | B6: =$A6*Calculateur_LCOE!$B$45/1000+Calculateur_LCOE!$B$46*(Calculateur_LCOE!$B$12+Calculateur_LCOE!$B$47)/(B$5/Calculateur_LCOE!$B$45)+Calculateur_LCOE!$B$56 -> 5.7862046 | C6: =$A6*Calculateur_LCOE!$B$45/1000+Calculateur_LCOE!$B$46*(Calculateur_LCOE!$B$12+Calculateur_LCOE!$B$47)/(C$5/Calculateur_LCOE!$B$45)+Calculateur_LCOE!$B$56 -> 4.5663566 | D6: =$A6*Calculateur_LCOE!$B$45/1000+Calculateur_LCOE!$B$46*(Calculateur_LCOE!$B$12+Calculateur_LCOE!$B$47)/(D$5/Calculateur_LCOE!$B$45)+Calculateur_LCOE!$B$56 -> 3.8344478 | E6: =$A6*Calculateur_LCOE!$B$45/1000+Calculateur_LCOE!$B$46*(Calculateur_LCOE!$B$12+Calculateur_LCOE!$B$47)/(E$5/Calculateur_LCOE!$B$45)+Calculateur_LCOE!$B$56 -> 3.3465086 | F6: =$A6*Calculateur_LCOE!$B$45/1000+Calculateur_LCOE!$B$46*(Calculateur_LCOE!$B$12+Calculateur_LCOE!$B$47)/(F$5/Calculateur_LCOE!$B$45)+Calculateur_LCOE!$B$56 -> 2.9979806 | G6: =$A6*Calculateur_LCOE!$B$45/1000+Calculateur_LCOE!$B$46*(Calculateur_LCOE!$B$12+Calculateur_LCOE!$B$47)/(G$5/Calculateur_LCOE!$B$45)+Calculateur_LCOE!$B$56 -> 2.7365847
A7: 20 | B7: =$A7*Calculateur_LCOE!$B$45/1000+Calculateur_LCOE!$B$46*(Calculateur_LCOE!$B$12+Calculateur_LCOE!$B$47)/(B$5/Calculateur_LCOE!$B$45)+Calculateur_LCOE!$B$56 -> 6.0810422 | C7: =$A7*Calculateur_LCOE!$B$45/1000+Calculateur_LCOE!$B$46*(Calculateur_LCOE!$B$12+Calculateur_LCOE!$B$47)/(C$5/Calculateur_LCOE!$B$45)+Calculateur_LCOE!$B$56 -> 4.8611942 | D7: =$A7*Calculateur_LCOE!$B$45/1000+Calculateur_LCOE!$B$46*(Calculateur_LCOE!$B$12+Calculateur_LCOE!$B$47)/(D$5/Calculateur_LCOE!$B$45)+Calculateur_LCOE!$B$56 -> 4.1292854 | E7: =$A7*Calculateur_LCOE!$B$45/1000+Calculateur_LCOE!$B$46*(Calculateur_LCOE!$B$12+Calculateur_LCOE!$B$47)/(E$5/Calculateur_LCOE!$B$45)+Calculateur_LCOE!$B$56 -> 3.6413462 | F7: =$A7*Calculateur_LCOE!$B$45/1000+Calculateur_LCOE!$B$46*(Calculateur_LCOE!$B$12+Calculateur_LCOE!$B$47)/(F$5/Calculateur_LCOE!$B$45)+Calculateur_LCOE!$B$56 -> 3.2928182 | G7: =$A7*Calculateur_LCOE!$B$45/1000+Calculateur_LCOE!$B$46*(Calculateur_LCOE!$B$12+Calculateur_LCOE!$B$47)/(G$5/Calculateur_LCOE!$B$45)+Calculateur_LCOE!$B$56 -> 3.0314222
A8: 25 | B8: =$A8*Calculateur_LCOE!$B$45/1000+Calculateur_LCOE!$B$46*(Calculateur_LCOE!$B$12+Calculateur_LCOE!$B$47)/(B$5/Calculateur_LCOE!$B$45)+Calculateur_LCOE!$B$56 -> 6.3758797 | C8: =$A8*Calculateur_LCOE!$B$45/1000+Calculateur_LCOE!$B$46*(Calculateur_LCOE!$B$12+Calculateur_LCOE!$B$47)/(C$5/Calculateur_LCOE!$B$45)+Calculateur_LCOE!$B$56 -> 5.1560317 | D8: =$A8*Calculateur_LCOE!$B$45/1000+Calculateur_LCOE!$B$46*(Calculateur_LCOE!$B$12+Calculateur_LCOE!$B$47)/(D$5/Calculateur_LCOE!$B$45)+Calculateur_LCOE!$B$56 -> 4.424123 | E8: =$A8*Calculateur_LCOE!$B$45/1000+Calculateur_LCOE!$B$46*(Calculateur_LCOE!$B$12+Calculateur_LCOE!$B$47)/(E$5/Calculateur_LCOE!$B$45)+Calculateur_LCOE!$B$56 -> 3.9361838 | F8: =$A8*Calculateur_LCOE!$B$45/1000+Calculateur_LCOE!$B$46*(Calculateur_LCOE!$B$12+Calculateur_LCOE!$B$47)/(F$5/Calculateur_LCOE!$B$45)+Calculateur_LCOE!$B$56 -> 3.5876558 | G8: =$A8*Calculateur_LCOE!$B$45/1000+Calculateur_LCOE!$B$46*(Calculateur_LCOE!$B$12+Calculateur_LCOE!$B$47)/(G$5/Calculateur_LCOE!$B$45)+Calculateur_LCOE!$B$56 -> 3.3262598
A9: 30 | B9: =$A9*Calculateur_LCOE!$B$45/1000+Calculateur_LCOE!$B$46*(Calculateur_LCOE!$B$12+Calculateur_LCOE!$B$47)/(B$5/Calculateur_LCOE!$B$45)+Calculateur_LCOE!$B$56 -> 6.6707173 | C9: =$A9*Calculateur_LCOE!$B$45/1000+Calculateur_LCOE!$B$46*(Calculateur_LCOE!$B$12+Calculateur_LCOE!$B$47)/(C$5/Calculateur_LCOE!$B$45)+Calculateur_LCOE!$B$56 -> 5.4508693 | D9: =$A9*Calculateur_LCOE!$B$45/1000+Calculateur_LCOE!$B$46*(Calculateur_LCOE!$B$12+Calculateur_LCOE!$B$47)/(D$5/Calculateur_LCOE!$B$45)+Calculateur_LCOE!$B$56 -> 4.7189605 | E9: =$A9*Calculateur_LCOE!$B$45/1000+Calculateur_LCOE!$B$46*(Calculateur_LCOE!$B$12+Calculateur_LCOE!$B$47)/(E$5/Calculateur_LCOE!$B$45)+Calculateur_LCOE!$B$56 -> 4.2310213 | F9: =$A9*Calculateur_LCOE!$B$45/1000+Calculateur_LCOE!$B$46*(Calculateur_LCOE!$B$12+Calculateur_LCOE!$B$47)/(F$5/Calculateur_LCOE!$B$45)+Calculateur_LCOE!$B$56 -> 3.8824933 | G9: =$A9*Calculateur_LCOE!$B$45/1000+Calculateur_LCOE!$B$46*(Calculateur_LCOE!$B$12+Calculateur_LCOE!$B$47)/(G$5/Calculateur_LCOE!$B$45)+Calculateur_LCOE!$B$56 -> 3.6210973
A10: 40 | B10: =$A10*Calculateur_LCOE!$B$45/1000+Calculateur_LCOE!$B$46*(Calculateur_LCOE!$B$12+Calculateur_LCOE!$B$47)/(B$5/Calculateur_LCOE!$B$45)+Calculateur_LCOE!$B$56 -> 7.2603924 | C10: =$A10*Calculateur_LCOE!$B$45/1000+Calculateur_LCOE!$B$46*(Calculateur_LCOE!$B$12+Calculateur_LCOE!$B$47)/(C$5/Calculateur_LCOE!$B$45)+Calculateur_LCOE!$B$56 -> 6.0405444 | D10: =$A10*Calculateur_LCOE!$B$45/1000+Calculateur_LCOE!$B$46*(Calculateur_LCOE!$B$12+Calculateur_LCOE!$B$47)/(D$5/Calculateur_LCOE!$B$45)+Calculateur_LCOE!$B$56 -> 5.3086356 | E10: =$A10*Calculateur_LCOE!$B$45/1000+Calculateur_LCOE!$B$46*(Calculateur_LCOE!$B$12+Calculateur_LCOE!$B$47)/(E$5/Calculateur_LCOE!$B$45)+Calculateur_LCOE!$B$56 -> 4.8206964 | F10: =$A10*Calculateur_LCOE!$B$45/1000+Calculateur_LCOE!$B$46*(Calculateur_LCOE!$B$12+Calculateur_LCOE!$B$47)/(F$5/Calculateur_LCOE!$B$45)+Calculateur_LCOE!$B$56 -> 4.4721685 | G10: =$A10*Calculateur_LCOE!$B$45/1000+Calculateur_LCOE!$B$46*(Calculateur_LCOE!$B$12+Calculateur_LCOE!$B$47)/(G$5/Calculateur_LCOE!$B$45)+Calculateur_LCOE!$B$56 -> 4.2107725
A11: 50 | B11: =$A11*Calculateur_LCOE!$B$45/1000+Calculateur_LCOE!$B$46*(Calculateur_LCOE!$B$12+Calculateur_LCOE!$B$47)/(B$5/Calculateur_LCOE!$B$45)+Calculateur_LCOE!$B$56 -> 7.8500675 | C11: =$A11*Calculateur_LCOE!$B$45/1000+Calculateur_LCOE!$B$46*(Calculateur_LCOE!$B$12+Calculateur_LCOE!$B$47)/(C$5/Calculateur_LCOE!$B$45)+Calculateur_LCOE!$B$56 -> 6.6302196 | D11: =$A11*Calculateur_LCOE!$B$45/1000+Calculateur_LCOE!$B$46*(Calculateur_LCOE!$B$12+Calculateur_LCOE!$B$47)/(D$5/Calculateur_LCOE!$B$45)+Calculateur_LCOE!$B$56 -> 5.8983108 | E11: =$A11*Calculateur_LCOE!$B$45/1000+Calculateur_LCOE!$B$46*(Calculateur_LCOE!$B$12+Calculateur_LCOE!$B$47)/(E$5/Calculateur_LCOE!$B$45)+Calculateur_LCOE!$B$56 -> 5.4103716 | F11: =$A11*Calculateur_LCOE!$B$45/1000+Calculateur_LCOE!$B$46*(Calculateur_LCOE!$B$12+Calculateur_LCOE!$B$47)/(F$5/Calculateur_LCOE!$B$45)+Calculateur_LCOE!$B$56 -> 5.0618436 | G11: =$A11*Calculateur_LCOE!$B$45/1000+Calculateur_LCOE!$B$46*(Calculateur_LCOE!$B$12+Calculateur_LCOE!$B$47)/(G$5/Calculateur_LCOE!$B$45)+Calculateur_LCOE!$B$56 -> 4.8004476
A12: 60 | B12: =$A12*Calculateur_LCOE!$B$45/1000+Calculateur_LCOE!$B$46*(Calculateur_LCOE!$B$12+Calculateur_LCOE!$B$47)/(B$5/Calculateur_LCOE!$B$45)+Calculateur_LCOE!$B$56 -> 8.4397427 | C12: =$A12*Calculateur_LCOE!$B$45/1000+Calculateur_LCOE!$B$46*(Calculateur_LCOE!$B$12+Calculateur_LCOE!$B$47)/(C$5/Calculateur_LCOE!$B$45)+Calculateur_LCOE!$B$56 -> 7.2198947 | D12: =$A12*Calculateur_LCOE!$B$45/1000+Calculateur_LCOE!$B$46*(Calculateur_LCOE!$B$12+Calculateur_LCOE!$B$47)/(D$5/Calculateur_LCOE!$B$45)+Calculateur_LCOE!$B$56 -> 6.4879859 | E12: =$A12*Calculateur_LCOE!$B$45/1000+Calculateur_LCOE!$B$46*(Calculateur_LCOE!$B$12+Calculateur_LCOE!$B$47)/(E$5/Calculateur_LCOE!$B$45)+Calculateur_LCOE!$B$56 -> 6.0000467 | F12: =$A12*Calculateur_LCOE!$B$45/1000+Calculateur_LCOE!$B$46*(Calculateur_LCOE!$B$12+Calculateur_LCOE!$B$47)/(F$5/Calculateur_LCOE!$B$45)+Calculateur_LCOE!$B$56 -> 5.6515187 | G12: =$A12*Calculateur_LCOE!$B$45/1000+Calculateur_LCOE!$B$46*(Calculateur_LCOE!$B$12+Calculateur_LCOE!$B$47)/(G$5/Calculateur_LCOE!$B$45)+Calculateur_LCOE!$B$56 -> 5.3901227
A13: 80 | B13: =$A13*Calculateur_LCOE!$B$45/1000+Calculateur_LCOE!$B$46*(Calculateur_LCOE!$B$12+Calculateur_LCOE!$B$47)/(B$5/Calculateur_LCOE!$B$45)+Calculateur_LCOE!$B$56 -> 9.6190929 | C13: =$A13*Calculateur_LCOE!$B$45/1000+Calculateur_LCOE!$B$46*(Calculateur_LCOE!$B$12+Calculateur_LCOE!$B$47)/(C$5/Calculateur_LCOE!$B$45)+Calculateur_LCOE!$B$56 -> 8.3992449 | D13: =$A13*Calculateur_LCOE!$B$45/1000+Calculateur_LCOE!$B$46*(Calculateur_LCOE!$B$12+Calculateur_LCOE!$B$47)/(D$5/Calculateur_LCOE!$B$45)+Calculateur_LCOE!$B$56 -> 7.6673361 | E13: =$A13*Calculateur_LCOE!$B$45/1000+Calculateur_LCOE!$B$46*(Calculateur_LCOE!$B$12+Calculateur_LCOE!$B$47)/(E$5/Calculateur_LCOE!$B$45)+Calculateur_LCOE!$B$56 -> 7.1793969 | F13: =$A13*Calculateur_LCOE!$B$45/1000+Calculateur_LCOE!$B$46*(Calculateur_LCOE!$B$12+Calculateur_LCOE!$B$47)/(F$5/Calculateur_LCOE!$B$45)+Calculateur_LCOE!$B$56 -> 6.8308689 | G13: =$A13*Calculateur_LCOE!$B$45/1000+Calculateur_LCOE!$B$46*(Calculateur_LCOE!$B$12+Calculateur_LCOE!$B$47)/(G$5/Calculateur_LCOE!$B$45)+Calculateur_LCOE!$B$56 -> 6.5694729
A14: Technologie d'électrolyse, WACC, vie, CAPEX et eau : issus du Calculateur_LCOE.
A16: 2. Coût de production du produit choisi (€/t) selon prix de l'électricité (lignes) et CAPEX électrolyseur (colonnes)
A17: Produit choisi | B17: e-methanol
A18: H2 (t/t produit) | B18: =INDEX(Calculateur_LCOE!$C$61:$C$66,MATCH($B$17,Calculateur_LCOE!$A$61:$A$66,0)) -> 0.19869899
A19: Autres coûts (€/t, hors H2) | B19: =INDEX(Calculateur_LCOE!$F$71:$F$76,MATCH($B$17,Calculateur_LCOE!$A$71:$A$76,0))-INDEX(Calculateur_LCOE!$B$71:$B$76,MATCH($B$17,Calculateur_LCOE!$A$71:$A$76,0))-INDEX(Calculateur_LCOE!$E$71:$E$76,MATCH($B$17,Calculateur_LCOE!$A$71:$A$76,0)) -> 174.35997
A20: Élec. synthèse + N2 (kWh/t) | B20: =INDEX(Calculateur_LCOE!$E$71:$E$76,MATCH($B$17,Calculateur_LCOE!$A$71:$A$76,0))/Calculateur_LCOE!$B$6*1000 -> 150
A21: Les coûts d'électricité de synthèse sont recalculés avec le prix de la ligne (colonne « élec. synthèse » ci-dessus).
A23: €/MWh \ CAPEX électrolyseur (€/kW) | B23: 800 | C23: 1200 | D23: 1600 | E23: 2000 | F23: 2500
A24: 15 | B24: =$B$18*1000*($A24*Calculateur_LCOE!$B$45/1000+B$23*(Calculateur_LCOE!$B$12+Calculateur_LCOE!$B$47)/(Calculateur_LCOE!$B$7/Calculateur_LCOE!$B$45)+Calculateur_LCOE!$B$56)+$B$19+$B$20/1000*$A24 -> 622.72104 | C24: =$B$18*1000*($A24*Calculateur_LCOE!$B$45/1000+C$23*(Calculateur_LCOE!$B$12+Calculateur_LCOE!$B$47)/(Calculateur_LCOE!$B$7/Calculateur_LCOE!$B$45)+Calculateur_LCOE!$B$56)+$B$19+$B$20/1000*$A24 -> 755.68519 | D24: =$B$18*1000*($A24*Calculateur_LCOE!$B$45/1000+D$23*(Calculateur_LCOE!$B$12+Calculateur_LCOE!$B$47)/(Calculateur_LCOE!$B$7/Calculateur_LCOE!$B$45)+Calculateur_LCOE!$B$56)+$B$19+$B$20/1000*$A24 -> 888.64934 | E24: =$B$18*1000*($A24*Calculateur_LCOE!$B$45/1000+E$23*(Calculateur_LCOE!$B$12+Calculateur_LCOE!$B$47)/(Calculateur_LCOE!$B$7/Calculateur_LCOE!$B$45)+Calculateur_LCOE!$B$56)+$B$19+$B$20/1000*$A24 -> 1021.6135 | F24: =$B$18*1000*($A24*Calculateur_LCOE!$B$45/1000+F$23*(Calculateur_LCOE!$B$12+Calculateur_LCOE!$B$47)/(Calculateur_LCOE!$B$7/Calculateur_LCOE!$B$45)+Calculateur_LCOE!$B$56)+$B$19+$B$20/1000*$A24 -> 1187.8187
A25: 20 | B25: =$B$18*1000*($A25*Calculateur_LCOE!$B$45/1000+B$23*(Calculateur_LCOE!$B$12+Calculateur_LCOE!$B$47)/(Calculateur_LCOE!$B$7/Calculateur_LCOE!$B$45)+Calculateur_LCOE!$B$56)+$B$19+$B$20/1000*$A25 -> 682.05497 | C25: =$B$18*1000*($A25*Calculateur_LCOE!$B$45/1000+C$23*(Calculateur_LCOE!$B$12+Calculateur_LCOE!$B$47)/(Calculateur_LCOE!$B$7/Calculateur_LCOE!$B$45)+Calculateur_LCOE!$B$56)+$B$19+$B$20/1000*$A25 -> 815.01912 | D25: =$B$18*1000*($A25*Calculateur_LCOE!$B$45/1000+D$23*(Calculateur_LCOE!$B$12+Calculateur_LCOE!$B$47)/(Calculateur_LCOE!$B$7/Calculateur_LCOE!$B$45)+Calculateur_LCOE!$B$56)+$B$19+$B$20/1000*$A25 -> 947.98327 | E25: =$B$18*1000*($A25*Calculateur_LCOE!$B$45/1000+E$23*(Calculateur_LCOE!$B$12+Calculateur_LCOE!$B$47)/(Calculateur_LCOE!$B$7/Calculateur_LCOE!$B$45)+Calculateur_LCOE!$B$56)+$B$19+$B$20/1000*$A25 -> 1080.9474 | F25: =$B$18*1000*($A25*Calculateur_LCOE!$B$45/1000+F$23*(Calculateur_LCOE!$B$12+Calculateur_LCOE!$B$47)/(Calculateur_LCOE!$B$7/Calculateur_LCOE!$B$45)+Calculateur_LCOE!$B$56)+$B$19+$B$20/1000*$A25 -> 1247.1526
A26: 25 | B26: =$B$18*1000*($A26*Calculateur_LCOE!$B$45/1000+B$23*(Calculateur_LCOE!$B$12+Calculateur_LCOE!$B$47)/(Calculateur_LCOE!$B$7/Calculateur_LCOE!$B$45)+Calculateur_LCOE!$B$56)+$B$19+$B$20/1000*$A26 -> 741.38889 | C26: =$B$18*1000*($A26*Calculateur_LCOE!$B$45/1000+C$23*(Calculateur_LCOE!$B$12+Calculateur_LCOE!$B$47)/(Calculateur_LCOE!$B$7/Calculateur_LCOE!$B$45)+Calculateur_LCOE!$B$56)+$B$19+$B$20/1000*$A26 -> 874.35305 | D26: =$B$18*1000*($A26*Calculateur_LCOE!$B$45/1000+D$23*(Calculateur_LCOE!$B$12+Calculateur_LCOE!$B$47)/(Calculateur_LCOE!$B$7/Calculateur_LCOE!$B$45)+Calculateur_LCOE!$B$56)+$B$19+$B$20/1000*$A26 -> 1007.3172 | E26: =$B$18*1000*($A26*Calculateur_LCOE!$B$45/1000+E$23*(Calculateur_LCOE!$B$12+Calculateur_LCOE!$B$47)/(Calculateur_LCOE!$B$7/Calculateur_LCOE!$B$45)+Calculateur_LCOE!$B$56)+$B$19+$B$20/1000*$A26 -> 1140.2813 | F26: =$B$18*1000*($A26*Calculateur_LCOE!$B$45/1000+F$23*(Calculateur_LCOE!$B$12+Calculateur_LCOE!$B$47)/(Calculateur_LCOE!$B$7/Calculateur_LCOE!$B$45)+Calculateur_LCOE!$B$56)+$B$19+$B$20/1000*$A26 -> 1306.4865
A27: 30 | B27: =$B$18*1000*($A27*Calculateur_LCOE!$B$45/1000+B$23*(Calculateur_LCOE!$B$12+Calculateur_LCOE!$B$47)/(Calculateur_LCOE!$B$7/Calculateur_LCOE!$B$45)+Calculateur_LCOE!$B$56)+$B$19+$B$20/1000*$A27 -> 800.72282 | C27: =$B$18*1000*($A27*Calculateur_LCOE!$B$45/1000+C$23*(Calculateur_LCOE!$B$12+Calculateur_LCOE!$B$47)/(Calculateur_LCOE!$B$7/Calculateur_LCOE!$B$45)+Calculateur_LCOE!$B$56)+$B$19+$B$20/1000*$A27 -> 933.68697 | D27: =$B$18*1000*($A27*Calculateur_LCOE!$B$45/1000+D$23*(Calculateur_LCOE!$B$12+Calculateur_LCOE!$B$47)/(Calculateur_LCOE!$B$7/Calculateur_LCOE!$B$45)+Calculateur_LCOE!$B$56)+$B$19+$B$20/1000*$A27 -> 1066.6511 | E27: =$B$18*1000*($A27*Calculateur_LCOE!$B$45/1000+E$23*(Calculateur_LCOE!$B$12+Calculateur_LCOE!$B$47)/(Calculateur_LCOE!$B$7/Calculateur_LCOE!$B$45)+Calculateur_LCOE!$B$56)+$B$19+$B$20/1000*$A27 -> 1199.6153 | F27: =$B$18*1000*($A27*Calculateur_LCOE!$B$45/1000+F$23*(Calculateur_LCOE!$B$12+Calculateur_LCOE!$B$47)/(Calculateur_LCOE!$B$7/Calculateur_LCOE!$B$45)+Calculateur_LCOE!$B$56)+$B$19+$B$20/1000*$A27 -> 1365.8205
