Workbook
Name Analysis_and_Graph: [1]!dd_analysis_graph[Analysis and Graph]
Name Analysis_and_Graph: [1]!dd_analysis_graph[Analysis and Graph]
Name Analysis_and_Graph: dd_analysis_graph[Analysis and Graph]
Name dd_components: [1]!Table3[Component of PtG]
Name dd_components: [1]!Table3[Component of PtG]
Name dd_components: Table3[Component of PtG]
Name temp: Library!$B$1:$F$138

Sheet Cockpit
B2: Economics of Converting Renewable Power to Hydrogen
C4: General Information
C6: Gunther Glenk
C7: TUM School of Management, Technical University of Munich
C9: Stefan Reichelstein
C10: Department of Business Administration, University of Mannheim
C11: Graduate School of Business, Stanford University
C13: December 2018
C15: Structure of this workbook
C17: Sheet | D17: Content
C19: Sources | D19: Overview and categorization of all sources used for the cost review
C21: Database | D21: Collection of all numericals (costs and operating performance measures) for sources used in the analysis
C23: Analysis | D23: Sheet collecting and illustrating the numericals based on filters
C25: Export | D25: Sheet enabling the export of numericals based on filters to use for further analysis in Matlab
C27: Library | D27: Bibliography of all sources
C29: Adjustment Factors | D29: List of conversion and adjustment factors for currencies and consumer price indeces
C31: Dropdowns | D31: List of used dropdowns

Sheet Sources
Z1: Checks | AG1: Secondary references
B2: Citekey | C2: Year | D2: In Library | E2: Type of Publication | F2: Method | G2: Reference to | H2: Analysis and Graph | I2: Type of Source | J2: Comment (temp) | L2: Analysis | T2: Abbreviations | Z2: In Database | AA2: Secondary reference listed | AG2: 1 | AH2: res. String | AI2: 2 | AJ2: res. String | AK2: 3 | AL2: res. String | AM2: 4 | AN2: res. String | AO2: 5
B3: hotellier2014hydrogen | C3: =IFERROR(VALUE(MID(Sources[[#This Row],[Citekey]],FIND("20",Sources[[#This Row],[Citekey]]),4)),"") -> 2014 | D3: yes | E3: Industry Statement | F3: No cost data | H3: =IFERROR(VLOOKUP(Sources[[#This Row],[Method]],dd_analysis_graph[],2,FALSE),"") -> Not in analysis, not in graph | I3: =IFERROR(VLOOKUP(Sources[[#This Row],[Type of Publication]],dd_type_source[],2,FALSE),"") -> Publication | M3: Original analysis, industry data | N3: Original review multiple sources | O3: No reference, unclear method | P3: Secondary source | Q3: No cost data | R3: Total | T3: AEL | U3: Alkaline Electrolyzer | Z3: =IF(OR(Sources[[#This Row],[Analysis and Graph]]="Analysis and Graph",Sources[[#This Row],[Analysis and Graph]]="Not in analysis, but extra in graph"),MATCH(Sources[[#This Row],[Citekey]],Database!$B$4:$B$2385,0),"") | AA3: =IF(AG3<>"",MATCH(AG3,Sources[Citekey],0),"") | AB3: =IF(AI3<>"",MATCH(AI3,Sources[Citekey],0),"") | AC3: =IF(AK3<>"",MATCH(AK3,Sources[Citekey],0),"") | AD3: =IF(AM3<>"",MATCH(AM3,Sources[Citekey],0),"") | AE3: =IF(AO3<>"",MATCH(AO3,Sources[Citekey],0),"") | AG3: =IFERROR(IF(Sources[[#This Row],[Reference to]]<>"",LEFT(Sources[[#This Row],[Reference to]],FIND(",",Sources[[#This Row],[Reference to]])-1),""),Sources[[#This Row],[Reference to]]) | AH3: =IFERROR(RIGHT(Sources[[#This Row],[Reference to]],LEN(Sources[[#This Row],[Reference to]])-LEN($AG3)-2),"") | AI3: =IFERROR(LEFT(AH3,FIND(",",AH3)-1),AH3) | AJ3: =IFERROR(RIGHT(Sources[[#This Row],[Reference to]],LEN(Sources[[#This Row],[Reference to]])-LEN($AG3)-2-LEN($AI3)-2),"") | AK3: =IFERROR(LEFT(AJ3,FIND(",",AJ3)-1),AJ3) | AL3: =IFERROR(RIGHT(Sources[[#This Row],[Reference to]],LEN(Sources[[#This Row],[Reference to]])-LEN($AG3)-2-LEN($AI3)-2-LEN($AK3)-2),"") | AM3: =IFERROR(LEFT(AL3,FIND(",",AL3)-1),AL3) | AN3: =IFERROR(RIGHT(Sources[[#This Row],[Reference to]],LEN(Sources[[#This Row],[Reference to]])-LEN($AG3)-2-LEN($AI3)-2-LEN($AK3)-2-LEN($AM3)-2),"") | AO3: =IFERROR(LEFT(AN3,FIND(",",AN3)-1),AN3)
B4: abbasi2011renewable | C4: =IFERROR(VALUE(MID(Sources[[#This Row],[Citekey]],FIND("20",Sources[[#This Row],[Citekey]]),4)),"") -> 2011 | D4: yes | E4: Journal Article | F4: Secondary source | G4: harrison2009wind | H4: =IFERROR(VLOOKUP(Sources[[#This Row],[Method]],dd_analysis_graph[],2,FALSE),"") -> Not in analysis, not in graph | I4: =IFERROR(VLOOKUP(Sources[[#This Row],[Type of Publication]],dd_type_source[],2,FALSE),"") -> Publication | L4: Report | M4: =COUNTIFS(Sources[Type of Publication],$L4,Sources[Method],M$3) -> 28 | N4: =COUNTIFS(Sources[Type of Publication],$L4,Sources[Method],N$3) -> 3 | O4: =COUNTIFS(Sources[Type of Publication],$L4,Sources[Method],O$3) -> 10 | P4: =COUNTIFS(Sources[Type of Publication],$L4,Sources[Method],P$3) -> 7 | Q4: =COUNTIFS(Sources[Type of Publication],$L4,Sources[Method],Q$3) -> 17 | R4: =SUM(M4:Q4) -> 65 | T4: PEM | U4: Polymer electrolyte membrane | Z4: =IF(OR(Sources[[#This Row],[Analysis and Graph]]="Analysis and Graph",Sources[[#This Row],[Analysis and Graph]]="Not in analysis, but extra in graph"),MATCH(Sources[[#This Row],[Citekey]],Database!$B$4:$B$2385,0),"") | AA4: =IF(AG4<>"",MATCH(AG4,Sources[Citekey],0),"") -> 125 | AB4: =IF(AI4<>"",MATCH(AI4,Sources[Citekey],0),"") | AC4: =IF(AK4<>"",MATCH(AK4,Sources[Citekey],0),"") | AD4: =IF(AM4<>"",MATCH(AM4,Sources[Citekey],0),"") | AE4: =IF(AO4<>"",MATCH(AO4,Sources[Citekey],0),"") | AG4: =IFERROR(IF(Sources[[#This Row],[Reference to]]<>"",LEFT(Sources[[#This Row],[Reference to]],FIND(",",Sources[[#This Row],[Reference to]])-1),""),Sources[[#This Row],[Reference to]]) -> harrison2009wind | AH4: =IFERROR(RIGHT(Sources[[#This Row],[Reference to]],LEN(Sources[[#This Row],[Reference to]])-LEN($AG4)-2),"") | AI4: =IFERROR(LEFT(AH4,FIND(",",AH4)-1),AH4) | AJ4: =IFERROR(RIGHT(Sources[[#This Row],[Reference to]],LEN(Sources[[#This Row],[Reference to]])-LEN($AG4)-2-LEN($AI4)-2),"") | AK4: =IFERROR(LEFT(AJ4,FIND(",",AJ4)-1),AJ4) | AL4: =IFERROR(RIGHT(Sources[[#This Row],[Reference to]],LEN(Sources[[#This Row],[Reference to]])-LEN($AG4)-2-LEN($AI4)-2-LEN($AK4)-2),"") | AM4: =IFERROR(LEFT(AL4,FIND(",",AL4)-1),AL4) | AN4: =IFERROR(RIGHT(Sources[[#This Row],[Reference to]],LEN(Sources[[#This Row],[Reference to]])-LEN($AG4)-2-LEN($AI4)-2-LEN($AK4)-2-LEN($AM4)-2),"") | AO4: =IFERROR(LEFT(AN4,FIND(",",AN4)-1),AN4)
B5: aguado2009economical | C5: 2009 | D5: yes | E5: Journal Article | F5: Secondary source | G5: smith2004low, greiner2007norwegian, lymberopoulos2005hydrogen | H5: =IFERROR(VLOOKUP(Sources[[#This Row],[Method]],dd_analysis_graph[],2,FALSE),"") -> Not in analysis, not in graph | I5: =IFERROR(VLOOKUP(Sources[[#This Row],[Type of Publication]],dd_type_source[],2,FALSE),"") -> Publication | L5: Journal Article | M5: =COUNTIFS(Sources[Type of Publication],$L5,Sources[Method],M$3) -> 18 | N5: =COUNTIFS(Sources[Type of Publication],$L5,Sources[Method],N$3) -> 6 | O5: =COUNTIFS(Sources[Type of Publication],$L5,Sources[Method],O$3) -> 5 | P5: =COUNTIFS(Sources[Type of Publication],$L5,Sources[Method],P$3) -> 29 | Q5: =COUNTIFS(Sources[Type of Publication],$L5,Sources[Method],Q$3) -> 22 | R5: =SUM(M5:Q5) -> 80 | T5: SOEC | U5: Solid oxide electrolyzer cell | Z5: =IF(OR(Sources[[#This Row],[Analysis and Graph]]="Analysis and Graph",Sources[[#This Row],[Analysis and Graph]]="Not in analysis, but extra in graph"),MATCH(Sources[[#This Row],[Citekey]],Database!$B$4:$B$2385,0),"") | AA5: =IF(AG5<>"",MATCH(AG5,Sources[Citekey],0),"") -> 149 | AB5: =IF(AI5<>"",MATCH(AI5,Sources[Citekey],0),"") -> 28 | AC5: =IF(AK5<>"",MATCH(AK5,Sources[Citekey],0),"") -> 135 | AD5: =IF(AM5<>"",MATCH(AM5,Sources[Citekey],0),"") | AE5: =IF(AO5<>"",MATCH(AO5,Sources[Citekey],0),"") | AG5: =IFERROR(IF(Sources[[#This Row],[Reference to]]<>"",LEFT(Sources[[#This Row],[Reference to]],FIND(",",Sources[[#This Row],[Reference to]])-1),""),Sources[[#This Row],[Reference to]]) -> smith2004low | AH5: =IFERROR(RIGHT(Sources[[#This Row],[Reference to]],LEN(Sources[[#This Row],[Reference to]])-LEN($AG5)-2),"") -> greiner2007norwegian, lymberopoulos2005hydrogen | AI5: =IFERROR(LEFT(AH5,FIND(",",AH5)-1),AH5) -> greiner2007norwegian | AJ5: =IFERROR(RIGHT(Sources[[#This Row],[Reference to]],LEN(Sources[[#This Row],[Reference to]])-LEN($AG5)-2-LEN($AI5)-2),"") -> lymberopoulos2005hydrogen | AK5: =IFERROR(LEFT(AJ5,FIND(",",AJ5)-1),AJ5) -> lymberopoulos2005hydrogen | AL5: =IFERROR(RIGHT(Sources[[#This Row],[Reference to]],LEN(Sources[[#This Row],[Reference to]])-LEN($AG5)-2-LEN($AI5)-2-LEN($AK5)-2),"") | AM5: =IFERROR(LEFT(AL5,FIND(",",AL5)-1),AL5) | AN5: =IFERROR(RIGHT(Sources[[#This Row],[Reference to]],LEN(Sources[[#This Row],[Reference to]])-LEN($AG5)-2-LEN($AI5)-2-LEN($AK5)-2-LEN($AM5)-2),"") | AO5: =IFERROR(LEFT(AN5,FIND(",",AN5)-1),AN5)
B6: badwal2013hydrogen | C6: =IFERROR(VALUE(MID(Sources[[#This Row],[Citekey]],FIND("20",Sources[[#This Row],[Citekey]]),4)),"") -> 2013 | D6: yes | E6: Journal Article | F6: Secondary source | G6: genovese2009current | H6: =IFERROR(VLOOKUP(Sources[[#This Row],[Method]],dd_analysis_graph[],2,FALSE),"") -> Not in analysis, not in graph | I6: =IFERROR(VLOOKUP(Sources[[#This Row],[Type of Publication]],dd_type_source[],2,FALSE),"") -> Publication | L6: News Article | M6: =COUNTIFS(Sources[Type of Publication],$L6,Sources[Method],M$3) -> 0 | N6: =COUNTIFS(Sources[Type of Publication],$L6,Sources[Method],N$3) -> 0 | O6: =COUNTIFS(Sources[Type of Publication],$L6,Sources[Method],O$3) -> 0 | P6: =COUNTIFS(Sources[Type of Publication],$L6,Sources[Method],P$3) -> 0 | Q6: =COUNTIFS(Sources[Type of Publication],$L6,Sources[Method],Q$3) -> 1 | R6: =SUM(M6:Q6) -> 1 | Z6: =IF(OR(Sources[[#This Row],[Analysis and Graph]]="Analysis and Graph",Sources[[#This Row],[Analysis and Graph]]="Not in analysis, but extra in graph"),MATCH(Sources[[#This Row],[Citekey]],Database!$B$4:$B$2385,0),"") | AA6: =IF(AG6<>"",MATCH(AG6,Sources[Citekey],0),"") -> 120 | AB6: =IF(AI6<>"",MATCH(AI6,Sources[Citekey],0),"") | AC6: =IF(AK6<>"",MATCH(AK6,Sources[Citekey],0),"") | AD6: =IF(AM6<>"",MATCH(AM6,Sources[Citekey],0),"") | AE6: =IF(AO6<>"",MATCH(AO6,Sources[Citekey],0),"") | AG6: =IFERROR(IF(Sources[[#This Row],[Reference to]]<>"",LEFT(Sources[[#This Row],[Reference to]],FIND(",",Sources[[#This Row],[Reference to]])-1),""),Sources[[#This Row],[Reference to]]) -> genovese2009current | AH6: =IFERROR(RIGHT(Sources[[#This Row],[Reference to]],LEN(Sources[[#This Row],[Reference to]])-LEN($AG6)-2),"") | AI6: =IFERROR(LEFT(AH6,FIND(",",AH6)-1),AH6) | AJ6: =IFERROR(RIGHT(Sources[[#This Row],[Reference to]],LEN(Sources[[#This Row],[Reference to]])-LEN($AG6)-2-LEN($AI6)-2),"") | AK6: =IFERROR(LEFT(AJ6,FIND(",",AJ6)-1),AJ6) | AL6: =IFERROR(RIGHT(Sources[[#This Row],[Reference to]],LEN(Sources[[#This Row],[Reference to]])-LEN($AG6)-2-LEN($AI6)-2-LEN($AK6)-2),"") | AM6: =IFERROR(LEFT(AL6,FIND(",",AL6)-1),AL6) | AN6: =IFERROR(RIGHT(Sources[[#This Row],[Reference to]],LEN(Sources[[#This Row],[Reference to]])-LEN($AG6)-2-LEN($AI6)-2-LEN($AK6)-2-LEN($AM6)-2),"") | AO6: =IFERROR(LEFT(AN6,FIND(",",AN6)-1),AN6)
B7: bajohr2011speicherung | C7: =IFERROR(VALUE(MID(Sources[[#This Row],[Citekey]],FIND("20",Sources[[#This Row],[Citekey]]),4)),"") -> 2011 | D7: yes | E7: Journal Article | F7: Secondary source | G7: wenske2008wasserstoff | H7: =IFERROR(VLOOKUP(Sources[[#This Row],[Method]],dd_analysis_graph[],2,FALSE),"") -> Not in analysis, not in graph | I7: =IFERROR(VLOOKUP(Sources[[#This Row],[Type of Publication]],dd_type_source[],2,FALSE),"") -> Publication | L7: Industry Statement | M7: =COUNTIFS(Sources[Type of Publication],$L7,Sources[Method],M$3) -> 0 | N7: =COUNTIFS(Sources[Type of Publication],$L7,Sources[Method],N$3) -> 0 | O7: =COUNTIFS(Sources[Type of Publication],$L7,Sources[Method],O$3) -> 0 | P7: =COUNTIFS(Sources[Type of Publication],$L7,Sources[Method],P$3) -> 0 | Q7: =COUNTIFS(Sources[Type of Publication],$L7,Sources[Method],Q$3) -> 1 | R7: =SUM(M7:Q7) -> 1 | Z7: =IF(OR(Sources[[#This Row],[Analysis and Graph]]="Analysis and Graph",Sources[[#This Row],[Analysis and Graph]]="Not in analysis, but extra in graph"),MATCH(Sources[[#This Row],[Citekey]],Database!$B$4:$B$2385,0),"") | AA7: =IF(AG7<>"",MATCH(AG7,Sources[Citekey],0),"") -> 164 | AB7: =IF(AI7<>"",MATCH(AI7,Sources[Citekey],0),"") | AC7: =IF(AK7<>"",MATCH(AK7,Sources[Citekey],0),"") | AD7: =IF(AM7<>"",MATCH(AM7,Sources[Citekey],0),"") | AE7: =IF(AO7<>"",MATCH(AO7,Sources[Citekey],0),"") | AG7: =IFERROR(IF(Sources[[#This Row],[Reference to]]<>"",LEFT(Sources[[#This Row],[Reference to]],FIND(",",Sources[[#This Row],[Reference to]])-1),""),Sources[[#This Row],[Reference to]]) -> wenske2008wasserstoff | AH7: =IFERROR(RIGHT(Sources[[#This Row],[Reference to]],LEN(Sources[[#This Row],[Reference to]])-LEN($AG7)-2),"") | AI7: =IFERROR(LEFT(AH7,FIND(",",AH7)-1),AH7) | AJ7: =IFERROR(RIGHT(Sources[[#This Row],[Reference to]],LEN(Sources[[#This Row],[Reference to]])-LEN($AG7)-2-LEN($AI7)-2),"") | AK7: =IFERROR(LEFT(AJ7,FIND(",",AJ7)-1),AJ7) | AL7: =IFERROR(RIGHT(Sources[[#This Row],[Reference to]],LEN(Sources[[#This Row],[Reference to]])-LEN($AG7)-2-LEN($AI7)-2-LEN($AK7)-2),"") | AM7: =IFERROR(LEFT(AL7,FIND(",",AL7)-1),AL7) | AN7: =IFERROR(RIGHT(Sources[[#This Row],[Reference to]],LEN(Sources[[#This Row],[Reference to]])-LEN($AG7)-2-LEN($AI7)-2-LEN($AK7)-2-LEN($AM7)-2),"") | AO7: =IFERROR(LEFT(AN7,FIND(",",AN7)-1),AN7)
B8: balan2016technical | C8: =IFERROR(VALUE(MID(Sources[[#This Row],[Citekey]],FIND("20",Sources[[#This Row],[Citekey]]),4)),"") -> 2016 | D8: yes | E8: Journal Article | F8: Secondary source | G8: bertuccioli2014development | H8: =IFERROR(VLOOKUP(Sources[[#This Row],[Method]],dd_analysis_graph[],2,FALSE),"") -> Not in analysis, not in graph | I8: =IFERROR(VLOOKUP(Sources[[#This Row],[Type of Publication]],dd_type_source[],2,FALSE),"") -> Publication | L8: Manufacturer Interview | M8: =COUNTIFS(Sources[Type of Publication],$L8,Sources[Method],M$3) -> 17 | N8: =COUNTIFS(Sources[Type of Publication],$L8,Sources[Method],N$3) -> 1 | O8: =COUNTIFS(Sources[Type of Publication],$L8,Sources[Method],O$3) -> 0 | P8: =COUNTIFS(Sources[Type of Publication],$L8,Sources[Method],P$3) -> 0 | Q8: =COUNTIFS(Sources[Type of Publication],$L8,Sources[Method],Q$3) -> 0 | R8: =SUM(M8:Q8) -> 18 | Z8: =IF(OR(Sources[[#This Row],[Analysis and Graph]]="Analysis and Graph",Sources[[#This Row],[Analysis and Graph]]="Not in analysis, but extra in graph"),MATCH(Sources[[#This Row],[Citekey]],Database!$B$4:$B$2385,0),"") | AA8: =IF(AG8<>"",MATCH(AG8,Sources[Citekey],0),"") -> 106 | AB8: =IF(AI8<>"",MATCH(AI8,Sources[Citekey],0),"") | AC8: =IF(AK8<>"",MATCH(AK8,Sources[Citekey],0),"") | AD8: =IF(AM8<>"",MATCH(AM8,Sources[Citekey],0),"") | AE8: =IF(AO8<>"",MATCH(AO8,Sources[Citekey],0),"") | AG8: =IFERROR(IF(Sources[[#This Row],[Reference to]]<>"",LEFT(Sources[[#This Row],[Reference to]],FIND(",",Sources[[#This Row],[Reference to]])-1),""),Sources[[#This Row],[Reference to]]) -> bertuccioli2014development | AH8: =IFERROR(RIGHT(Sources[[#This Row],[Reference to]],LEN(Sources[[#This Row],[Reference to]])-LEN($AG8)-2),"") | AI8: =IFERROR(LEFT(AH8,FIND(",",AH8)-1),AH8) | AJ8: =IFERROR(RIGHT(Sources[[#This Row],[Reference to]],LEN(Sources[[#This Row],[Reference to]])-LEN($AG8)-2-LEN($AI8)-2),"") | AK8: =IFERROR(LEFT(AJ8,FIND(",",AJ8)-1),AJ8) | AL8: =IFERROR(RIGHT(Sources[[#This Row],[Reference to]],LEN(Sources[[#This Row],[Reference to]])-LEN($AG8)-2-LEN($AI8)-2-LEN($AK8)-2),"") | AM8: =IFERROR(LEFT(AL8,FIND(",",AL8)-1),AL8) | AN8: =IFERROR(RIGHT(Sources[[#This Row],[Reference to]],LEN(Sources[[#This Row],[Reference to]])-LEN($AG8)-2-LEN($AI8)-2-LEN($AK8)-2-LEN($AM8)-2),"") | AO8: =IFERROR(LEFT(AN8,FIND(",",AN8)-1),AN8)
B9: barbir1997efficiency | C9: 1997 | D9: yes | E9: Journal Article | F9: No cost data | H9: =IFERROR(VLOOKUP(Sources[[#This Row],[Method]],dd_analysis_graph[],2,FALSE),"") -> Not in analysis, not in graph | I9: =IFERROR(VLOOKUP(Sources[[#This Row],[Type of Publication]],dd_type_source[],2,FALSE),"") -> Publication | J9: Excluded due to age | L9: Total | M9: =SUM(M4:M8) -> 63 | N9: =SUM(N4:N8) -> 10 | O9: =SUM(O4:O8) -> 15 | P9: =SUM(P4:P8) -> 36 | Q9: =SUM(Q4:Q8) -> 41 | R9: =SUM(R4:R8) -> 165 | Z9: =IF(OR(Sources[[#This Row],[Analysis and Graph]]="Analysis and Graph",Sources[[#This Row],[Analysis and Graph]]="Not in analysis, but extra in graph"),MATCH(Sources[[#This Row],[Citekey]],Database!$B$4:$B$2385,0),"") | AA9: =IF(AG9<>"",MATCH(AG9,Sources[Citekey],0),"") | AB9: =IF(AI9<>"",MATCH(AI9,Sources[Citekey],0),"") | AC9: =IF(AK9<>"",MATCH(AK9,Sources[Citekey],0),"") | AD9: =IF(AM9<>"",MATCH(AM9,Sources[Citekey],0),"") | AE9: =IF(AO9<>"",MATCH(AO9,Sources[Citekey],0),"") | AG9: =IFERROR(IF(Sources[[#This Row],[Reference to]]<>"",LEFT(Sources[[#This Row],[Reference to]],FIND(",",Sources[[#This Row],[Reference to]])-1),""),Sources[[#This Row],[Reference to]]) | AH9: =IFERROR(RIGHT(Sources[[#This Row],[Reference to]],LEN(Sources[[#This Row],[Reference to]])-LEN($AG9)-2),"") | AI9: =IFERROR(LEFT(AH9,FIND(",",AH9)-1),AH9) | AJ9: =IFERROR(RIGHT(Sources[[#This Row],[Reference to]],LEN(Sources[[#This Row],[Reference to]])-LEN($AG9)-2-LEN($AI9)-2),"") | AK9: =IFERROR(LEFT(AJ9,FIND(",",AJ9)-1),AJ9) | AL9: =IFERROR(RIGHT(Sources[[#This Row],[Reference to]],LEN(Sources[[#This Row],[Reference to]])-LEN($AG9)-2-LEN($AI9)-2-LEN($AK9)-2),"") | AM9: =IFERROR(LEFT(AL9,FIND(",",AL9)-1),AL9) | AN9: =IFERROR(RIGHT(Sources[[#This Row],[Reference to]],LEN(Sources[[#This Row],[Reference to]])-LEN($AG9)-2-LEN($AI9)-2-LEN($AK9)-2-LEN($AM9)-2),"") | AO9: =IFERROR(LEFT(AN9,FIND(",",AN9)-1),AN9)
B10: bernal-agustin2008hourly | C10: =IFERROR(VALUE(MID(Sources[[#This Row],[Citekey]],FIND("20",Sources[[#This Row],[Citekey]]),4)),"") -> 2008 | D10: yes | E10: Journal Article | F10: Secondary source | G10: lipman2004fuel, greiner2007norwegian, lymberopoulos2005hydrogen, briguglio2008new | H10: =IFERROR(VLOOKUP(Sources[[#This Row],[Method]],dd_analysis_graph[],2,FALSE),"") -> Not in analysis, not in graph | I10: =IFERROR(VLOOKUP(Sources[[#This Row],[Type of Publication]],dd_type_source[],2,FALSE),"") -> Publication | Z10: =IF(OR(Sources[[#This Row],[Analysis and Graph]]="Analysis and Graph",Sources[[#This Row],[Analysis and Graph]]="Not in analysis, but extra in graph"),MATCH(Sources[[#This Row],[Citekey]],Database!$B$4:$B$2385,0),"") | AA10: =IF(AG10<>"",MATCH(AG10,Sources[Citekey],0),"") -> 46 | AB10: =IF(AI10<>"",MATCH(AI10,Sources[Citekey],0),"") -> 28 | AC10: =IF(AK10<>"",MATCH(AK10,Sources[Citekey],0),"") -> 135 | AD10: =IF(AM10<>"",MATCH(AM10,Sources[Citekey],0),"") -> 12 | AE10: =IF(AO10<>"",MATCH(AO10,Sources[Citekey],0),"") | AG10: =IFERROR(IF(Sources[[#This Row],[Reference to]]<>"",LEFT(Sources[[#This Row],[Reference to]],FIND(",",Sources[[#This Row],[Reference to]])-1),""),Sources[[#This Row],[Reference to]]) -> lipman2004fuel | AH10: =IFERROR(RIGHT(Sources[[#This Row],[Reference to]],LEN(Sources[[#This Row],[Reference to]])-LEN($AG10)-2),"") -> greiner2007norwegian, lymberopoulos2005hydrogen, briguglio2008new | AI10: =IFERROR(LEFT(AH10,FIND(",",AH10)-1),AH10) -> greiner2007norwegian | AJ10: =IFERROR(RIGHT(Sources[[#This Row],[Reference to]],LEN(Sources[[#This Row],[Reference to]])-LEN($AG10)-2-LEN($AI10)-2),"") -> lymberopoulos2005hydrogen, briguglio2008new | AK10: =IFERROR(LEFT(AJ10,FIND(",",AJ10)-1),AJ10) -> lymberopoulos2005hydrogen | AL10: =IFERROR(RIGHT(Sources[[#This Row],[Reference to]],LEN(Sources[[#This Row],[Reference to]])-LEN($AG10)-2-LEN($AI10)-2-LEN($AK10)-2),"") -> briguglio2008new | AM10: =IFERROR(LEFT(AL10,FIND(",",AL10)-1),AL10) -> briguglio2008new | AN10: =IFERROR(RIGHT(Sources[[#This Row],[Reference to]],LEN(Sources[[#This Row],[Reference to]])-LEN($AG10)-2-LEN($AI10)-2-LEN($AK10)-2-LEN($AM10)-2),"") | AO10: =IFERROR(LEFT(AN10,FIND(",",AN10)-1),AN10)
B11: bernal-agustin2009simulation | C11: =IFERROR(VALUE(MID(Sources[[#This Row],[Citekey]],FIND("20",Sources[[#This Row],[Citekey]]),4)),"") -> 2009 | D11: yes | E11: Journal Article | F11: No cost data | H11: =IFERROR(VLOOKUP(Sources[[#This Row],[Method]],dd_analysis_graph[],2,FALSE),"") -> Not in analysis, not in graph | I11: =IFERROR(VLOOKUP(Sources[[#This Row],[Type of Publication]],dd_type_source[],2,FALSE),"") -> Publication | Z11: =IF(OR(Sources[[#This Row],[Analysis and Graph]]="Analysis and Graph",Sources[[#This Row],[Analysis and Graph]]="Not in analysis, but extra in graph"),MATCH(Sources[[#This Row],[Citekey]],Database!$B$4:$B$2385,0),"") | AA11: =IF(AG11<>"",MATCH(AG11,Sources[Citekey],0),"") | AB11: =IF(AI11<>"",MATCH(AI11,Sources[Citekey],0),"") | AC11: =IF(AK11<>"",MATCH(AK11,Sources[Citekey],0),"") | AD11: =IF(AM11<>"",MATCH(AM11,Sources[Citekey],0),"") | AE11: =IF(AO11<>"",MATCH(AO11,Sources[Citekey],0),"") | AG11: =IFERROR(IF(Sources[[#This Row],[Reference to]]<>"",LEFT(Sources[[#This Row],[Reference to]],FIND(",",Sources[[#This Row],[Reference to]])-1),""),Sources[[#This Row],[Reference to]]) | AH11: =IFERROR(RIGHT(Sources[[#This Row],[Reference to]],LEN(Sources[[#This Row],[Reference to]])-LEN($AG11)-2),"") | AI11: =IFERROR(LEFT(AH11,FIND(",",AH11)-1),AH11) | AJ11: =IFERROR(RIGHT(Sources[[#This Row],[Reference to]],LEN(Sources[[#This Row],[Reference to]])-LEN($AG11)-2-LEN($AI11)-2),"") | AK11: =IFERROR(LEFT(AJ11,FIND(",",AJ11)-1),AJ11) | AL11: =IFERROR(RIGHT(Sources[[#This Row],[Reference to]],LEN(Sources[[#This Row],[Reference to]])-LEN($AG11)-2-LEN($AI11)-2-LEN($AK11)-2),"") | AM11: =IFERROR(LEFT(AL11,FIND(",",AL11)-1),AL11) | AN11: =IFERROR(RIGHT(Sources[[#This Row],[Reference to]],LEN(Sources[[#This Row],[Reference to]])-LEN($AG11)-2-LEN($AI11)-2-LEN($AK11)-2-LEN($AM11)-2),"") | AO11: =IFERROR(LEFT(AN11,FIND(",",AN11)-1),AN11)
B12: bernal-agustin2010techno | C12: =IFERROR(VALUE(MID(Sources[[#This Row],[Citekey]],FIND("20",Sources[[#This Row],[Citekey]]),4)),"") -> 2010 | D12: yes | E12: Journal Article | F12: Secondary source | G12: linnemann2007realistic | H12: =IFERROR(VLOOKUP(Sources[[#This Row],[Method]],dd_analysis_graph[],2,FALSE),"") -> Not in analysis, not in graph | I12: =IFERROR(VLOOKUP(Sources[[#This Row],[Type of Publication]],dd_type_source[],2,FALSE),"") -> Publication | Z12: =IF(OR(Sources[[#This Row],[Analysis and Graph]]="Analysis and Graph",Sources[[#This Row],[Analysis and Graph]]="Not in analysis, but extra in graph"),MATCH(Sources[[#This Row],[Citekey]],Database!$B$4:$B$2385,0),"") | AA12: =IF(AG12<>"",MATCH(AG12,Sources[Citekey],0),"") -> 45 | AB12: =IF(AI12<>"",MATCH(AI12,Sources[Citekey],0),"") | AC12: =IF(AK12<>"",MATCH(AK12,Sources[Citekey],0),"") | AD12: =IF(AM12<>"",MATCH(AM12,Sources[Citekey],0),"") | AE12: =IF(AO12<>"",MATCH(AO12,Sources[Citekey],0),"") | AG12: =IFERROR(IF(Sources[[#This Row],[Reference to]]<>"",LEFT(Sources[[#This Row],[Reference to]],FIND(",",Sources[[#This Row],[Reference to]])-1),""),Sources[[#This Row],[Reference to]]) -> linnemann2007realistic | AH12: =IFERROR(RIGHT(Sources[[#This Row],[Reference to]],LEN(Sources[[#This Row],[Reference to]])-LEN($AG12)-2),"") | AI12: =IFERROR(LEFT(AH12,FIND(",",AH12)-1),AH12) | AJ12: =IFERROR(RIGHT(Sources[[#This Row],[Reference to]],LEN(Sources[[#This Row],[Reference to]])-LEN($AG12)-2-LEN($AI12)-2),"") | AK12: =IFERROR(LEFT(AJ12,FIND(",",AJ12)-1),AJ12) | AL12: =IFERROR(RIGHT(Sources[[#This Row],[Reference to]],LEN(Sources[[#This Row],[Reference to]])-LEN($AG12)-2-LEN($AI12)-2-LEN($AK12)-2),"") | AM12: =IFERROR(LEFT(AL12,FIND(",",AL12)-1),AL12) | AN12: =IFERROR(RIGHT(Sources[[#This Row],[Reference to]],LEN(Sources[[#This Row],[Reference to]])-LEN($AG12)-2-LEN($AI12)-2-LEN($AK12)-2-LEN($AM12)-2),"") | AO12: =IFERROR(LEFT(AN12,FIND(",",AN12)-1),AN12)
B13: bockris2007estimates | C13: =IFERROR(VALUE(MID(Sources[[#This Row],[Citekey]],FIND("20",Sources[[#This Row],[Citekey]]),4)),"") -> 2007 | D13: yes | E13: Journal Article | F13: No cost data | H13: =IFERROR(VLOOKUP(Sources[[#This Row],[Method]],dd_analysis_graph[],2,FALSE),"") -> Not in analysis, not in graph | I13: =IFERROR(VLOOKUP(Sources[[#This Row],[Type of Publication]],dd_type_source[],2,FALSE),"") -> Publication | Z13: =IF(OR(Sources[[#This Row],[Analysis and Graph]]="Analysis and Graph",Sources[[#This Row],[Analysis and Graph]]="Not in analysis, but extra in graph"),MATCH(Sources[[#This Row],[Citekey]],Database!$B$4:$B$2385,0),"") | AA13: =IF(AG13<>"",MATCH(AG13,Sources[Citekey],0),"") | AB13: =IF(AI13<>"",MATCH(AI13,Sources[Citekey],0),"") | AC13: =IF(AK13<>"",MATCH(AK13,Sources[Citekey],0),"") | AD13: =IF(AM13<>"",MATCH(AM13,Sources[Citekey],0),"") | AE13: =IF(AO13<>"",MATCH(AO13,Sources[Citekey],0),"") | AG13: =IFERROR(IF(Sources[[#This Row],[Reference to]]<>"",LEFT(Sources[[#This Row],[Reference to]],FIND(",",Sources[[#This Row],[Reference to]])-1),""),Sources[[#This Row],[Reference to]]) | AH13: =IFERROR(RIGHT(Sources[[#This Row],[Reference to]],LEN(Sources[[#This Row],[Reference to]])-LEN($AG13)-2),"") | AI13: =IFERROR(LEFT(AH13,FIND(",",AH13)-1),AH13) | AJ13: =IFERROR(RIGHT(Sources[[#This Row],[Reference to]],LEN(Sources[[#This Row],[Reference to]])-LEN($AG13)-2-LEN($AI13)-2),"") | AK13: =IFERROR(LEFT(AJ13,FIND(",",AJ13)-1),AJ13) | AL13: =IFERROR(RIGHT(Sources[[#This Row],[Reference to]],LEN(Sources[[#This Row],[Reference to]])-LEN($AG13)-2-LEN($AI13)-2-LEN($AK13)-2),"") | AM13: =IFERROR(LEFT(AL13,FIND(",",AL13)-1),AL13) | AN13: =IFERROR(RIGHT(Sources[[#This Row],[Reference to]],LEN(Sources[[#This Row],[Reference to]])-LEN($AG13)-2-LEN($AI13)-2-LEN($AK13)-2-LEN($AM13)-2),"") | AO13: =IFERROR(LEFT(AN13,FIND(",",AN13)-1),AN13)
B14: briguglio2008new | C14: =IFERROR(VALUE(MID(Sources[[#This Row],[Citekey]],FIND("20",Sources[[#This Row],[Citekey]]),4)),"") -> 2008 | D14: yes | E14: Journal Article | F14: Secondary source | G14: brunetto2007optimal, levene2005economic | H14: =IFERROR(VLOOKUP(Sources[[#This Row],[Method]],dd_analysis_graph[],2,FALSE),"") -> Not in analysis, not in graph | I14: =IFERROR(VLOOKUP(Sources[[#This Row],[Type of Publication]],dd_type_source[],2,FALSE),"") -> Publication | Z14: =IF(OR(Sources[[#This Row],[Analysis and Graph]]="Analysis and Graph",Sources[[#This Row],[Analysis and Graph]]="Not in analysis, but extra in graph"),MATCH(Sources[[#This Row],[Citekey]],Database!$B$4:$B$2385,0),"") | AA14: =IF(AG14<>"",MATCH(AG14,Sources[Citekey],0),"") -> 14 | AB14: =IF(AI14<>"",MATCH(AI14,Sources[Citekey],0),"") -> 133 | AC14: =IF(AK14<>"",MATCH(AK14,Sources[Citekey],0),"") | AD14: =IF(AM14<>"",MATCH(AM14,Sources[Citekey],0),"") | AE14: =IF(AO14<>"",MATCH(AO14,Sources[Citekey],0),"") | AG14: =IFERROR(IF(Sources[[#This Row],[Reference to]]<>"",LEFT(Sources[[#This Row],[Reference to]],FIND(",",Sources[[#This Row],[Reference to]])-1),""),Sources[[#This Row],[Reference to]]) -> brunetto2007optimal | AH14: =IFERROR(RIGHT(Sources[[#This Row],[Reference to]],LEN(Sources[[#This Row],[Reference to]])-LEN($AG14)-2),"") -> levene2005economic | AI14: =IFERROR(LEFT(AH14,FIND(",",AH14)-1),AH14) -> levene2005economic | AJ14: =IFERROR(RIGHT(Sources[[#This Row],[Reference to]],LEN(Sources[[#This Row],[Reference to]])-LEN($AG14)-2-LEN($AI14)-2),"") | AK14: =IFERROR(LEFT(AJ14,FIND(",",AJ14)-1),AJ14) | AL14: =IFERROR(RIGHT(Sources[[#This Row],[Reference to]],LEN(Sources[[#This Row],[Reference to]])-LEN($AG14)-2-LEN($AI14)-2-LEN($AK14)-2),"") | AM14: =IFERROR(LEFT(AL14,FIND(",",AL14)-1),AL14) | AN14: =IFERROR(RIGHT(Sources[[#This Row],[Reference to]],LEN(Sources[[#This Row],[Reference to]])-LEN($AG14)-2-LEN($AI14)-2-LEN($AK14)-2-LEN($AM14)-2),"") | AO14: =IFERROR(LEFT(AN14,FIND(",",AN14)-1),AN14)
B15: brisse2012high | C15: 2012 | D15: yes | E15: Journal Article | F15: Original analysis, industry data | H15: =IFERROR(VLOOKUP(Sources[[#This Row],[Method]],dd_analysis_graph[],2,FALSE),"") -> Analysis and Graph | I15: =IFERROR(VLOOKUP(Sources[[#This Row],[Type of Publication]],dd_type_source[],2,FALSE),"") -> Publication | Z15: =IF(OR(Sources[[#This Row],[Analysis and Graph]]="Analysis and Graph",Sources[[#This Row],[Analysis and Graph]]="Not in analysis, but extra in graph"),MATCH(Sources[[#This Row],[Citekey]],Database!$B$4:$B$2385,0),"") -> 241 | AA15: =IF(AG15<>"",MATCH(AG15,Sources[Citekey],0),"") | AB15: =IF(AI15<>"",MATCH(AI15,Sources[Citekey],0),"") | AC15: =IF(AK15<>"",MATCH(AK15,Sources[Citekey],0),"") | AD15: =IF(AM15<>"",MATCH(AM15,Sources[Citekey],0),"") | AE15: =IF(AO15<>"",MATCH(AO15,Sources[Citekey],0),"") | AG15: =IFERROR(IF(Sources[[#This Row],[Reference to]]<>"",LEFT(Sources[[#This Row],[Reference to]],FIND(",",Sources[[#This Row],[Reference to]])-1),""),Sources[[#This Row],[Reference to]]) | AH15: =IFERROR(RIGHT(Sources[[#This Row],[Reference to]],LEN(Sources[[#This Row],[Reference to]])-LEN($AG15)-2),"") | AI15: =IFERROR(LEFT(AH15,FIND(",",AH15)-1),AH15) | AJ15: =IFERROR(RIGHT(Sources[[#This Row],[Reference to]],LEN(Sources[[#This Row],[Reference to]])-LEN($AG15)-2-LEN($AI15)-2),"") | AK15: =IFERROR(LEFT(AJ15,FIND(",",AJ15)-1),AJ15) | AL15: =IFERROR(RIGHT(Sources[[#This Row],[Reference to]],LEN(Sources[[#This Row],[Reference to]])-LEN($AG15)-2-LEN($AI15)-2-LEN($AK15)-2),"") | AM15: =IFERROR(LEFT(AL15,FIND(",",AL15)-1),AL15) | AN15: =IFERROR(RIGHT(Sources[[#This Row],[Reference to]],LEN(Sources[[#This Row],[Reference to]])-LEN($AG15)-2-LEN($AI15)-2-LEN($AK15)-2-LEN($AM15)-2),"") | AO15: =IFERROR(LEFT(AN15,FIND(",",AN15)-1),AN15)
B16: brunetto2007optimal | C16: 2007 | D16: yes | E16: Journal Article | F16: Original analysis, industry data | H16: =IFERROR(VLOOKUP(Sources[[#This Row],[Method]],dd_analysis_graph[],2,FALSE),"") -> Analysis and Graph | I16: =IFERROR(VLOOKUP(Sources[[#This Row],[Type of Publication]],dd_type_source[],2,FALSE),"") -> Publication | Z16: =IF(OR(Sources[[#This Row],[Analysis and Graph]]="Analysis and Graph",Sources[[#This Row],[Analysis and Graph]]="Not in analysis, but extra in graph"),MATCH(Sources[[#This Row],[Citekey]],Database!$B$4:$B$2385,0),"") -> 193 | AA16: =IF(AG16<>"",MATCH(AG16,Sources[Citekey],0),"") | AB16: =IF(AI16<>"",MATCH(AI16,Sources[Citekey],0),"") | AC16: =IF(AK16<>"",MATCH(AK16,Sources[Citekey],0),"") | AD16: =IF(AM16<>"",MATCH(AM16,Sources[Citekey],0),"") | AE16: =IF(AO16<>"",MATCH(AO16,Sources[Citekey],0),"") | AG16: =IFERROR(IF(Sources[[#This Row],[Reference to]]<>"",LEFT(Sources[[#This Row],[Reference to]],FIND(",",Sources[[#This Row],[Reference to]])-1),""),Sources[[#This Row],[Reference to]]) | AH16: =IFERROR(RIGHT(Sources[[#This Row],[Reference to]],LEN(Sources[[#This Row],[Reference to]])-LEN($AG16)-2),"") | AI16: =IFERROR(LEFT(AH16,FIND(",",AH16)-1),AH16) | AJ16: =IFERROR(RIGHT(Sources[[#This Row],[Reference to]],LEN(Sources[[#This Row],[Reference to]])-LEN($AG16)-2-LEN($AI16)-2),"") | AK16: =IFERROR(LEFT(AJ16,FIND(",",AJ16)-1),AJ16) | AL16: =IFERROR(RIGHT(Sources[[#This Row],[Reference to]],LEN(Sources[[#This Row],[Reference to]])-LEN($AG16)-2-LEN($AI16)-2-LEN($AK16)-2),"") | AM16: =IFERROR(LEFT(AL16,FIND(",",AL16)-1),AL16) | AN16: =IFERROR(RIGHT(Sources[[#This Row],[Reference to]],LEN(Sources[[#This Row],[Reference to]])-LEN($AG16)-2-LEN($AI16)-2-LEN($AK16)-2-LEN($AM16)-2),"") | AO16: =IFERROR(LEFT(AN16,FIND(",",AN16)-1),AN16)
B17: buchholz2014power | C17: =IFERROR(VALUE(MID(Sources[[#This Row],[Citekey]],FIND("20",Sources[[#This Row],[Citekey]]),4)),"") -> 2014 | D17: yes | E17: Journal Article | F17: Secondary source | G17: seider2003product | H17: =IFERROR(VLOOKUP(Sources[[#This Row],[Method]],dd_analysis_graph[],2,FALSE),"") -> Not in analysis, not in graph | I17: =IFERROR(VLOOKUP(Sources[[#This Row],[Type of Publication]],dd_type_source[],2,FALSE),"") -> Publication | Z17: =IF(OR(Sources[[#This Row],[Analysis and Graph]]="Analysis and Graph",Sources[[#This Row],[Analysis and Graph]]="Not in analysis, but extra in graph"),MATCH(Sources[[#This Row],[Citekey]],Database!$B$4:$B$2385,0),"") | AA17: =IF(AG17<>"",MATCH(AG17,Sources[Citekey],0),"") -> 146 | AB17: =IF(AI17<>"",MATCH(AI17,Sources[Citekey],0),"") | AC17: =IF(AK17<>"",MATCH(AK17,Sources[Citekey],0),"") | AD17: =IF(AM17<>"",MATCH(AM17,Sources[Citekey],0),"") | AE17: =IF(AO17<>"",MATCH(AO17,Sources[Citekey],0),"") | AG17: =IFERROR(IF(Sources[[#This Row],[Reference to]]<>"",LEFT(Sources[[#This Row],[Reference to]],FIND(",",Sources[[#This Row],[Reference to]])-1),""),Sources[[#This Row],[Reference to]]) -> seider2003product | AH17: =IFERROR(RIGHT(Sources[[#This Row],[Reference to]],LEN(Sources[[#This Row],[Reference to]])-LEN($AG17)-2),"") | AI17: =IFERROR(LEFT(AH17,FIND(",",AH17)-1),AH17) | AJ17: =IFERROR(RIGHT(Sources[[#This Row],[Reference to]],LEN(Sources[[#This Row],[Reference to]])-LEN($AG17)-2-LEN($AI17)-2),"") | AK17: =IFERROR(LEFT(AJ17,FIND(",",AJ17)-1),AJ17) | AL17: =IFERROR(RIGHT(Sources[[#This Row],[Reference to]],LEN(Sources[[#This Row],[Reference to]])-LEN($AG17)-2-LEN($AI17)-2-LEN($AK17)-2),"") | AM17: =IFERROR(LEFT(AL17,FIND(",",AL17)-1),AL17) | AN17: =IFERROR(RIGHT(Sources[[#This Row],[Reference to]],LEN(Sources[[#This Row],[Reference to]])-LEN($AG17)-2-LEN($AI17)-2-LEN($AK17)-2-LEN($AM17)-2),"") | AO17: =IFERROR(LEFT(AN17,FIND(",",AN17)-1),AN17)
B18: budny2015economic | C18: =IFERROR(VALUE(MID(Sources[[#This Row],[Citekey]],FIND("20",Sources[[#This Row],[Citekey]]),4)),"") -> 2015 | D18: yes | E18: Journal Article | F18: No cost data | H18: =IFERROR(VLOOKUP(Sources[[#This Row],[Method]],dd_analysis_graph[],2,FALSE),"") -> Not in analysis, not in graph | I18: =IFERROR(VLOOKUP(Sources[[#This Row],[Type of Publication]],dd_type_source[],2,FALSE),"") -> Publication | Z18: =IF(OR(Sources[[#This Row],[Analysis and Graph]]="Analysis and Graph",Sources[[#This Row],[Analysis and Graph]]="Not in analysis, but extra in graph"),MATCH(Sources[[#This Row],[Citekey]],Database!$B$4:$B$2385,0),"") | AA18: =IF(AG18<>"",MATCH(AG18,Sources[Citekey],0),"") | AB18: =IF(AI18<>"",MATCH(AI18,Sources[Citekey],0),"") | AC18: =IF(AK18<>"",MATCH(AK18,Sources[Citekey],0),"") | AD18: =IF(AM18<>"",MATCH(AM18,Sources[Citekey],0),"") | AE18: =IF(AO18<>"",MATCH(AO18,Sources[Citekey],0),"") | AG18: =IFERROR(IF(Sources[[#This Row],[Reference to]]<>"",LEFT(Sources[[#This Row],[Reference to]],FIND(",",Sources[[#This Row],[Reference to]])-1),""),Sources[[#This Row],[Reference to]]) | AH18: =IFERROR(RIGHT(Sources[[#This Row],[Reference to]],LEN(Sources[[#This Row],[Reference to]])-LEN($AG18)-2),"") | AI18: =IFERROR(LEFT(AH18,FIND(",",AH18)-1),AH18) | AJ18: =IFERROR(RIGHT(Sources[[#This Row],[Reference to]],LEN(Sources[[#This Row],[Reference to]])-LEN($AG18)-2-LEN($AI18)-2),"") | AK18: =IFERROR(LEFT(AJ18,FIND(",",AJ18)-1),AJ18) | AL18: =IFERROR(RIGHT(Sources[[#This Row],[Reference to]],LEN(Sources[[#This Row],[Reference to]])-LEN($AG18)-2-LEN($AI18)-2-LEN($AK18)-2),"") | AM18: =IFERROR(LEFT(AL18,FIND(",",AL18)-1),AL18) | AN18: =IFERROR(RIGHT(Sources[[#This Row],[Reference to]],LEN(Sources[[#This Row],[Reference to]])-LEN($AG18)-2-LEN($AI18)-2-LEN($AK18)-2-LEN($AM18)-2),"") | AO18: =IFERROR(LEFT(AN18,FIND(",",AN18)-1),AN18)
B19: buttler2015detailed | C19: =IFERROR(VALUE(MID(Sources[[#This Row],[Citekey]],FIND("20",Sources[[#This Row],[Citekey]]),4)),"") -> 2015 | D19: yes | E19: Journal Article | F19: Secondary source | G19: brisse2012high, harvego2008economic, DOE2013solid | H19: =IFERROR(VLOOKUP(Sources[[#This Row],[Method]],dd_analysis_graph[],2,FALSE),"") -> Not in analysis, not in graph | I19: =IFERROR(VLOOKUP(Sources[[#This Row],[Type of Publication]],dd_type_source[],2,FALSE),"") -> Publication | Z19: =IF(OR(Sources[[#This Row],[Analysis and Graph]]="Analysis and Graph",Sources[[#This Row],[Analysis and Graph]]="Not in analysis, but extra in graph"),MATCH(Sources[[#This Row],[Citekey]],Database!$B$4:$B$2385,0),"") | AA19: =IF(AG19<>"",MATCH(AG19,Sources[Citekey],0),"") -> 13 | AB19: =IF(AI19<>"",MATCH(AI19,Sources[Citekey],0),"") -> 126 | AC19: =IF(AK19<>"",MATCH(AK19,Sources[Citekey],0),"") -> 113 | AD19: =IF(AM19<>"",MATCH(AM19,Sources[Citekey],0),"") | AE19: =IF(AO19<>"",MATCH(AO19,Sources[Citekey],0),"") | AG19: =IFERROR(IF(Sources[[#This Row],[Reference to]]<>"",LEFT(Sources[[#This Row],[Reference to]],FIND(",",Sources[[#This Row],[Reference to]])-1),""),Sources[[#This Row],[Reference to]]) -> brisse2012high | AH19: =IFERROR(RIGHT(Sources[[#This Row],[Reference to]],LEN(Sources[[#This Row],[Reference to]])-LEN($AG19)-2),"") -> harvego2008economic, DOE2013solid | AI19: =IFERROR(LEFT(AH19,FIND(",",AH19)-1),AH19) -> harvego2008economic | AJ19: =IFERROR(RIGHT(Sources[[#This Row],[Reference to]],LEN(Sources[[#This Row],[Reference to]])-LEN($AG19)-2-LEN($AI19)-2),"") -> DOE2013solid | AK19: =IFERROR(LEFT(AJ19,FIND(",",AJ19)-1),AJ19) -> DOE2013solid | AL19: =IFERROR(RIGHT(Sources[[#This Row],[Reference to]],LEN(Sources[[#This Row],[Reference to]])-LEN($AG19)-2-LEN($AI19)-2-LEN($AK19)-2),"") | AM19: =IFERROR(LEFT(AL19,FIND(",",AL19)-1),AL19) | AN19: =IFERROR(RIGHT(Sources[[#This Row],[Reference to]],LEN(Sources[[#This Row],[Reference to]])-LEN($AG19)-2-LEN($AI19)-2-LEN($AK19)-2-LEN($AM19)-2),"") | AO19: =IFERROR(LEFT(AN19,FIND(",",AN19)-1),AN19)
B20: DeBoear2014application | C20: =IFERROR(VALUE(MID(Sources[[#This Row],[Citekey]],FIND("20",Sources[[#This Row],[Citekey]]),4)),"") -> 2014 | D20: yes | E20: Journal Article | F20: No cost data | H20: =IFERROR(VLOOKUP(Sources[[#This Row],[Method]],dd_analysis_graph[],2,FALSE),"") -> Not in analysis, not in graph | I20: =IFERROR(VLOOKUP(Sources[[#This Row],[Type of Publication]],dd_type_source[],2,FALSE),"") -> Publication | Z20: =IF(OR(Sources[[#This Row],[Analysis and Graph]]="Analysis and Graph",Sources[[#This Row],[Analysis and Graph]]="Not in analysis, but extra in graph"),MATCH(Sources[[#This Row],[Citekey]],Database!$B$4:$B$2385,0),"") | AA20: =IF(AG20<>"",MATCH(AG20,Sources[Citekey],0),"") | AB20: =IF(AI20<>"",MATCH(AI20,Sources[Citekey],0),"") | AC20: =IF(AK20<>"",MATCH(AK20,Sources[Citekey],0),"") | AD20: =IF(AM20<>"",MATCH(AM20,Sources[Citekey],0),"") | AE20: =IF(AO20<>"",MATCH(AO20,Sources[Citekey],0),"") | AG20: =IFERROR(IF(Sources[[#This Row],[Reference to]]<>"",LEFT(Sources[[#This Row],[Reference to]],FIND(",",Sources[[#This Row],[Reference to]])-1),""),Sources[[#This Row],[Reference to]]) | AH20: =IFERROR(RIGHT(Sources[[#This Row],[Reference to]],LEN(Sources[[#This Row],[Reference to]])-LEN($AG20)-2),"") | AI20: =IFERROR(LEFT(AH20,FIND(",",AH20)-1),AH20) | AJ20: =IFERROR(RIGHT(Sources[[#This Row],[Reference to]],LEN(Sources[[#This Row],[Reference to]])-LEN($AG20)-2-LEN($AI20)-2),"") | AK20: =IFERROR(LEFT(AJ20,FIND(",",AJ20)-1),AJ20) | AL20: =IFERROR(RIGHT(Sources[[#This Row],[Reference to]],LEN(Sources[[#This Row],[Reference to]])-LEN($AG20)-2-LEN($AI20)-2-LEN($AK20)-2),"") | AM20: =IFERROR(LEFT(AL20,FIND(",",AL20)-1),AL20) | AN20: =IFERROR(RIGHT(Sources[[#This Row],[Reference to]],LEN(Sources[[#This Row],[Reference to]])-LEN($AG20)-2-LEN($AI20)-2-LEN($AK20)-2-LEN($AM20)-2),"") | AO20: =IFERROR(LEFT(AN20,FIND(",",AN20)-1),AN20)
B21: DeSaintJean2015economic | C21: =IFERROR(VALUE(MID(Sources[[#This Row],[Citekey]],FIND("20",Sources[[#This Row],[Citekey]]),4)),"") -> 2015 | D21: yes | E21: Journal Article | F21: No cost data | H21: =IFERROR(VLOOKUP(Sources[[#This Row],[Method]],dd_analysis_graph[],2,FALSE),"") -> Not in analysis, not in graph | I21: =IFERROR(VLOOKUP(Sources[[#This Row],[Type of Publication]],dd_type_source[],2,FALSE),"") -> Publication | Z21: =IF(OR(Sources[[#This Row],[Analysis and Graph]]="Analysis and Graph",Sources[[#This Row],[Analysis and Graph]]="Not in analysis, but extra in graph"),MATCH(Sources[[#This Row],[Citekey]],Database!$B$4:$B$2385,0),"") | AA21: =IF(AG21<>"",MATCH(AG21,Sources[Citekey],0),"") | AB21: =IF(AI21<>"",MATCH(AI21,Sources[Citekey],0),"") | AC21: =IF(AK21<>"",MATCH(AK21,Sources[Citekey],0),"") | AD21: =IF(AM21<>"",MATCH(AM21,Sources[Citekey],0),"") | AE21: =IF(AO21<>"",MATCH(AO21,Sources[Citekey],0),"") | AG21: =IFERROR(IF(Sources[[#This Row],[Reference to]]<>"",LEFT(Sources[[#This Row],[Reference to]],FIND(",",Sources[[#This Row],[Reference to]])-1),""),Sources[[#This Row],[Reference to]]) | AH21: =IFERROR(RIGHT(Sources[[#This Row],[Reference to]],LEN(Sources[[#This Row],[Reference to]])-LEN($AG21)-2),"") | AI21: =IFERROR(LEFT(AH21,FIND(",",AH21)-1),AH21) | AJ21: =IFERROR(RIGHT(Sources[[#This Row],[Reference to]],LEN(Sources[[#This Row],[Reference to]])-LEN($AG21)-2-LEN($AI21)-2),"") | AK21: =IFERROR(LEFT(AJ21,FIND(",",AJ21)-1),AJ21) | AL21: =IFERROR(RIGHT(Sources[[#This Row],[Reference to]],LEN(Sources[[#This Row],[Reference to]])-LEN($AG21)-2-LEN($AI21)-2-LEN($AK21)-2),"") | AM21: =IFERROR(LEFT(AL21,FIND(",",AL21)-1),AL21) | AN21: =IFERROR(RIGHT(Sources[[#This Row],[Reference to]],LEN(Sources[[#This Row],[Reference to]])-LEN($AG21)-2-LEN($AI21)-2-LEN($AK21)-2-LEN($AM21)-2),"") | AO21: =IFERROR(LEFT(AN21,FIND(",",AN21)-1),AN21)
B22: edwards2008hydrogen | C22: =IFERROR(VALUE(MID(Sources[[#This Row],[Citekey]],FIND("20",Sources[[#This Row],[Citekey]]),4)),"") -> 2008 | D22: yes | E22: Journal Article | F22: Secondary source | H22: =IFERROR(VLOOKUP(Sources[[#This Row],[Method]],dd_analysis_graph[],2,FALSE),"") -> Not in analysis, not in graph | I22: =IFERROR(VLOOKUP(Sources[[#This Row],[Type of Publication]],dd_type_source[],2,FALSE),"") -> Publication | Z22: =IF(OR(Sources[[#This Row],[Analysis and Graph]]="Analysis and Graph",Sources[[#This Row],[Analysis and Graph]]="Not in analysis, but extra in graph"),MATCH(Sources[[#This Row],[Citekey]],Database!$B$4:$B$2385,0),"") | AA22: =IF(AG22<>"",MATCH(AG22,Sources[Citekey],0),"") | AB22: =IF(AI22<>"",MATCH(AI22,Sources[Citekey],0),"") | AC22: =IF(AK22<>"",MATCH(AK22,Sources[Citekey],0),"") | AD22: =IF(AM22<>"",MATCH(AM22,Sources[Citekey],0),"") | AE22: =IF(AO22<>"",MATCH(AO22,Sources[Citekey],0),"") | AG22: =IFERROR(IF(Sources[[#This Row],[Reference to]]<>"",LEFT(Sources[[#This Row],[Reference to]],FIND(",",Sources[[#This Row],[Reference to]])-1),""),Sources[[#This Row],[Reference to]]) | AH22: =IFERROR(RIGHT(Sources[[#This Row],[Reference to]],LEN(Sources[[#This Row],[Reference to]])-LEN($AG22)-2),"") | AI22: =IFERROR(LEFT(AH22,FIND(",",AH22)-1),AH22) | AJ22: =IFERROR(RIGHT(Sources[[#This Row],[Reference to]],LEN(Sources[[#This Row],[Reference to]])-LEN($AG22)-2-LEN($AI22)-2),"") | AK22: =IFERROR(LEFT(AJ22,FIND(",",AJ22)-1),AJ22) | AL22: =IFERROR(RIGHT(Sources[[#This Row],[Reference to]],LEN(Sources[[#This Row],[Reference to]])-LEN($AG22)-2-LEN($AI22)-2-LEN($AK22)-2),"") | AM22: =IFERROR(LEFT(AL22,FIND(",",AL22)-1),AL22) | AN22: =IFERROR(RIGHT(Sources[[#This Row],[Reference to]],LEN(Sources[[#This Row],[Reference to]])-LEN($AG22)-2-LEN($AI22)-2-LEN($AK22)-2-LEN($AM22)-2),"") | AO22: =IFERROR(LEFT(AN22,FIND(",",AN22)-1),AN22)
B23: felgenhauer2015state | C23: =IFERROR(VALUE(MID(Sources[[#This Row],[Citekey]],FIND("20",Sources[[#This Row],[Citekey]]),4)),"") -> 2015 | D23: yes | E23: Journal Article | F23: No reference, unclear method | H23: =IFERROR(VLOOKUP(Sources[[#This Row],[Method]],dd_analysis_graph[],2,FALSE),"") -> Not in analysis, not in graph | I23: =IFERROR(VLOOKUP(Sources[[#This Row],[Type of Publication]],dd_type_source[],2,FALSE),"") -> Publication | J23: Numbers for complete PtG plant, not only electrolyzer | Z23: =IF(OR(Sources[[#This Row],[Analysis and Graph]]="Analysis and Graph",Sources[[#This Row],[Analysis and Graph]]="Not in analysis, but extra in graph"),MATCH(Sources[[#This Row],[Citekey]],Database!$B$4:$B$2385,0),"") | AA23: =IF(AG23<>"",MATCH(AG23,Sources[Citekey],0),"") | AB23: =IF(AI23<>"",MATCH(AI23,Sources[Citekey],0),"") | AC23: =IF(AK23<>"",MATCH(AK23,Sources[Citekey],0),"") | AD23: =IF(AM23<>"",MATCH(AM23,Sources[Citekey],0),"") | AE23: =IF(AO23<>"",MATCH(AO23,Sources[Citekey],0),"") | AG23: =IFERROR(IF(Sources[[#This Row],[Reference to]]<>"",LEFT(Sources[[#This Row],[Reference to]],FIND(",",Sources[[#This Row],[Reference to]])-1),""),Sources[[#This Row],[Reference to]]) | AH23: =IFERROR(RIGHT(Sources[[#This Row],[Reference to]],LEN(Sources[[#This Row],[Reference to]])-LEN($AG23)-2),"") | AI23: =IFERROR(LEFT(AH23,FIND(",",AH23)-1),AH23) | AJ23: =IFERROR(RIGHT(Sources[[#This Row],[Reference to]],LEN(Sources[[#This Row],[Reference to]])-LEN($AG23)-2-LEN($AI23)-2),"") | AK23: =IFERROR(LEFT(AJ23,FIND(",",AJ23)-1),AJ23) | AL23: =IFERROR(RIGHT(Sources[[#This Row],[Reference to]],LEN(Sources[[#This Row],[Reference to]])-LEN($AG23)-2-LEN($AI23)-2-LEN($AK23)-2),"") | AM23: =IFERROR(LEFT(AL23,FIND(",",AL23)-1),AL23) | AN23: =IFERROR(RIGHT(Sources[[#This Row],[Reference to]],LEN(Sources[[#This Row],[Reference to]])-LEN($AG23)-2-LEN($AI23)-2-LEN($AK23)-2-LEN($AM23)-2),"") | AO23: =IFERROR(LEFT(AN23,FIND(",",AN23)-1),AN23)
B24: floch2007on | C24: =IFERROR(VALUE(MID(Sources[[#This Row],[Citekey]],FIND("20",Sources[[#This Row],[Citekey]]),4)),"") -> 2007 | D24: yes | E24: Journal Article | F24: No reference, unclear method | H24: =IFERROR(VLOOKUP(Sources[[#This Row],[Method]],dd_analysis_graph[],2,FALSE),"") -> Not in analysis, not in graph | I24: =IFERROR(VLOOKUP(Sources[[#This Row],[Type of Publication]],dd_type_source[],2,FALSE),"") -> Publication | Z24: =IF(OR(Sources[[#This Row],[Analysis and Graph]]="Analysis and Graph",Sources[[#This Row],[Analysis and Graph]]="Not in analysis, but extra in graph"),MATCH(Sources[[#This Row],[Citekey]],Database!$B$4:$B$2385,0),"") | AA24: =IF(AG24<>"",MATCH(AG24,Sources[Citekey],0),"") | AB24: =IF(AI24<>"",MATCH(AI24,Sources[Citekey],0),"") | AC24: =IF(AK24<>"",MATCH(AK24,Sources[Citekey],0),"") | AD24: =IF(AM24<>"",MATCH(AM24,Sources[Citekey],0),"") | AE24: =IF(AO24<>"",MATCH(AO24,Sources[Citekey],0),"") | AG24: =IFERROR(IF(Sources[[#This Row],[Reference to]]<>"",LEFT(Sources[[#This Row],[Reference to]],FIND(",",Sources[[#This Row],[Reference to]])-1),""),Sources[[#This Row],[Reference to]]) | AH24: =IFERROR(RIGHT(Sources[[#This Row],[Reference to]],LEN(Sources[[#This Row],[Reference to]])-LEN($AG24)-2),"") | AI24: =IFERROR(LEFT(AH24,FIND(",",AH24)-1),AH24) | AJ24: =IFERROR(RIGHT(Sources[[#This Row],[Reference to]],LEN(Sources[[#This Row],[Reference to]])-LEN($AG24)-2-LEN($AI24)-2),"") | AK24: =IFERROR(LEFT(AJ24,FIND(",",AJ24)-1),AJ24) | AL24: =IFERROR(RIGHT(Sources[[#This Row],[Reference to]],LEN(Sources[[#This Row],[Reference to]])-LEN($AG24)-2-LEN($AI24)-2-LEN($AK24)-2),"") | AM24: =IFERROR(LEFT(AL24,FIND(",",AL24)-1),AL24) | AN24: =IFERROR(RIGHT(Sources[[#This Row],[Reference to]],LEN(Sources[[#This Row],[Reference to]])-LEN($AG24)-2-LEN($AI24)-2-LEN($AK24)-2-LEN($AM24)-2),"") | AO24: =IFERROR(LEFT(AN24,FIND(",",AN24)-1),AN24)
B25: gahleitner2013hydrogen | C25: =IFERROR(VALUE(MID(Sources[[#This Row],[Citekey]],FIND("20",Sources[[#This Row],[Citekey]]),4)),"") -> 2013 | D25: yes | E25: Journal Article | F25: Secondary source | G25: sterner2009bioenergy | H25: =IFERROR(VLOOKUP(Sources[[#This Row],[Method]],dd_analysis_graph[],2,FALSE),"") -> Not in analysis, not in graph | I25: =IFERROR(VLOOKUP(Sources[[#This Row],[Type of Publication]],dd_type_source[],2,FALSE),"") -> Publication | Z25: =IF(OR(Sources[[#This Row],[Analysis and Graph]]="Analysis and Graph",Sources[[#This Row],[Analysis and Graph]]="Not in analysis, but extra in graph"),MATCH(Sources[[#This Row],[Citekey]],Database!$B$4:$B$2385,0),"") | AA25: =IF(AG25<>"",MATCH(AG25,Sources[Citekey],0),"") -> 155 | AB25: =IF(AI25<>"",MATCH(AI25,Sources[Citekey],0),"") | AC25: =IF(AK25<>"",MATCH(AK25,Sources[Citekey],0),"") | AD25: =IF(AM25<>"",MATCH(AM25,Sources[Citekey],0),"") | AE25: =IF(AO25<>"",MATCH(AO25,Sources[Citekey],0),"") | AG25: =IFERROR(IF(Sources[[#This Row],[Reference to]]<>"",LEFT(Sources[[#This Row],[Reference to]],FIND(",",Sources[[#This Row],[Reference to]])-1),""),Sources[[#This Row],[Reference to]]) -> sterner2009bioenergy | AH25: =IFERROR(RIGHT(Sources[[#This Row],[Reference to]],LEN(Sources[[#This Row],[Reference to]])-LEN($AG25)-2),"") | AI25: =IFERROR(LEFT(AH25,FIND(",",AH25)-1),AH25) | AJ25: =IFERROR(RIGHT(Sources[[#This Row],[Reference to]],LEN(Sources[[#This Row],[Reference to]])-LEN($AG25)-2-LEN($AI25)-2),"") | AK25: =IFERROR(LEFT(AJ25,FIND(",",AJ25)-1),AJ25) | AL25: =IFERROR(RIGHT(Sources[[#This Row],[Reference to]],LEN(Sources[[#This Row],[Reference to]])-LEN($AG25)-2-LEN($AI25)-2-LEN($AK25)-2),"") | AM25: =IFERROR(LEFT(AL25,FIND(",",AL25)-1),AL25) | AN25: =IFERROR(RIGHT(Sources[[#This Row],[Reference to]],LEN(Sources[[#This Row],[Reference to]])-LEN($AG25)-2-LEN($AI25)-2-LEN($AK25)-2-LEN($AM25)-2),"") | AO25: =IFERROR(LEFT(AN25,FIND(",",AN25)-1),AN25)
B26: garmsiri2014integration | C26: =IFERROR(VALUE(MID(Sources[[#This Row],[Citekey]],FIND("20",Sources[[#This Row],[Citekey]]),4)),"") -> 2014 | D26: yes | E26: Journal Article | F26: No cost data | H26: =IFERROR(VLOOKUP(Sources[[#This Row],[Method]],dd_analysis_graph[],2,FALSE),"") -> Not in analysis, not in graph | I26: =IFERROR(VLOOKUP(Sources[[#This Row],[Type of Publication]],dd_type_source[],2,FALSE),"") -> Publication | Z26: =IF(OR(Sources[[#This Row],[Analysis and Graph]]="Analysis and Graph",Sources[[#This Row],[Analysis and Graph]]="Not in analysis, but extra in graph"),MATCH(Sources[[#This Row],[Citekey]],Database!$B$4:$B$2385,0),"") | AA26: =IF(AG26<>"",MATCH(AG26,Sources[Citekey],0),"") | AB26: =IF(AI26<>"",MATCH(AI26,Sources[Citekey],0),"") | AC26: =IF(AK26<>"",MATCH(AK26,Sources[Citekey],0),"") | AD26: =IF(AM26<>"",MATCH(AM26,Sources[Citekey],0),"") | AE26: =IF(AO26<>"",MATCH(AO26,Sources[Citekey],0),"") | AG26: =IFERROR(IF(Sources[[#This Row],[Reference to]]<>"",LEFT(Sources[[#This Row],[Reference to]],FIND(",",Sources[[#This Row],[Reference to]])-1),""),Sources[[#This Row],[Reference to]]) | AH26: =IFERROR(RIGHT(Sources[[#This Row],[Reference to]],LEN(Sources[[#This Row],[Reference to]])-LEN($AG26)-2),"") | AI26: =IFERROR(LEFT(AH26,FIND(",",AH26)-1),AH26) | AJ26: =IFERROR(RIGHT(Sources[[#This Row],[Reference to]],LEN(Sources[[#This Row],[Reference to]])-LEN($AG26)-2-LEN($AI26)-2),"") | AK26: =IFERROR(LEFT(AJ26,FIND(",",AJ26)-1),AJ26) | AL26: =IFERROR(RIGHT(Sources[[#This Row],[Reference to]],LEN(Sources[[#This Row],[Reference to]])-LEN($AG26)-2-LEN($AI26)-2-LEN($AK26)-2),"") | AM26: =IFERROR(LEFT(AL26,FIND(",",AL26)-1),AL26) | AN26: =IFERROR(RIGHT(Sources[[#This Row],[Reference to]],LEN(Sources[[#This Row],[Reference to]])-LEN($AG26)-2-LEN($AI26)-2-LEN($AK26)-2-LEN($AM26)-2),"") | AO26: =IFERROR(LEFT(AN26,FIND(",",AN26)-1),AN26)
B27: giglio2015synthetic | C27: =IFERROR(VALUE(MID(Sources[[#This Row],[Citekey]],FIND("20",Sources[[#This Row],[Citekey]]),4)),"") -> 2015 | D27: yes | E27: Journal Article | F27: No cost data | H27: =IFERROR(VLOOKUP(Sources[[#This Row],[Method]],dd_analysis_graph[],2,FALSE),"") -> Not in analysis, not in graph | I27: =IFERROR(VLOOKUP(Sources[[#This Row],[Type of Publication]],dd_type_source[],2,FALSE),"") -> Publication | Z27: =IF(OR(Sources[[#This Row],[Analysis and Graph]]="Analysis and Graph",Sources[[#This Row],[Analysis and Graph]]="Not in analysis, but extra in graph"),MATCH(Sources[[#This Row],[Citekey]],Database!$B$4:$B$2385,0),"") | AA27: =IF(AG27<>"",MATCH(AG27,Sources[Citekey],0),"") | AB27: =IF(AI27<>"",MATCH(AI27,Sources[Citekey],0),"") | AC27: =IF(AK27<>"",MATCH(AK27,Sources[Citekey],0),"") | AD27: =IF(AM27<>"",MATCH(AM27,Sources[Citekey],0),"") | AE27: =IF(AO27<>"",MATCH(AO27,Sources[Citekey],0),"") | AG27: =IFERROR(IF(Sources[[#This Row],[Reference to]]<>"",LEFT(Sources[[#This Row],[Reference to]],FIND(",",Sources[[#This Row],[Reference to]])-1),""),Sources[[#This Row],[Reference to]]) | AH27: =IFERROR(RIGHT(Sources[[#This Row],[Reference to]],LEN(Sources[[#This Row],[Reference to]])-LEN($AG27)-2),"") | AI27: =IFERROR(LEFT(AH27,FIND(",",AH27)-1),AH27) | AJ27: =IFERROR(RIGHT(Sources[[#This Row],[Reference to]],LEN(Sources[[#This Row],[Reference to]])-LEN($AG27)-2-LEN($AI27)-2),"") | AK27: =IFERROR(LEFT(AJ27,FIND(",",AJ27)-1),AJ27) | AL27: =IFERROR(RIGHT(Sources[[#This Row],[Reference to]],LEN(Sources[[#This Row],[Reference to]])-LEN($AG27)-2-LEN($AI27)-2-LEN($AK27)-2),"") | AM27: =IFERROR(LEFT(AL27,FIND(",",AL27)-1),AL27) | AN27: =IFERROR(RIGHT(Sources[[#This Row],[Reference to]],LEN(Sources[[#This Row],[Reference to]])-LEN($AG27)-2-LEN($AI27)-2-LEN($AK27)-2-LEN($AM27)-2),"") | AO27: =IFERROR(LEFT(AN27,FIND(",",AN27)-1),AN27)
B28: gonzalez2004the | C28: =IFERROR(VALUE(MID(Sources[[#This Row],[Citekey]],FIND("20",Sources[[#This Row],[Citekey]]),4)),"") -> 2004 | D28: yes | E28: Journal Article | F28: Original analysis, industry data | H28: =IFERROR(VLOOKUP(Sources[[#This Row],[Method]],dd_analysis_graph[],2,FALSE),"") -> Analysis and Graph | I28: =IFERROR(VLOOKUP(Sources[[#This Row],[Type of Publication]],dd_type_source[],2,FALSE),"") -> Publication | Z28: =IF(OR(Sources[[#This Row],[Analysis and Graph]]="Analysis and Graph",Sources[[#This Row],[Analysis and Graph]]="Not in analysis, but extra in graph"),MATCH(Sources[[#This Row],[Citekey]],Database!$B$4:$B$2385,0),"") -> 433 | AA28: =IF(AG28<>"",MATCH(AG28,Sources[Citekey],0),"") | AB28: =IF(AI28<>"",MATCH(AI28,Sources[Citekey],0),"") | AC28: =IF(AK28<>"",MATCH(AK28,Sources[Citekey],0),"") | AD28: =IF(AM28<>"",MATCH(AM28,Sources[Citekey],0),"") | AE28: =IF(AO28<>"",MATCH(AO28,Sources[Citekey],0),"") | AG28: =IFERROR(IF(Sources[[#This Row],[Reference to]]<>"",LEFT(Sources[[#This Row],[Reference to]],FIND(",",Sources[[#This Row],[Reference to]])-1),""),Sources[[#This Row],[Reference to]]) | AH28: =IFERROR(RIGHT(Sources[[#This Row],[Reference to]],LEN(Sources[[#This Row],[Reference to]])-LEN($AG28)-2),"") | AI28: =IFERROR(LEFT(AH28,FIND(",",AH28)-1),AH28) | AJ28: =IFERROR(RIGHT(Sources[[#This Row],[Reference to]],LEN(Sources[[#This Row],[Reference to]])-LEN($AG28)-2-LEN($AI28)-2),"") | AK28: =IFERROR(LEFT(AJ28,FIND(",",AJ28)-1),AJ28) | AL28: =IFERROR(RIGHT(Sources[[#This Row],[Reference to]],LEN(Sources[[#This Row],[Reference to]])-LEN($AG28)-2-LEN($AI28)-2-LEN($AK28)-2),"") | AM28: =IFERROR(LEFT(AL28,FIND(",",AL28)-1),AL28) | AN28: =IFERROR(RIGHT(Sources[[#This Row],[Reference to]],LEN(Sources[[#This Row],[Reference to]])-LEN($AG28)-2-LEN($AI28)-2-LEN($AK28)-2-LEN($AM28)-2),"") | AO28: =IFERROR(LEFT(AN28,FIND(",",AN28)-1),AN28)
B29: gotz2016renewable | C29: 2016 | D29: yes | E29: Journal Article | F29: Original review multiple sources | G29: buchholz2014power, lehner2014power | H29: =IFERROR(VLOOKUP(Sources[[#This Row],[Method]],dd_analysis_graph[],2,FALSE),"") -> Analysis and Graph | I29: =IFERROR(VLOOKUP(Sources[[#This Row],[Type of Publication]],dd_type_source[],2,FALSE),"") -> Publication | Z29: =IF(OR(Sources[[#This Row],[Analysis and Graph]]="Analysis and Graph",Sources[[#This Row],[Analysis and Graph]]="Not in analysis, but extra in graph"),MATCH(Sources[[#This Row],[Citekey]],Database!$B$4:$B$2385,0),"") -> 1 | AA29: =IF(AG29<>"",MATCH(AG29,Sources[Citekey],0),"") -> 15 | AB29: =IF(AI29<>"",MATCH(AI29,Sources[Citekey],0),"") -> 44 | AC29: =IF(AK29<>"",MATCH(AK29,Sources[Citekey],0),"") | AD29: =IF(AM29<>"",MATCH(AM29,Sources[Citekey],0),"") | AE29: =IF(AO29<>"",MATCH(AO29,Sources[Citekey],0),"") | AG29: =IFERROR(IF(Sources[[#This Row],[Reference to]]<>"",LEFT(Sources[[#This Row],[Reference to]],FIND(",",Sources[[#This Row],[Reference to]])-1),""),Sources[[#This Row],[Reference to]]) -> buchholz2014power | AH29: =IFERROR(RIGHT(Sources[[#This Row],[Reference to]],LEN(Sources[[#This Row],[Reference to]])-LEN($AG29)-2),"") -> lehner2014power | AI29: =IFERROR(LEFT(AH29,FIND(",",AH29)-1),AH29) -> lehner2014power | AJ29: =IFERROR(RIGHT(Sources[[#This Row],[Reference to]],LEN(Sources[[#This Row],[Reference to]])-LEN($AG29)-2-LEN($AI29)-2),"") | AK29: =IFERROR(LEFT(AJ29,FIND(",",AJ29)-1),AJ29) | AL29: =IFERROR(RIGHT(Sources[[#This Row],[Reference to]],LEN(Sources[[#This Row],[Reference to]])-LEN($AG29)-2-LEN($AI29)-2-LEN($AK29)-2),"") | AM29: =IFERROR(LEFT(AL29,FIND(",",AL29)-1),AL29) | AN29: =IFERROR(RIGHT(Sources[[#This Row],[Reference to]],LEN(Sources[[#This Row],[Reference to]])-LEN($AG29)-2-LEN($AI29)-2-LEN($AK29)-2-LEN($AM29)-2),"") | AO29: =IFERROR(LEFT(AN29,FIND(",",AN29)-1),AN29)
B30: greiner2007norwegian | C30: 2007 | D30: yes | E30: Journal Article | F30: Original analysis, industry data | H30: =IFERROR(VLOOKUP(Sources[[#This Row],[Method]],dd_analysis_graph[],2,FALSE),"") -> Analysis and Graph | I30: =IFERROR(VLOOKUP(Sources[[#This Row],[Type of Publication]],dd_type_source[],2,FALSE),"") -> Publication | Z30: =IF(OR(Sources[[#This Row],[Analysis and Graph]]="Analysis and Graph",Sources[[#This Row],[Analysis and Graph]]="Not in analysis, but extra in graph"),MATCH(Sources[[#This Row],[Citekey]],Database!$B$4:$B$2385,0),"") -> 49 | AA30: =IF(AG30<>"",MATCH(AG30,Sources[Citekey],0),"") | AB30: =IF(AI30<>"",MATCH(AI30,Sources[Citekey],0),"") | AC30: =IF(AK30<>"",MATCH(AK30,Sources[Citekey],0),"") | AD30: =IF(AM30<>"",MATCH(AM30,Sources[Citekey],0),"") | AE30: =IF(AO30<>"",MATCH(AO30,Sources[Citekey],0),"") | AG30: =IFERROR(IF(Sources[[#This Row],[Reference to]]<>"",LEFT(Sources[[#This Row],[Reference to]],FIND(",",Sources[[#This Row],[Reference to]])-1),""),Sources[[#This Row],[Reference to]]) | AH30: =IFERROR(RIGHT(Sources[[#This Row],[Reference to]],LEN(Sources[[#This Row],[Reference to]])-LEN($AG30)-2),"") | AI30: =IFERROR(LEFT(AH30,FIND(",",AH30)-1),AH30) | AJ30: =IFERROR(RIGHT(Sources[[#This Row],[Reference to]],LEN(Sources[[#This Row],[Reference to]])-LEN($AG30)-2-LEN($AI30)-2),"") | AK30: =IFERROR(LEFT(AJ30,FIND(",",AJ30)-1),AJ30) | AL30: =IFERROR(RIGHT(Sources[[#This Row],[Reference to]],LEN(Sources[[#This Row],[Reference to]])-LEN($AG30)-2-LEN($AI30)-2-LEN($AK30)-2),"") | AM30: =IFERROR(LEFT(AL30,FIND(",",AL30)-1),AL30) | AN30: =IFERROR(RIGHT(Sources[[#This Row],[Reference to]],LEN(Sources[[#This Row],[Reference to]])-LEN($AG30)-2-LEN($AI30)-2-LEN($AK30)-2-LEN($AM30)-2),"") | AO30: =IFERROR(LEFT(AN30,FIND(",",AN30)-1),AN30)
B31: guandalini2015power | C31: =IFERROR(VALUE(MID(Sources[[#This Row],[Citekey]],FIND("20",Sources[[#This Row],[Citekey]]),4)),"") -> 2015 | D31: yes | E31: Journal Article | F31: Secondary source | G31: bajohr2011speicherung | H31: =IFERROR(VLOOKUP(Sources[[#This Row],[Method]],dd_analysis_graph[],2,FALSE),"") -> Not in analysis, not in graph | I31: =IFERROR(VLOOKUP(Sources[[#This Row],[Type of Publication]],dd_type_source[],2,FALSE),"") -> Publication | Z31: =IF(OR(Sources[[#This Row],[Analysis and Graph]]="Analysis and Graph",Sources[[#This Row],[Analysis and Graph]]="Not in analysis, but extra in graph"),MATCH(Sources[[#This Row],[Citekey]],Database!$B$4:$B$2385,0),"") | AA31: =IF(AG31<>"",MATCH(AG31,Sources[Citekey],0),"") -> 5 | AB31: =IF(AI31<>"",MATCH(AI31,Sources[Citekey],0),"") | AC31: =IF(AK31<>"",MATCH(AK31,Sources[Citekey],0),"") | AD31: =IF(AM31<>"",MATCH(AM31,Sources[Citekey],0),"") | AE31: =IF(AO31<>"",MATCH(AO31,Sources[Citekey],0),"") | AG31: =IFERROR(IF(Sources[[#This Row],[Reference to]]<>"",LEFT(Sources[[#This Row],[Reference to]],FIND(",",Sources[[#This Row],[Reference to]])-1),""),Sources[[#This Row],[Reference to]]) -> bajohr2011speicherung | AH31: =IFERROR(RIGHT(Sources[[#This Row],[Reference to]],LEN(Sources[[#This Row],[Reference to]])-LEN($AG31)-2),"") | AI31: =IFERROR(LEFT(AH31,FIND(",",AH31)-1),AH31) | AJ31: =IFERROR(RIGHT(Sources[[#This Row],[Reference to]],LEN(Sources[[#This Row],[Reference to]])-LEN($AG31)-2-LEN($AI31)-2),"") | AK31: =IFERROR(LEFT(AJ31,FIND(",",AJ31)-1),AJ31) | AL31: =IFERROR(RIGHT(Sources[[#This Row],[Reference to]],LEN(Sources[[#This Row],[Reference to]])-LEN($AG31)-2-LEN($AI31)-2-LEN($AK31)-2),"") | AM31: =IFERROR(LEFT(AL31,FIND(",",AL31)-1),AL31) | AN31: =IFERROR(RIGHT(Sources[[#This Row],[Reference to]],LEN(Sources[[#This Row],[Reference to]])-LEN($AG31)-2-LEN($AI31)-2-LEN($AK31)-2-LEN($AM31)-2),"") | AO31: =IFERROR(LEFT(AN31,FIND(",",AN31)-1),AN31)
