Workbook

Sheet Lisez-moi
A1: Classeur maître « Électrolyseurs » : CAPEX, rendement et paramètres (alcalin / PEM / SOEC)
A3: Onglets
A4: • Hypothèses : taux de change, inflation, définition de l'horizon « actuel ». Cellules bleues sur fond jaune = à modifier ; tout se recalcule.
A5: • Données : une ligne par valeur (table à charger dans Power BI). Colonnes Facteur, Min/Typique/Max normalisés et Horizon = formules.
A6: • Sources : une ligne par base et par étude/source (auteur, titre, année, DOI ou lien, licence, date de consultation).
A7: • Synthèse : CAPEX et rendement par technologie et horizon (actuel, 2030, 2050) : min, médiane, max, nombre de valeurs et de sources. Formules MEDIAN / MIN / MAX / SUMPRODUCT, mises à jour dès qu'on ajoute des lignes dans Données.
A8: • Lacunes : nombre de sources par paramètre et par technologie (objectif : au moins 2).
A9: • Interface : tableau d'interface du bloc électrolyseur (entrées, sorties, paramètres) pour Capella et le modèle Python.
A11: Contenu importé
A12: • Ghadim et al. 2025 (CAPEX et LCOH, alcalin et PEM, USD 2024) : valeurs observées et projections, min / moyenne / max par étude et par année.
A13: • Delft (CAPEX_DATA, onglet CAPEX) : CAPEX alcalin et PEM 2003-2023 en EUR/kW.
A14: • Muñoz-Peña et al. 2024 (micro-réseau) : paramètres de l'électrolyseur PEM (OPEX, remplacement, durée de vie, rendement, charge minimale), eau stœchiométrique, compresseur. Hypothèses d'un cas d'étude, statut « à vérifier ».
... A25: • Données observées et projections sont mélangées pour un même horizon : filtrer sur la colonne Type si besoin.

Sheet Hypothèses
A1: Hypothèses de conversion et d'horizon
A2: Cellules bleues sur fond jaune = modifiables. Unité cible du CAPEX : USD 2024 par kW.
A4: Paramètre | B4: Valeur | C4: Source / commentaire | D4: Année | E4: Coef. USD→USD 2024
A5: Taux EUR → USD (2024) | B5: 1.082 | C5: Ghadim et al. 2025, onglet « Conversion rates » : 1 EUR = 1,082 USD en 2024 | D5: 2001 | E5: 1.77
A6: Année de référence des EUR de Delft | B6: 2018 | C6: Hypothèse : les valeurs 2019-2023 de Delft sont ajustées de l'inflation vers ≈2018 ; avant 2019 ce sont des EUR de l'année. À vérifier auprès de Glenk & Reichelstein / Delft. | D6: 2002 | E6: 1.74
A7: Coefficient d'inflation USD vers USD 2024 (année de réf. Delft) | B7: =INDEX($E$5:$E$40,MATCH(B6,$D$5:$D$40,0)) -> 1.25 | C7: Lu dans le tableau ci-dessous (Ghadim, « Conversion rates »). Approximation : on applique l'inflation USD aux EUR de Delft. | D7: 2003 | E7: 1.7
A8: Facteur Delft : EUR → USD 2024 | B8: =B5*B7 -> 1.3525 | C8: Taux EUR/USD × coefficient d'inflation (calculé) | D8: 2004 | E8: 1.66
A9: Début de la plage « actuel » | B9: 2020 | C9: Choix de l'utilisateur : horizon « actuel » = valeurs datées de cette année à la suivante | D9: 2005 | E9: 1.61
A10: Fin de la plage « actuel » | B10: 2025 | C10: idem | D10: 2006 | E10: 1.56
A11: Année de réf. des EUR du micro-réseau | B11: 2024 | C11: Muñoz-Peña : « EUR courants 2024 » (facteur d'inflation = 1) | D11: 2007 | E11: 1.51
D12: 2008 | E12: 1.46
A13: Clé de conversion | B13: Facteur vers USD 2024 | C13: Usage | D13: 2009 | E13: 1.46
A14: USD2024 | B14: =1 -> 1 | C14: Ghadim (déjà en USD 2024) | D14: 2010 | E14: 1.44
A15: EUR_DELFT | B15: =B8 -> 1.3525 | C15: Delft (EUR de réf. ≈2018) | D15: 2011 | E15: 1.39
A16: EUR2024 | B16: =B5*1 -> 1.082 | C16: Micro-réseau (EUR courants 2024) | D16: 2012 | E16: 1.37
A17: aucune | B17: =1 -> 1 | C17: Paramètres non monétaires | D17: 2013 | E17: 1.35
D18: 2014 | E18: 1.32
A19: Remarque : l'inflation EUR 2018→2024 est probablement différente de l'inflation USD ; la conversion Delft est donc une approximation, à documenter dans la réunion. | D19: 2015 | E19: 1.32
D20: 2016 | E20: 1.31
D21: 2017 | E21: 1.28
D22: 2018 | E22: 1.25
D23: 2019 | E23: 1.23
D24: 2020 | E24: 1.21
D25: 2021 | E25: 1.16
D26: 2022 | E26: 1.07
D27: 2023 | E27: 1.03
D28: 2024 | E28: 1

Sheet Sources
A1: Source | B1: Base | C1: Auteur(s) | D1: Titre | E1: Année | F1: DOI ou lien | G1: Licence | H1: Date de consultation | I1: Statut | J1: Remarque
A2: Actual CAPEX | B2: Ghadim | C2: Actual CAPEX (étude compilée par Ghadim et al.) | D2: Voir Supplementary Table 1 de Ghadim et al. 2025 | F2: 10.1038/s41597-025-05951-4 (article) ; 10.5281/zenodo.16417026 (jeu de données) ; étude d'origine à retrouver | G2: CC BY 4.0 (base Ghadim) | H2: 2026-10-19 | I2: à vérifier | J2: Étude primaire non consultée
A3: Actual LCOH | B3: Ghadim | C3: Actual LCOH (étude compilée par Ghadim et al.) | D3: Voir Supplementary Table 1 de Ghadim et al. 2025 | F3: 10.1038/s41597-025-05951-4 (article) ; 10.5281/zenodo.16417026 (jeu de données) ; étude d'origine à retrouver | G3: CC BY 4.0 (base Ghadim) | H3: 2026-10-19 | I3: à vérifier | J3: Étude primaire non consultée
A4: BNEF 2020 (China) | B4: Ghadim | C4: BNEF 2020 (China) (étude compilée par Ghadim et al.) | D4: Voir Supplementary Table 1 de Ghadim et al. 2025 | F4: 10.1038/s41597-025-05951-4 (article) ; 10.5281/zenodo.16417026 (jeu de données) ; étude d'origine à retrouver | G4: CC BY 4.0 (base Ghadim) | H4: 2026-10-19 | I4: à vérifier | J4: Étude primaire non consultée
A5: BNEF 2020 (World) | B5: Ghadim | C5: BNEF 2020 (World) (étude compilée par Ghadim et al.) | D5: Voir Supplementary Table 1 de Ghadim et al. 2025 | F5: 10.1038/s41597-025-05951-4 (article) ; 10.5281/zenodo.16417026 (jeu de données) ; étude d'origine à retrouver | G5: CC BY 4.0 (base Ghadim) | H5: 2026-10-19 | I5: à vérifier | J5: Étude primaire non consultée
A6: Brandle et al. 2021 (World) | B6: Ghadim | C6: Brandle et al. 2021 (World) (étude compilée par Ghadim et al.) | D6: Voir Supplementary Table 1 de Ghadim et al. 2025 | F6: 10.1038/s41597-025-05951-4 (article) ; 10.5281/zenodo.16417026 (jeu de données) ; étude d'origine à retrouver | G6: CC BY 4.0 (base Ghadim) | H6: 2026-10-19 | I6: à vérifier | J6: Étude primaire non consultée
A7: DEA 2025 (Denmark) - 10 MW | B7: Ghadim | C7: DEA 2025 (Denmark) - 10 MW (étude compilée par Ghadim et al.) | D7: Voir Supplementary Table 1 de Ghadim et al. 2025 | F7: 10.1038/s41597-025-05951-4 (article) ; 10.5281/zenodo.16417026 (jeu de données) ; étude d'origine à retrouver | G7: CC BY 4.0 (base Ghadim) | H7: 2026-10-19 | I7: à vérifier | J7: Étude primaire non consultée
A8: DEA 2025 (Denmark) - 100 MW | B8: Ghadim | C8: DEA 2025 (Denmark) - 100 MW (étude compilée par Ghadim et al.) | D8: Voir Supplementary Table 1 de Ghadim et al. 2025 | F8: 10.1038/s41597-025-05951-4 (article) ; 10.5281/zenodo.16417026 (jeu de données) ; étude d'origine à retrouver | G8: CC BY 4.0 (base Ghadim) | H8: 2026-10-19 | I8: à vérifier | J8: Étude primaire non consultée
A9: DEA 2025 (Denmark) - 1000 MW | B9: Ghadim | C9: DEA 2025 (Denmark) - 1000 MW (étude compilée par Ghadim et al.) | D9: Voir Supplementary Table 1 de Ghadim et al. 2025 | F9: 10.1038/s41597-025-05951-4 (article) ; 10.5281/zenodo.16417026 (jeu de données) ; étude d'origine à retrouver | G9: CC BY 4.0 (base Ghadim) | H9: 2026-10-19 | I9: à vérifier | J9: Étude primaire non consultée
A10: DNV 2022 (World) | B10: Ghadim | C10: DNV 2022 (World) (étude compilée par Ghadim et al.) | D10: Voir Supplementary Table 1 de Ghadim et al. 2025 | F10: 10.1038/s41597-025-05951-4 (article) ; 10.5281/zenodo.16417026 (jeu de données) ; étude d'origine à retrouver | G10: CC BY 4.0 (base Ghadim) | H10: 2026-10-19 | I10: à vérifier | J10: Étude primaire non consultée
A11: ETC 2019 (China) | B11: Ghadim | C11: ETC 2019 (China) (étude compilée par Ghadim et al.) | D11: Voir Supplementary Table 1 de Ghadim et al. 2025 | F11: 10.1038/s41597-025-05951-4 (article) ; 10.5281/zenodo.16417026 (jeu de données) ; étude d'origine à retrouver | G11: CC BY 4.0 (base Ghadim) | H11: 2026-10-19 | I11: à vérifier | J11: Étude primaire non consultée
A12: Gallardo et al. 2021 (Chile) | B12: Ghadim | C12: Gallardo et al. 2021 (Chile) (étude compilée par Ghadim et al.) | D12: Voir Supplementary Table 1 de Ghadim et al. 2025 | F12: 10.1038/s41597-025-05951-4 (article) ; 10.5281/zenodo.16417026 (jeu de données) ; étude d'origine à retrouver | G12: CC BY 4.0 (base Ghadim) | H12: 2026-10-19 | I12: à vérifier | J12: Étude primaire non consultée
A13: Gandhi et al 2022 (UAE) | B13: Ghadim | C13: Gandhi et al 2022 (UAE) (étude compilée par Ghadim et al.) | D13: Voir Supplementary Table 1 de Ghadim et al. 2025 | F13: 10.1038/s41597-025-05951-4 (article) ; 10.5281/zenodo.16417026 (jeu de données) ; étude d'origine à retrouver | G13: CC BY 4.0 (base Ghadim) | H13: 2026-10-19 | I13: à vérifier | J13: Étude primaire non consultée
... A35: WEC 2021 (World) | B35: Ghadim | C35: WEC 2021 (World) (étude compilée par Ghadim et al.) | D35: Voir Supplementary Table 1 de Ghadim et al. 2025 | F35: 10.1038/s41597-025-05951-4 (article) ; 10.5281/zenodo.16417026 (jeu de données) ; étude d'origine à retrouver | G35: CC BY 4.0 (base Ghadim) | H35: 2026-10-19 | I35: à vérifier | J35: Étude primaire non consultée
A36: Glenk & Reichelstein 2019 | B36: Delft | C36: Glenk G., Reichelstein S. | D36: Economics of converting renewable power to hydrogen | E36: 2019 | F36: Nature Energy (DOI à compléter) | G36: (à compléter) | H36: 2026-10-19 | I36: à vérifier | J36: Cité dans le classeur CAPEX_DATA de Delft (onglet CALC) ; page exacte indiquée dans CALC
A37: IEA The Future of Hydrogen 2019 | B37: Delft | C37: IEA | D37: The Future of Hydrogen | E37: 2019 | F37: (lien IEA à compléter) | G37: (à compléter) | H37: 2026-10-19 | I37: à vérifier | J37: Cité dans le classeur CAPEX_DATA de Delft (onglet CALC) ; page exacte indiquée dans CALC
A38: IEA Global Hydrogen Review 2021 | B38: Delft | C38: IEA | D38: Global Hydrogen Review 2021 | E38: 2021 | F38: (lien IEA à compléter) | G38: (à compléter) | H38: 2026-10-19 | I38: à vérifier | J38: Cité dans le classeur CAPEX_DATA de Delft (onglet CALC) ; page exacte indiquée dans CALC
A39: IEA Global Hydrogen Review 2022 | B39: Delft | C39: IEA | D39: Global Hydrogen Review 2022 | E39: 2022 | F39: (lien IEA à compléter) | G39: (à compléter) | H39: 2026-10-19 | I39: à vérifier | J39: Cité dans le classeur CAPEX_DATA de Delft (onglet CALC) ; page exacte indiquée dans CALC
A40: IEA Global Hydrogen Review 2023 | B40: Delft | C40: IEA | D40: Global Hydrogen Review 2023 | E40: 2023 | F40: (lien IEA à compléter) | G40: (à compléter) | H40: 2026-10-19 | I40: à vérifier | J40: Cité dans le classeur CAPEX_DATA de Delft (onglet CALC) ; page exacte indiquée dans CALC
A41: IEA Global Hydrogen Review 2024 | B41: Delft | C41: IEA | D41: Global Hydrogen Review 2024 | E41: 2024 | F41: (lien IEA à compléter) | G41: (à compléter) | H41: 2026-10-19 | I41: à vérifier | J41: Cité dans le classeur CAPEX_DATA de Delft (onglet CALC) ; page exacte indiquée dans CALC
A42: Muñoz-Peña et al. 2024 | B42: Microgrid | C42: Muñoz-Peña et al. | D42: Optimal design of a hydrogen system of grid-connected flexible industrial microgrids (23rd Wind & Solar Integration Workshop, Helsinki) | E42: 2024 | F42: (DOI à compléter) | G42: (à compléter) | H42: 2026-10-19 | I42: à vérifier | J42: Tableaux 2 et 3 ; valeurs reprises de Marocco et al. 2023 (J. Clean. Prod. 388, 135969) et 2024 (J. Clean. Prod. 434, 140007)
A43: Potsdam (Electrolyser Data Complete, Efuels JE FU) | B43: Potsdam | C43: (à compléter depuis le README) | D43: Electrolyser_Data_Complete_Efuels_JE_FU | F43: (voir README) | G43: CC BY 4.0 (selon vos notes) | I43: à importer | J43: NON IMPORTÉ : fichier .xlsx absent de cette session

Sheet Données
A1: ID | B1: Base de données | C1: Source | D1: Technologie | E1: Paramètre | F1: Type de donnée | G1: Valeur min | H1: Valeur typique | I1: Valeur max | J1: Unité | K1: Année de la valeur | L1: Horizon | M1: Taille | N1: Périmètre | O1: Base énergétique | P1: Région | Q1: Clé de conversion | R1: Facteur de conversion | S1: Min normalisé | T1: Typique normalisé | U1: Max normalisé | V1: Unité normalisée | W1: Statut | X1: Commentaire
A2: D0001 | B2: Ghadim | C2: Actual CAPEX | D2: Alcalin | E2: CAPEX | F2: Observé | G2: 837.45901 | H2: 1164.5901 | I2: 1596.4073 | J2: USD 2024/kW | K2: 2015 | L2: =IF(AND(K2>=Hypothèses!$B$9,K2<=Hypothèses!$B$10),"actuel",IF(K2=2030,"2030",IF(K2=2050,"2050","autre"))) -> autre | N2: non précisé (varie selon l'étude) | P2: Marché | Q2: USD2024 | R2: =INDEX(Hypothèses!$B$14:$B$17,MATCH(Q2,Hypothèses!$A$14:$A$17,0)) -> 1 | S2: =IF(G2="","",G2*R2) -> 837.45901 | T2: =IF(H2="","",H2*R2) -> 1164.5901 | U2: =IF(I2="","",I2*R2) -> 1596.4073 | V2: USD 2024/kW | W2: à vérifier | X2: Base Ghadim et al. 2025 (USD 2024, déjà corrigé de l'inflation).
A3: D0002 | B3: Ghadim | C3: Actual CAPEX | D3: Alcalin | E3: CAPEX | F3: Observé | G3: 850.54413 | H3: 1138.4178 | I3: 1478.6371 | J3: USD 2024/kW | K3: 2016 | L3: =IF(AND(K3>=Hypothèses!$B$9,K3<=Hypothèses!$B$10),"actuel",IF(K3=2030,"2030",IF(K3=2050,"2050","autre"))) -> autre | N3: non précisé (varie selon l'étude) | P3: Marché | Q3: USD2024 | R3: =INDEX(Hypothèses!$B$14:$B$17,MATCH(Q3,Hypothèses!$A$14:$A$17,0)) -> 1 | S3: =IF(G3="","",G3*R3) -> 850.54413 | T3: =IF(H3="","",H3*R3) -> 1138.4178 | U3: =IF(I3="","",I3*R3) -> 1478.6371 | V3: USD 2024/kW | W3: à vérifier | X3: Base Ghadim et al. 2025 (USD 2024, déjà corrigé de l'inflation).
A4: D0003 | B4: Ghadim | C4: Actual CAPEX | D4: Alcalin | E4: CAPEX | F4: Observé | G4: 1417.6096 | H4: 978.5 | I4: 1498.9178 | J4: USD 2024/kW | K4: 2017 | L4: =IF(AND(K4>=Hypothèses!$B$9,K4<=Hypothèses!$B$10),"actuel",IF(K4=2030,"2030",IF(K4=2050,"2050","autre"))) -> autre | N4: non précisé (varie selon l'étude) | P4: Marché | Q4: USD2024 | R4: =INDEX(Hypothèses!$B$14:$B$17,MATCH(Q4,Hypothèses!$A$14:$A$17,0)) -> 1 | S4: =IF(G4="","",G4*R4) -> 1417.6096 | T4: =IF(H4="","",H4*R4) -> 978.5 | U4: =IF(I4="","",I4*R4) -> 1498.9178 | V4: USD 2024/kW | W4: à vérifier | X4: Base Ghadim et al. 2025 (USD 2024, déjà corrigé de l'inflation).
A5: D0004 | B5: Ghadim | C5: Actual CAPEX | D5: Alcalin | E5: CAPEX | F5: Observé | G5: 824 | H5: 1184.5 | I5: 1545 | J5: USD 2024/kW | K5: 2019 | L5: =IF(AND(K5>=Hypothèses!$B$9,K5<=Hypothèses!$B$10),"actuel",IF(K5=2030,"2030",IF(K5=2050,"2050","autre"))) -> autre | N5: non précisé (varie selon l'étude) | P5: Marché | Q5: USD2024 | R5: =INDEX(Hypothèses!$B$14:$B$17,MATCH(Q5,Hypothèses!$A$14:$A$17,0)) -> 1 | S5: =IF(G5="","",G5*R5) -> 824 | T5: =IF(H5="","",H5*R5) -> 1184.5 | U5: =IF(I5="","",I5*R5) -> 1545 | V5: USD 2024/kW | W5: à vérifier | X5: Base Ghadim et al. 2025 (USD 2024, déjà corrigé de l'inflation).
A6: D0005 | B6: Ghadim | C6: Actual CAPEX | D6: Alcalin | E6: CAPEX | F6: Observé | G6: 772.5 | H6: 983.65 | I6: 1194.8 | J6: USD 2024/kW | K6: 2020 | L6: =IF(AND(K6>=Hypothèses!$B$9,K6<=Hypothèses!$B$10),"actuel",IF(K6=2030,"2030",IF(K6=2050,"2050","autre"))) -> actuel | N6: non précisé (varie selon l'étude) | P6: Marché | Q6: USD2024 | R6: =INDEX(Hypothèses!$B$14:$B$17,MATCH(Q6,Hypothèses!$A$14:$A$17,0)) -> 1 | S6: =IF(G6="","",G6*R6) -> 772.5 | T6: =IF(H6="","",H6*R6) -> 983.65 | U6: =IF(I6="","",I6*R6) -> 1194.8 | V6: USD 2024/kW | W6: à vérifier | X6: Base Ghadim et al. 2025 (USD 2024, déjà corrigé de l'inflation).
A7: D0006 | B7: Ghadim | C7: Actual CAPEX | D7: Alcalin | E7: CAPEX | F7: Observé | G7: 613.88 | H7: 965.625 | I7: 1317.37 | J7: USD 2024/kW | K7: 2021 | L7: =IF(AND(K7>=Hypothèses!$B$9,K7<=Hypothèses!$B$10),"actuel",IF(K7=2030,"2030",IF(K7=2050,"2050","autre"))) -> actuel | N7: non précisé (varie selon l'étude) | P7: Marché | Q7: USD2024 | R7: =INDEX(Hypothèses!$B$14:$B$17,MATCH(Q7,Hypothèses!$A$14:$A$17,0)) -> 1 | S7: =IF(G7="","",G7*R7) -> 613.88 | T7: =IF(H7="","",H7*R7) -> 965.625 | U7: =IF(I7="","",I7*R7) -> 1317.37 | V7: USD 2024/kW | W7: à vérifier | X7: Base Ghadim et al. 2025 (USD 2024, déjà corrigé de l'inflation).
A8: D0007 | B8: Ghadim | C8: Actual CAPEX | D8: Alcalin | E8: CAPEX | F8: Observé | G8: 515 | H8: 978.5 | I8: 1442 | J8: USD 2024/kW | K8: 2022 | L8: =IF(AND(K8>=Hypothèses!$B$9,K8<=Hypothèses!$B$10),"actuel",IF(K8=2030,"2030",IF(K8=2050,"2050","autre"))) -> actuel | N8: non précisé (varie selon l'étude) | P8: Marché | Q8: USD2024 | R8: =INDEX(Hypothèses!$B$14:$B$17,MATCH(Q8,Hypothèses!$A$14:$A$17,0)) -> 1 | S8: =IF(G8="","",G8*R8) -> 515 | T8: =IF(H8="","",H8*R8) -> 978.5 | U8: =IF(I8="","",I8*R8) -> 1442 | V8: USD 2024/kW | W8: à vérifier | X8: Base Ghadim et al. 2025 (USD 2024, déjà corrigé de l'inflation).
A9: D0008 | B9: Ghadim | C9: BNEF 2020 (China) | D9: Alcalin | E9: CAPEX | F9: Projection | H9: 206 | J9: USD 2024/kW | K9: 2020 | L9: =IF(AND(K9>=Hypothèses!$B$9,K9<=Hypothèses!$B$10),"actuel",IF(K9=2030,"2030",IF(K9=2050,"2050","autre"))) -> actuel | N9: non précisé (varie selon l'étude) | P9: China | Q9: USD2024 | R9: =INDEX(Hypothèses!$B$14:$B$17,MATCH(Q9,Hypothèses!$A$14:$A$17,0)) -> 1 | S9: =IF(G9="","",G9*R9) | T9: =IF(H9="","",H9*R9) -> 206 | U9: =IF(I9="","",I9*R9) | V9: USD 2024/kW | W9: à vérifier | X9: Base Ghadim et al. 2025 (USD 2024, déjà corrigé de l'inflation).
A10: D0009 | B10: Ghadim | C10: BNEF 2020 (China) | D10: Alcalin | E10: CAPEX | F10: Projection | H10: 128.75 | J10: USD 2024/kW | K10: 2030 | L10: =IF(AND(K10>=Hypothèses!$B$9,K10<=Hypothèses!$B$10),"actuel",IF(K10=2030,"2030",IF(K10=2050,"2050","autre"))) -> 2030 | N10: non précisé (varie selon l'étude) | P10: China | Q10: USD2024 | R10: =INDEX(Hypothèses!$B$14:$B$17,MATCH(Q10,Hypothèses!$A$14:$A$17,0)) -> 1 | S10: =IF(G10="","",G10*R10) | T10: =IF(H10="","",H10*R10) -> 128.75 | U10: =IF(I10="","",I10*R10) | V10: USD 2024/kW | W10: à vérifier | X10: Base Ghadim et al. 2025 (USD 2024, déjà corrigé de l'inflation).
A11: D0010 | B11: Ghadim | C11: BNEF 2020 (China) | D11: Alcalin | E11: CAPEX | F11: Projection | H11: 92.7 | J11: USD 2024/kW | K11: 2050 | L11: =IF(AND(K11>=Hypothèses!$B$9,K11<=Hypothèses!$B$10),"actuel",IF(K11=2030,"2030",IF(K11=2050,"2050","autre"))) -> 2050 | N11: non précisé (varie selon l'étude) | P11: China | Q11: USD2024 | R11: =INDEX(Hypothèses!$B$14:$B$17,MATCH(Q11,Hypothèses!$A$14:$A$17,0)) -> 1 | S11: =IF(G11="","",G11*R11) | T11: =IF(H11="","",H11*R11) -> 92.7 | U11: =IF(I11="","",I11*R11) | V11: USD 2024/kW | W11: à vérifier | X11: Base Ghadim et al. 2025 (USD 2024, déjà corrigé de l'inflation).
A12: D0011 | B12: Ghadim | C12: DEA 2025 (Denmark) - 10 MW | D12: Alcalin | E12: CAPEX | F12: Projection | G12: 1647 | H12: 2052 | I12: 2457 | J12: USD 2024/kW | K12: 2020 | L12: =IF(AND(K12>=Hypothèses!$B$9,K12<=Hypothèses!$B$10),"actuel",IF(K12=2030,"2030",IF(K12=2050,"2050","autre"))) -> actuel | M12: 10 MW | N12: non précisé (varie selon l'étude) | P12: Denmark | Q12: USD2024 | R12: =INDEX(Hypothèses!$B$14:$B$17,MATCH(Q12,Hypothèses!$A$14:$A$17,0)) -> 1 | S12: =IF(G12="","",G12*R12) -> 1647 | T12: =IF(H12="","",H12*R12) -> 2052 | U12: =IF(I12="","",I12*R12) -> 2457 | V12: USD 2024/kW | W12: à vérifier | X12: Base Ghadim et al. 2025 (USD 2024, déjà corrigé de l'inflation).
A13: D0012 | B13: Ghadim | C13: DEA 2025 (Denmark) - 10 MW | D13: Alcalin | E13: CAPEX | F13: Projection | H13: 1512 | J13: USD 2024/kW | K13: 2025 | L13: =IF(AND(K13>=Hypothèses!$B$9,K13<=Hypothèses!$B$10),"actuel",IF(K13=2030,"2030",IF(K13=2050,"2050","autre"))) -> actuel | M13: 10 MW | N13: non précisé (varie selon l'étude) | P13: Denmark | Q13: USD2024 | R13: =INDEX(Hypothèses!$B$14:$B$17,MATCH(Q13,Hypothèses!$A$14:$A$17,0)) -> 1 | S13: =IF(G13="","",G13*R13) | T13: =IF(H13="","",H13*R13) -> 1512 | U13: =IF(I13="","",I13*R13) | V13: USD 2024/kW | W13: à vérifier | X13: Base Ghadim et al. 2025 (USD 2024, déjà corrigé de l'inflation).
A14: D0013 | B14: Ghadim | C14: DEA 2025 (Denmark) - 10 MW | D14: Alcalin | E14: CAPEX | F14: Projection | H14: 945 | J14: USD 2024/kW | K14: 2030 | L14: =IF(AND(K14>=Hypothèses!$B$9,K14<=Hypothèses!$B$10),"actuel",IF(K14=2030,"2030",IF(K14=2050,"2050","autre"))) -> 2030 | M14: 10 MW | N14: non précisé (varie selon l'étude) | P14: Denmark | Q14: USD2024 | R14: =INDEX(Hypothèses!$B$14:$B$17,MATCH(Q14,Hypothèses!$A$14:$A$17,0)) -> 1 | S14: =IF(G14="","",G14*R14) | T14: =IF(H14="","",H14*R14) -> 945 | U14: =IF(I14="","",I14*R14) | V14: USD 2024/kW | W14: à vérifier | X14: Base Ghadim et al. 2025 (USD 2024, déjà corrigé de l'inflation).
A15: D0014 | B15: Ghadim | C15: DEA 2025 (Denmark) - 10 MW | D15: Alcalin | E15: CAPEX | F15: Projection | H15: 729 | J15: USD 2024/kW | K15: 2040 | L15: =IF(AND(K15>=Hypothèses!$B$9,K15<=Hypothèses!$B$10),"actuel",IF(K15=2030,"2030",IF(K15=2050,"2050","autre"))) -> autre | M15: 10 MW | N15: non précisé (varie selon l'étude) | P15: Denmark | Q15: USD2024 | R15: =INDEX(Hypothèses!$B$14:$B$17,MATCH(Q15,Hypothèses!$A$14:$A$17,0)) -> 1 | S15: =IF(G15="","",G15*R15) | T15: =IF(H15="","",H15*R15) -> 729 | U15: =IF(I15="","",I15*R15) | V15: USD 2024/kW | W15: à vérifier | X15: Base Ghadim et al. 2025 (USD 2024, déjà corrigé de l'inflation).
A16: D0015 | B16: Ghadim | C16: DEA 2025 (Denmark) - 10 MW | D16: Alcalin | E16: CAPEX | F16: Projection | G16: 405 | H16: 513 | I16: 621 | J16: USD 2024/kW | K16: 2050 | L16: =IF(AND(K16>=Hypothèses!$B$9,K16<=Hypothèses!$B$10),"actuel",IF(K16=2030,"2030",IF(K16=2050,"2050","autre"))) -> 2050 | M16: 10 MW | N16: non précisé (varie selon l'étude) | P16: Denmark | Q16: USD2024 | R16: =INDEX(Hypothèses!$B$14:$B$17,MATCH(Q16,Hypothèses!$A$14:$A$17,0)) -> 1 | S16: =IF(G16="","",G16*R16) -> 405 | T16: =IF(H16="","",H16*R16) -> 513 | U16: =IF(I16="","",I16*R16) -> 621 | V16: USD 2024/kW | W16: à vérifier | X16: Base Ghadim et al. 2025 (USD 2024, déjà corrigé de l'inflation).
A17: D0016 | B17: Ghadim | C17: DEA 2025 (Denmark) - 100 MW | D17: Alcalin | E17: CAPEX | F17: Projection | G17: 1026 | H17: 1296 | I17: 1566 | J17: USD 2024/kW | K17: 2020 | L17: =IF(AND(K17>=Hypothèses!$B$9,K17<=Hypothèses!$B$10),"actuel",IF(K17=2030,"2030",IF(K17=2050,"2050","autre"))) -> actuel | M17: 100 MW | N17: non précisé (varie selon l'étude) | P17: Denmark | Q17: USD2024 | R17: =INDEX(Hypothèses!$B$14:$B$17,MATCH(Q17,Hypothèses!$A$14:$A$17,0)) -> 1 | S17: =IF(G17="","",G17*R17) -> 1026 | T17: =IF(H17="","",H17*R17) -> 1296 | U17: =IF(I17="","",I17*R17) -> 1566 | V17: USD 2024/kW | W17: à vérifier | X17: Base Ghadim et al. 2025 (USD 2024, déjà corrigé de l'inflation).
A18: D0017 | B18: Ghadim | C18: DEA 2025 (Denmark) - 100 MW | D18: Alcalin | E18: CAPEX | F18: Projection | H18: 945 | J18: USD 2024/kW | K18: 2025 | L18: =IF(AND(K18>=Hypothèses!$B$9,K18<=Hypothèses!$B$10),"actuel",IF(K18=2030,"2030",IF(K18=2050,"2050","autre"))) -> actuel | M18: 100 MW | N18: non précisé (varie selon l'étude) | P18: Denmark | Q18: USD2024 | R18: =INDEX(Hypothèses!$B$14:$B$17,MATCH(Q18,Hypothèses!$A$14:$A$17,0)) -> 1 | S18: =IF(G18="","",G18*R18) | T18: =IF(H18="","",H18*R18) -> 945 | U18: =IF(I18="","",I18*R18) | V18: USD 2024/kW | W18: à vérifier | X18: Base Ghadim et al. 2025 (USD 2024, déjà corrigé de l'inflation).
A19: D0018 | B19: Ghadim | C19: DEA 2025 (Denmark) - 100 MW | D19: Alcalin | E19: CAPEX | F19: Projection | H19: 594 | J19: USD 2024/kW | K19: 2030 | L19: =IF(AND(K19>=Hypothèses!$B$9,K19<=Hypothèses!$B$10),"actuel",IF(K19=2030,"2030",IF(K19=2050,"2050","autre"))) -> 2030 | M19: 100 MW | N19: non précisé (varie selon l'étude) | P19: Denmark | Q19: USD2024 | R19: =INDEX(Hypothèses!$B$14:$B$17,MATCH(Q19,Hypothèses!$A$14:$A$17,0)) -> 1 | S19: =IF(G19="","",G19*R19) | T19: =IF(H19="","",H19*R19) -> 594 | U19: =IF(I19="","",I19*R19) | V19: USD 2024/kW | W19: à vérifier | X19: Base Ghadim et al. 2025 (USD 2024, déjà corrigé de l'inflation).
A20: D0019 | B20: Ghadim | C20: DEA 2025 (Denmark) - 100 MW | D20: Alcalin | E20: CAPEX | F20: Projection | H20: 459 | J20: USD 2024/kW | K20: 2040 | L20: =IF(AND(K20>=Hypothèses!$B$9,K20<=Hypothèses!$B$10),"actuel",IF(K20=2030,"2030",IF(K20=2050,"2050","autre"))) -> autre | M20: 100 MW | N20: non précisé (varie selon l'étude) | P20: Denmark | Q20: USD2024 | R20: =INDEX(Hypothèses!$B$14:$B$17,MATCH(Q20,Hypothèses!$A$14:$A$17,0)) -> 1 | S20: =IF(G20="","",G20*R20) | T20: =IF(H20="","",H20*R20) -> 459 | U20: =IF(I20="","",I20*R20) | V20: USD 2024/kW | W20: à vérifier | X20: Base Ghadim et al. 2025 (USD 2024, déjà corrigé de l'inflation).
A21: D0020 | B21: Ghadim | C21: DEA 2025 (Denmark) - 100 MW | D21: Alcalin | E21: CAPEX | F21: Projection | G21: 270 | H21: 324 | I21: 378 | J21: USD 2024/kW | K21: 2050 | L21: =IF(AND(K21>=Hypothèses!$B$9,K21<=Hypothèses!$B$10),"actuel",IF(K21=2030,"2030",IF(K21=2050,"2050","autre"))) -> 2050 | M21: 100 MW | N21: non précisé (varie selon l'étude) | P21: Denmark | Q21: USD2024 | R21: =INDEX(Hypothèses!$B$14:$B$17,MATCH(Q21,Hypothèses!$A$14:$A$17,0)) -> 1 | S21: =IF(G21="","",G21*R21) -> 270 | T21: =IF(H21="","",H21*R21) -> 324 | U21: =IF(I21="","",I21*R21) -> 378 | V21: USD 2024/kW | W21: à vérifier | X21: Base Ghadim et al. 2025 (USD 2024, déjà corrigé de l'inflation).
A22: D0021 | B22: Ghadim | C22: DEA 2025 (Denmark) - 1000 MW | D22: Alcalin | E22: CAPEX | F22: Projection | G22: 945 | H22: 1188 | I22: 1431 | J22: USD 2024/kW | K22: 2020 | L22: =IF(AND(K22>=Hypothèses!$B$9,K22<=Hypothèses!$B$10),"actuel",IF(K22=2030,"2030",IF(K22=2050,"2050","autre"))) -> actuel | M22: 1000 MW | N22: non précisé (varie selon l'étude) | P22: Denmark | Q22: USD2024 | R22: =INDEX(Hypothèses!$B$14:$B$17,MATCH(Q22,Hypothèses!$A$14:$A$17,0)) -> 1 | S22: =IF(G22="","",G22*R22) -> 945 | T22: =IF(H22="","",H22*R22) -> 1188 | U22: =IF(I22="","",I22*R22) -> 1431 | V22: USD 2024/kW | W22: à vérifier | X22: Base Ghadim et al. 2025 (USD 2024, déjà corrigé de l'inflation).
A23: D0022 | B23: Ghadim | C23: DEA 2025 (Denmark) - 1000 MW | D23: Alcalin | E23: CAPEX | F23: Projection | H23: 864 | J23: USD 2024/kW | K23: 2025 | L23: =IF(AND(K23>=Hypothèses!$B$9,K23<=Hypothèses!$B$10),"actuel",IF(K23=2030,"2030",IF(K23=2050,"2050","autre"))) -> actuel | M23: 1000 MW | N23: non précisé (varie selon l'étude) | P23: Denmark | Q23: USD2024 | R23: =INDEX(Hypothèses!$B$14:$B$17,MATCH(Q23,Hypothèses!$A$14:$A$17,0)) -> 1 | S23: =IF(G23="","",G23*R23) | T23: =IF(H23="","",H23*R23) -> 864 | U23: =IF(I23="","",I23*R23) | V23: USD 2024/kW | W23: à vérifier | X23: Base Ghadim et al. 2025 (USD 2024, déjà corrigé de l'inflation).
A24: D0023 | B24: Ghadim | C24: DEA 2025 (Denmark) - 1000 MW | D24: Alcalin | E24: CAPEX | F24: Projection | H24: 540 | J24: USD 2024/kW | K24: 2030 | L24: =IF(AND(K24>=Hypothèses!$B$9,K24<=Hypothèses!$B$10),"actuel",IF(K24=2030,"2030",IF(K24=2050,"2050","autre"))) -> 2030 | M24: 1000 MW | N24: non précisé (varie selon l'étude) | P24: Denmark | Q24: USD2024 | R24: =INDEX(Hypothèses!$B$14:$B$17,MATCH(Q24,Hypothèses!$A$14:$A$17,0)) -> 1 | S24: =IF(G24="","",G24*R24) | T24: =IF(H24="","",H24*R24) -> 540 | U24: =IF(I24="","",I24*R24) | V24: USD 2024/kW | W24: à vérifier | X24: Base Ghadim et al. 2025 (USD 2024, déjà corrigé de l'inflation).
A25: D0024 | B25: Ghadim | C25: DEA 2025 (Denmark) - 1000 MW | D25: Alcalin | E25: CAPEX | F25: Projection | H25: 432 | J25: USD 2024/kW | K25: 2040 | L25: =IF(AND(K25>=Hypothèses!$B$9,K25<=Hypothèses!$B$10),"actuel",IF(K25=2030,"2030",IF(K25=2050,"2050","autre"))) -> autre | M25: 1000 MW | N25: non précisé (varie selon l'étude) | P25: Denmark | Q25: USD2024 | R25: =INDEX(Hypothèses!$B$14:$B$17,MATCH(Q25,Hypothèses!$A$14:$A$17,0)) -> 1 | S25: =IF(G25="","",G25*R25) | T25: =IF(H25="","",H25*R25) -> 432 | U25: =IF(I25="","",I25*R25) | V25: USD 2024/kW | W25: à vérifier | X25: Base Ghadim et al. 2025 (USD 2024, déjà corrigé de l'inflation).
A26: D0025 | B26: Ghadim | C26: DEA 2025 (Denmark) - 1000 MW | D26: Alcalin | E26: CAPEX | F26: Projection | G26: 243 | H26: 297 | I26: 351 | J26: USD 2024/kW | K26: 2050 | L26: =IF(AND(K26>=Hypothèses!$B$9,K26<=Hypothèses!$B$10),"actuel",IF(K26=2030,"2030",IF(K26=2050,"2050","autre"))) -> 2050 | M26: 1000 MW | N26: non précisé (varie selon l'étude) | P26: Denmark | Q26: USD2024 | R26: =INDEX(Hypothèses!$B$14:$B$17,MATCH(Q26,Hypothèses!$A$14:$A$17,0)) -> 1 | S26: =IF(G26="","",G26*R26) -> 243 | T26: =IF(H26="","",H26*R26) -> 297 | U26: =IF(I26="","",I26*R26) -> 351 | V26: USD 2024/kW | W26: à vérifier | X26: Base Ghadim et al. 2025 (USD 2024, déjà corrigé de l'inflation).
A27: D0026 | B27: Ghadim | C27: DNV 2022 (World) | D27: Alcalin | E27: CAPEX | F27: Projection | G27: 926.28518 | H27: 1051.4549 | I27: 1166.6192 | J27: USD 2024/kW | K27: 2020 | L27: =IF(AND(K27>=Hypothèses!$B$9,K27<=Hypothèses!$B$10),"actuel",IF(K27=2030,"2030",IF(K27=2050,"2050","autre"))) -> actuel | N27: non précisé (varie selon l'étude) | P27: World | Q27: USD2024 | R27: =INDEX(Hypothèses!$B$14:$B$17,MATCH(Q27,Hypothèses!$A$14:$A$17,0)) -> 1 | S27: =IF(G27="","",G27*R27) -> 926.28518 | T27: =IF(H27="","",H27*R27) -> 1051.4549 | U27: =IF(I27="","",I27*R27) -> 1166.6192 | V27: USD 2024/kW | W27: à vérifier | X27: Base Ghadim et al. 2025 (USD 2024, déjà corrigé de l'inflation).
A28: D0027 | B28: Ghadim | C28: DNV 2022 (World) | D28: Alcalin | E28: CAPEX | F28: Projection | G28: 841.16701 | H28: 936.29884 | I28: 1031.4317 | J28: USD 2024/kW | K28: 2025 | L28: =IF(AND(K28>=Hypothèses!$B$9,K28<=Hypothèses!$B$10),"actuel",IF(K28=2030,"2030",IF(K28=2050,"2050","autre"))) -> actuel | N28: non précisé (varie selon l'étude) | P28: World | Q28: USD2024 | R28: =INDEX(Hypothèses!$B$14:$B$17,MATCH(Q28,Hypothèses!$A$14:$A$17,0)) -> 1 | S28: =IF(G28="","",G28*R28) -> 841.16701 | T28: =IF(H28="","",H28*R28) -> 936.29884 | U28: =IF(I28="","",I28*R28) -> 1031.4317 | V28: USD 2024/kW | W28: à vérifier | X28: Base Ghadim et al. 2025 (USD 2024, déjà corrigé de l'inflation).
A29: D0028 | B29: Ghadim | C29: DNV 2022 (World) | D29: Alcalin | E29: CAPEX | F29: Projection | G29: 736.02049 | H29: 836.16018 | I29: 941.30567 | J29: USD 2024/kW | K29: 2030 | L29: =IF(AND(K29>=Hypothèses!$B$9,K29<=Hypothèses!$B$10),"actuel",IF(K29=2030,"2030",IF(K29=2050,"2050","autre"))) -> 2030 | N29: non précisé (varie selon l'étude) | P29: World | Q29: USD2024 | R29: =INDEX(Hypothèses!$B$14:$B$17,MATCH(Q29,Hypothèses!$A$14:$A$17,0)) -> 1 | S29: =IF(G29="","",G29*R29) -> 736.02049 | T29: =IF(H29="","",H29*R29) -> 836.16018 | U29: =IF(I29="","",I29*R29) -> 941.30567 | V29: USD 2024/kW | W29: à vérifier | X29: Base Ghadim et al. 2025 (USD 2024, déjà corrigé de l'inflation).
A30: D0029 | B30: Ghadim | C30: DNV 2022 (World) | D30: Alcalin | E30: CAPEX | F30: Projection | G30: 620.86134 | H30: 751.04201 | I30: 881.22268 | J30: USD 2024/kW | K30: 2035 | L30: =IF(AND(K30>=Hypothèses!$B$9,K30<=Hypothèses!$B$10),"actuel",IF(K30=2030,"2030",IF(K30=2050,"2050","autre"))) -> autre | N30: non précisé (varie selon l'étude) | P30: World | Q30: USD2024 | R30: =INDEX(Hypothèses!$B$14:$B$17,MATCH(Q30,Hypothèses!$A$14:$A$17,0)) -> 1 | S30: =IF(G30="","",G30*R30) -> 620.86134 | T30: =IF(H30="","",H30*R30) -> 751.04201 | U30: =IF(I30="","",I30*R30) -> 881.22268 | V30: USD 2024/kW | W30: à vérifier | X30: Base Ghadim et al. 2025 (USD 2024, déjà corrigé de l'inflation).
A31: D0030 | B31: Ghadim | C31: DNV 2022 (World) | D31: Alcalin | E31: CAPEX | F31: Projection | G31: 520.72268 | H31: 670.93067 | I31: 826.14549 | J31: USD 2024/kW | K31: 2040 | L31: =IF(AND(K31>=Hypothèses!$B$9,K31<=Hypothèses!$B$10),"actuel",IF(K31=2030,"2030",IF(K31=2050,"2050","autre"))) -> autre | N31: non précisé (varie selon l'étude) | P31: World | Q31: USD2024 | R31: =INDEX(Hypothèses!$B$14:$B$17,MATCH(Q31,Hypothèses!$A$14:$A$17,0)) -> 1 | S31: =IF(G31="","",G31*R31) -> 520.72268 | T31: =IF(H31="","",H31*R31) -> 670.93067 | U31: =IF(I31="","",I31*R31) -> 826.14549 | V31: USD 2024/kW | W31: à vérifier | X31: Base Ghadim et al. 2025 (USD 2024, déjà corrigé de l'inflation).
A32: D0031 | B32: Ghadim | C32: DNV 2022 (World) | D32: Alcalin | E32: CAPEX | F32: Projection | G32: 430.59768 | H32: 600.83299 | I32: 776.07616 | J32: USD 2024/kW | K32: 2045 | L32: =IF(AND(K32>=Hypothèses!$B$9,K32<=Hypothèses!$B$10),"actuel",IF(K32=2030,"2030",IF(K32=2050,"2050","autre"))) -> autre | N32: non précisé (varie selon l'étude) | P32: World | Q32: USD2024 | R32: =INDEX(Hypothèses!$B$14:$B$17,MATCH(Q32,Hypothèses!$A$14:$A$17,0)) -> 1 | S32: =IF(G32="","",G32*R32) -> 430.59768 | T32: =IF(H32="","",H32*R32) -> 600.83299 | U32: =IF(I32="","",I32*R32) -> 776.07616 | V32: USD 2024/kW | W32: à vérifier | X32: Base Ghadim et al. 2025 (USD 2024, déjà corrigé de l'inflation).
A33: D0032 | B33: Ghadim | C33: DNV 2022 (World) | D33: Alcalin | E33: CAPEX | F33: Projection | G33: 355.49317 | H33: 535.74317 | I33: 731.01366 | J33: USD 2024/kW | K33: 2050 | L33: =IF(AND(K33>=Hypothèses!$B$9,K33<=Hypothèses!$B$10),"actuel",IF(K33=2030,"2030",IF(K33=2050,"2050","autre"))) -> 2050 | N33: non précisé (varie selon l'étude) | P33: World | Q33: USD2024 | R33: =INDEX(Hypothèses!$B$14:$B$17,MATCH(Q33,Hypothèses!$A$14:$A$17,0)) -> 1 | S33: =IF(G33="","",G33*R33) -> 355.49317 | T33: =IF(H33="","",H33*R33) -> 535.74317 | U33: =IF(I33="","",I33*R33) -> 731.01366 | V33: USD 2024/kW | W33: à vérifier | X33: Base Ghadim et al. 2025 (USD 2024, déjà corrigé de l'inflation).
A34: D0033 | B34: Ghadim | C34: Gandhi et al 2022 (UAE) | D34: Alcalin | E34: CAPEX | F34: Projection | G34: 824 | J34: USD 2024/kW | K34: 2020 | L34: =IF(AND(K34>=Hypothèses!$B$9,K34<=Hypothèses!$B$10),"actuel",IF(K34=2030,"2030",IF(K34=2050,"2050","autre"))) -> actuel | N34: non précisé (varie selon l'étude) | P34: UAE | Q34: USD2024 | R34: =INDEX(Hypothèses!$B$14:$B$17,MATCH(Q34,Hypothèses!$A$14:$A$17,0)) -> 1 | S34: =IF(G34="","",G34*R34) -> 824 | T34: =IF(H34="","",H34*R34) | U34: =IF(I34="","",I34*R34) | V34: USD 2024/kW | W34: à vérifier | X34: Base Ghadim et al. 2025 (USD 2024, déjà corrigé de l'inflation).
A35: D0034 | B35: Ghadim | C35: Gandhi et al 2022 (UAE) | D35: Alcalin | E35: CAPEX | F35: Projection | G35: 352.26 | J35: USD 2024/kW | K35: 2025 | L35: =IF(AND(K35>=Hypothèses!$B$9,K35<=Hypothèses!$B$10),"actuel",IF(K35=2030,"2030",IF(K35=2050,"2050","autre"))) -> actuel | N35: non précisé (varie selon l'étude) | P35: UAE | Q35: USD2024 | R35: =INDEX(Hypothèses!$B$14:$B$17,MATCH(Q35,Hypothèses!$A$14:$A$17,0)) -> 1 | S35: =IF(G35="","",G35*R35) -> 352.26 | T35: =IF(H35="","",H35*R35) | U35: =IF(I35="","",I35*R35) | V35: USD 2024/kW | W35: à vérifier | X35: Base Ghadim et al. 2025 (USD 2024, déjà corrigé de l'inflation).
A36: D0035 | B36: Ghadim | C36: Gandhi et al 2022 (UAE) | D36: Alcalin | E36: CAPEX | F36: Projection | G36: 196.73 | J36: USD 2024/kW | K36: 2030 | L36: =IF(AND(K36>=Hypothèses!$B$9,K36<=Hypothèses!$B$10),"actuel",IF(K36=2030,"2030",IF(K36=2050,"2050","autre"))) -> 2030 | N36: non précisé (varie selon l'étude) | P36: UAE | Q36: USD2024 | R36: =INDEX(Hypothèses!$B$14:$B$17,MATCH(Q36,Hypothèses!$A$14:$A$17,0)) -> 1 | S36: =IF(G36="","",G36*R36) -> 196.73 | T36: =IF(H36="","",H36*R36) | U36: =IF(I36="","",I36*R36) | V36: USD 2024/kW | W36: à vérifier | X36: Base Ghadim et al. 2025 (USD 2024, déjà corrigé de l'inflation).
A37: D0036 | B37: Ghadim | C37: Gandhi et al 2022 (UAE) | D37: Alcalin | E37: CAPEX | F37: Projection | G37: 76.22 | J37: USD 2024/kW | K37: 2050 | L37: =IF(AND(K37>=Hypothèses!$B$9,K37<=Hypothèses!$B$10),"actuel",IF(K37=2030,"2030",IF(K37=2050,"2050","autre"))) -> 2050 | N37: non précisé (varie selon l'étude) | P37: UAE | Q37: USD2024 | R37: =INDEX(Hypothèses!$B$14:$B$17,MATCH(Q37,Hypothèses!$A$14:$A$17,0)) -> 1 | S37: =IF(G37="","",G37*R37) -> 76.22 | T37: =IF(H37="","",H37*R37) | U37: =IF(I37="","",I37*R37) | V37: USD 2024/kW | W37: à vérifier | X37: Base Ghadim et al. 2025 (USD 2024, déjà corrigé de l'inflation).
A38: D0037 | B38: Ghadim | C38: George et al. 2022 (Germany) | D38: Alcalin | E38: CAPEX | F38: Projection | G38: 667.36374 | H38: 742.78846 | I38: 811.33793 | J38: USD 2024/kW | K38: 2020 | L38: =IF(AND(K38>=Hypothèses!$B$9,K38<=Hypothèses!$B$10),"actuel",IF(K38=2030,"2030",IF(K38=2050,"2050","autre"))) -> actuel | N38: non précisé (varie selon l'étude) | P38: Germany | Q38: USD2024 | R38: =INDEX(Hypothèses!$B$14:$B$17,MATCH(Q38,Hypothèses!$A$14:$A$17,0)) -> 1 | S38: =IF(G38="","",G38*R38) -> 667.36374 | T38: =IF(H38="","",H38*R38) -> 742.78846 | U38: =IF(I38="","",I38*R38) -> 811.33793 | V38: USD 2024/kW | W38: à vérifier | X38: Base Ghadim et al. 2025 (USD 2024, déjà corrigé de l'inflation).
A39: D0038 | B39: Ghadim | C39: George et al. 2022 (Germany) | D39: Alcalin | E39: CAPEX | F39: Projection | G39: 397.19969 | H39: 575.89776 | I39: 775.76827 | J39: USD 2024/kW | K39: 2025 | L39: =IF(AND(K39>=Hypothèses!$B$9,K39<=Hypothèses!$B$10),"actuel",IF(K39=2030,"2030",IF(K39=2050,"2050","autre"))) -> actuel | N39: non précisé (varie selon l'étude) | P39: Germany | Q39: USD2024 | R39: =INDEX(Hypothèses!$B$14:$B$17,MATCH(Q39,Hypothèses!$A$14:$A$17,0)) -> 1 | S39: =IF(G39="","",G39*R39) -> 397.19969 | T39: =IF(H39="","",H39*R39) -> 575.89776 | U39: =IF(I39="","",I39*R39) -> 775.76827 | V39: USD 2024/kW | W39: à vérifier | X39: Base Ghadim et al. 2025 (USD 2024, déjà corrigé de l'inflation).
A40: D0039 | B40: Ghadim | C40: George et al. 2022 (Germany) | D40: Alcalin | E40: CAPEX | F40: Projection | G40: 245.6035 | H40: 444.62723 | I40: 744.4325 | J40: USD 2024/kW | K40: 2030 | L40: =IF(AND(K40>=Hypothèses!$B$9,K40<=Hypothèses!$B$10),"actuel",IF(K40=2030,"2030",IF(K40=2050,"2050","autre"))) -> 2030 | N40: non précisé (varie selon l'étude) | P40: Germany | Q40: USD2024 | R40: =INDEX(Hypothèses!$B$14:$B$17,MATCH(Q40,Hypothèses!$A$14:$A$17,0)) -> 1 | S40: =IF(G40="","",G40*R40) -> 245.6035 | T40: =IF(H40="","",H40*R40) -> 444.62723 | U40: =IF(I40="","",I40*R40) -> 744.4325 | V40: USD 2024/kW | W40: à vérifier | X40: Base Ghadim et al. 2025 (USD 2024, déjà corrigé de l'inflation).
...

Sheet Synthèse
A1: Synthèse CAPEX et rendement par technologie et horizon
A2: CAPEX en USD 2024/kW (conversion : onglet Hypothèses) ; rendement en % base PCI. Statistiques sur les valeurs typiques (moyenne de chaque étude). « Bornes études » = plus petit min et plus grand max publiés par les études qui donnent une fourchette.
A4: Technologie | B4: Horizon | C4: CAPEX Nb valeurs | D4: CAPEX Nb sources | E4: CAPEX Min | F4: CAPEX Médiane | G4: CAPEX Max | H4: CAPEX Borne basse études | I4: CAPEX Borne haute études | J4: Rendement Nb valeurs | K4: Rendement Nb sources | L4: Rendement Min | M4: Rendement Médiane | N4: Rendement Max
A5: Alcalin | B5: actuel | C5: =SUMPRODUCT((Données!$D$2:$D$800=$A5)*(Données!$E$2:$E$800="CAPEX")*(Données!$L$2:$L$800=$B5)*ISNUMBER(Données!$T$2:$T$800)) -> 32 | D5: =SUMPRODUCT(((Données!$D$2:$D$800=$A5)*(Données!$E$2:$E$800="CAPEX")*(Données!$L$2:$L$800=$B5)*ISNUMBER(Données!$T$2:$T$800))/(COUNTIFS(Données!$C$2:$C$800,Données!$C$2:$C$800,Données!$D$2:$D$800,Données!$D$2:$D$800,Données!$E$2:$E$800,Données!$E$2:$E$800,Données!$L$2:$L$800,Données!$L$2:$L$800)+(Données!$C$2:$C$800=""))) -> 18 | E5: {=IF(C5=0,"—",MIN(IF((Données!$D$2:$D$800=$A5)*(Données!$E$2:$E$800="CAPEX")*(Données!$L$2:$L$800=$B5)*ISNUMBER(Données!$T$2:$T$800),Données!$T$2:$T$800)))} -> 206 | F5: {=IF(C5=0,"—",MEDIAN(IF((Données!$D$2:$D$800=$A5)*(Données!$E$2:$E$800="CAPEX")*(Données!$L$2:$L$800=$B5)*ISNUMBER(Données!$T$2:$T$800),Données!$T$2:$T$800)))} -> 981.075 | G5: {=IF(C5=0,"—",MAX(IF((Données!$D$2:$D$800=$A5)*(Données!$E$2:$E$800="CAPEX")*(Données!$L$2:$L$800=$B5)*ISNUMBER(Données!$T$2:$T$800),Données!$T$2:$T$800)))} -> 2146.1199 | H5: {=IF(SUMPRODUCT((Données!$D$2:$D$800=$A5)*(Données!$E$2:$E$800="CAPEX")*(Données!$L$2:$L$800=$B5)*ISNUMBER(Données!$S$2:$S$800))=0,"—",MIN(IF((Données!$D$2:$D$800=$A5)*(Données!$E$2:$E$800="CAPEX")*(Données!$L$2:$L$800=$B5)*ISNUMBER(Données!$S$2:$S$800),Données!$S$2:$S$800)))} -> 352.26 | I5: {=IF(SUMPRODUCT((Données!$D$2:$D$800=$A5)*(Données!$E$2:$E$800="CAPEX")*(Données!$L$2:$L$800=$B5)*ISNUMBER(Données!$U$2:$U$800))=0,"—",MAX(IF((Données!$D$2:$D$800=$A5)*(Données!$E$2:$E$800="CAPEX")*(Données!$L$2:$L$800=$B5)*ISNUMBER(Données!$U$2:$U$800),Données!$U$2:$U$800)))} -> 2457 | J5: =SUMPRODUCT((Données!$D$2:$D$800=$A5)*(Données!$E$2:$E$800="Rendement (PCI)")*(Données!$L$2:$L$800=$B5)*ISNUMBER(Données!$T$2:$T$800)) -> 0 | K5: =SUMPRODUCT(((Données!$D$2:$D$800=$A5)*(Données!$E$2:$E$800="Rendement (PCI)")*(Données!$L$2:$L$800=$B5)*ISNUMBER(Données!$T$2:$T$800))/(COUNTIFS(Données!$C$2:$C$800,Données!$C$2:$C$800,Données!$D$2:$D$800,Données!$D$2:$D$800,Données!$E$2:$E$800,Données!$E$2:$E$800,Données!$L$2:$L$800,Données!$L$2:$L$800)+(Données!$C$2:$C$800=""))) -> 0 | L5: {=IF(J5=0,"—",MIN(IF((Données!$D$2:$D$800=$A5)*(Données!$E$2:$E$800="Rendement (PCI)")*(Données!$L$2:$L$800=$B5)*ISNUMBER(Données!$T$2:$T$800),Données!$T$2:$T$800)))} -> — | M5: {=IF(J5=0,"—",MEDIAN(IF((Données!$D$2:$D$800=$A5)*(Données!$E$2:$E$800="Rendement (PCI)")*(Données!$L$2:$L$800=$B5)*ISNUMBER(Données!$T$2:$T$800),Données!$T$2:$T$800)))} -> — | N5: {=IF(J5=0,"—",MAX(IF((Données!$D$2:$D$800=$A5)*(Données!$E$2:$E$800="Rendement (PCI)")*(Données!$L$2:$L$800=$B5)*ISNUMBER(Données!$T$2:$T$800),Données!$T$2:$T$800)))} -> —
A6: Alcalin | B6: 2030 | C6: =SUMPRODUCT((Données!$D$2:$D$800=$A6)*(Données!$E$2:$E$800="CAPEX")*(Données!$L$2:$L$800=$B6)*ISNUMBER(Données!$T$2:$T$800)) -> 13 | D6: =SUMPRODUCT(((Données!$D$2:$D$800=$A6)*(Données!$E$2:$E$800="CAPEX")*(Données!$L$2:$L$800=$B6)*ISNUMBER(Données!$T$2:$T$800))/(COUNTIFS(Données!$C$2:$C$800,Données!$C$2:$C$800,Données!$D$2:$D$800,Données!$D$2:$D$800,Données!$E$2:$E$800,Données!$E$2:$E$800,Données!$L$2:$L$800,Données!$L$2:$L$800)+(Données!$C$2:$C$800=""))) -> 13 | E6: {=IF(C6=0,"—",MIN(IF((Données!$D$2:$D$800=$A6)*(Données!$E$2:$E$800="CAPEX")*(Données!$L$2:$L$800=$B6)*ISNUMBER(Données!$T$2:$T$800),Données!$T$2:$T$800)))} -> 128.75 | F6: {=IF(C6=0,"—",MEDIAN(IF((Données!$D$2:$D$800=$A6)*(Données!$E$2:$E$800="CAPEX")*(Données!$L$2:$L$800=$B6)*ISNUMBER(Données!$T$2:$T$800),Données!$T$2:$T$800)))} -> 594 | G6: {=IF(C6=0,"—",MAX(IF((Données!$D$2:$D$800=$A6)*(Données!$E$2:$E$800="CAPEX")*(Données!$L$2:$L$800=$B6)*ISNUMBER(Données!$T$2:$T$800),Données!$T$2:$T$800)))} -> 945 | H6: {=IF(SUMPRODUCT((Données!$D$2:$D$800=$A6)*(Données!$E$2:$E$800="CAPEX")*(Données!$L$2:$L$800=$B6)*ISNUMBER(Données!$S$2:$S$800))=0,"—",MIN(IF((Données!$D$2:$D$800=$A6)*(Données!$E$2:$E$800="CAPEX")*(Données!$L$2:$L$800=$B6)*ISNUMBER(Données!$S$2:$S$800),Données!$S$2:$S$800)))} -> 196.73 | I6: {=IF(SUMPRODUCT((Données!$D$2:$D$800=$A6)*(Données!$E$2:$E$800="CAPEX")*(Données!$L$2:$L$800=$B6)*ISNUMBER(Données!$U$2:$U$800))=0,"—",MAX(IF((Données!$D$2:$D$800=$A6)*(Données!$E$2:$E$800="CAPEX")*(Données!$L$2:$L$800=$B6)*ISNUMBER(Données!$U$2:$U$800),Données!$U$2:$U$800)))} -> 1141.3383 | J6: =SUMPRODUCT((Données!$D$2:$D$800=$A6)*(Données!$E$2:$E$800="Rendement (PCI)")*(Données!$L$2:$L$800=$B6)*ISNUMBER(Données!$T$2:$T$800)) -> 0 | K6: =SUMPRODUCT(((Données!$D$2:$D$800=$A6)*(Données!$E$2:$E$800="Rendement (PCI)")*(Données!$L$2:$L$800=$B6)*ISNUMBER(Données!$T$2:$T$800))/(COUNTIFS(Données!$C$2:$C$800,Données!$C$2:$C$800,Données!$D$2:$D$800,Données!$D$2:$D$800,Données!$E$2:$E$800,Données!$E$2:$E$800,Données!$L$2:$L$800,Données!$L$2:$L$800)+(Données!$C$2:$C$800=""))) -> 0 | L6: {=IF(J6=0,"—",MIN(IF((Données!$D$2:$D$800=$A6)*(Données!$E$2:$E$800="Rendement (PCI)")*(Données!$L$2:$L$800=$B6)*ISNUMBER(Données!$T$2:$T$800),Données!$T$2:$T$800)))} -> — | M6: {=IF(J6=0,"—",MEDIAN(IF((Données!$D$2:$D$800=$A6)*(Données!$E$2:$E$800="Rendement (PCI)")*(Données!$L$2:$L$800=$B6)*ISNUMBER(Données!$T$2:$T$800),Données!$T$2:$T$800)))} -> — | N6: {=IF(J6=0,"—",MAX(IF((Données!$D$2:$D$800=$A6)*(Données!$E$2:$E$800="Rendement (PCI)")*(Données!$L$2:$L$800=$B6)*ISNUMBER(Données!$T$2:$T$800),Données!$T$2:$T$800)))} -> —
A7: Alcalin | B7: 2050 | C7: =SUMPRODUCT((Données!$D$2:$D$800=$A7)*(Données!$E$2:$E$800="CAPEX")*(Données!$L$2:$L$800=$B7)*ISNUMBER(Données!$T$2:$T$800)) -> 13 | D7: =SUMPRODUCT(((Données!$D$2:$D$800=$A7)*(Données!$E$2:$E$800="CAPEX")*(Données!$L$2:$L$800=$B7)*ISNUMBER(Données!$T$2:$T$800))/(COUNTIFS(Données!$C$2:$C$800,Données!$C$2:$C$800,Données!$D$2:$D$800,Données!$D$2:$D$800,Données!$E$2:$E$800,Données!$E$2:$E$800,Données!$L$2:$L$800,Données!$L$2:$L$800)+(Données!$C$2:$C$800=""))) -> 13 | E7: {=IF(C7=0,"—",MIN(IF((Données!$D$2:$D$800=$A7)*(Données!$E$2:$E$800="CAPEX")*(Données!$L$2:$L$800=$B7)*ISNUMBER(Données!$T$2:$T$800),Données!$T$2:$T$800)))} -> 79.230769 | F7: {=IF(C7=0,"—",MEDIAN(IF((Données!$D$2:$D$800=$A7)*(Données!$E$2:$E$800="CAPEX")*(Données!$L$2:$L$800=$B7)*ISNUMBER(Données!$T$2:$T$800),Données!$T$2:$T$800)))} -> 368.85845 | G7: {=IF(C7=0,"—",MAX(IF((Données!$D$2:$D$800=$A7)*(Données!$E$2:$E$800="CAPEX")*(Données!$L$2:$L$800=$B7)*ISNUMBER(Données!$T$2:$T$800),Données!$T$2:$T$800)))} -> 710.42494 | H7: {=IF(SUMPRODUCT((Données!$D$2:$D$800=$A7)*(Données!$E$2:$E$800="CAPEX")*(Données!$L$2:$L$800=$B7)*ISNUMBER(Données!$S$2:$S$800))=0,"—",MIN(IF((Données!$D$2:$D$800=$A7)*(Données!$E$2:$E$800="CAPEX")*(Données!$L$2:$L$800=$B7)*ISNUMBER(Données!$S$2:$S$800),Données!$S$2:$S$800)))} -> 76.22 | I7: {=IF(SUMPRODUCT((Données!$D$2:$D$800=$A7)*(Données!$E$2:$E$800="CAPEX")*(Données!$L$2:$L$800=$B7)*ISNUMBER(Données!$U$2:$U$800))=0,"—",MAX(IF((Données!$D$2:$D$800=$A7)*(Données!$E$2:$E$800="CAPEX")*(Données!$L$2:$L$800=$B7)*ISNUMBER(Données!$U$2:$U$800),Données!$U$2:$U$800)))} -> 1024.8757 | J7: =SUMPRODUCT((Données!$D$2:$D$800=$A7)*(Données!$E$2:$E$800="Rendement (PCI)")*(Données!$L$2:$L$800=$B7)*ISNUMBER(Données!$T$2:$T$800)) -> 0 | K7: =SUMPRODUCT(((Données!$D$2:$D$800=$A7)*(Données!$E$2:$E$800="Rendement (PCI)")*(Données!$L$2:$L$800=$B7)*ISNUMBER(Données!$T$2:$T$800))/(COUNTIFS(Données!$C$2:$C$800,Données!$C$2:$C$800,Données!$D$2:$D$800,Données!$D$2:$D$800,Données!$E$2:$E$800,Données!$E$2:$E$800,Données!$L$2:$L$800,Données!$L$2:$L$800)+(Données!$C$2:$C$800=""))) -> 0 | L7: {=IF(J7=0,"—",MIN(IF((Données!$D$2:$D$800=$A7)*(Données!$E$2:$E$800="Rendement (PCI)")*(Données!$L$2:$L$800=$B7)*ISNUMBER(Données!$T$2:$T$800),Données!$T$2:$T$800)))} -> — | M7: {=IF(J7=0,"—",MEDIAN(IF((Données!$D$2:$D$800=$A7)*(Données!$E$2:$E$800="Rendement (PCI)")*(Données!$L$2:$L$800=$B7)*ISNUMBER(Données!$T$2:$T$800),Données!$T$2:$T$800)))} -> — | N7: {=IF(J7=0,"—",MAX(IF((Données!$D$2:$D$800=$A7)*(Données!$E$2:$E$800="Rendement (PCI)")*(Données!$L$2:$L$800=$B7)*ISNUMBER(Données!$T$2:$T$800),Données!$T$2:$T$800)))} -> —
A8: PEM | B8: actuel | C8: =SUMPRODUCT((Données!$D$2:$D$800=$A8)*(Données!$E$2:$E$800="CAPEX")*(Données!$L$2:$L$800=$B8)*ISNUMBER(Données!$T$2:$T$800)) -> 48 | D8: =SUMPRODUCT(((Données!$D$2:$D$800=$A8)*(Données!$E$2:$E$800="CAPEX")*(Données!$L$2:$L$800=$B8)*ISNUMBER(Données!$T$2:$T$800))/(COUNTIFS(Données!$C$2:$C$800,Données!$C$2:$C$800,Données!$D$2:$D$800,Données!$D$2:$D$800,Données!$E$2:$E$800,Données!$E$2:$E$800,Données!$L$2:$L$800,Données!$L$2:$L$800)+(Données!$C$2:$C$800=""))) -> 22 | E8: {=IF(C8=0,"—",MIN(IF((Données!$D$2:$D$800=$A8)*(Données!$E$2:$E$800="CAPEX")*(Données!$L$2:$L$800=$B8)*ISNUMBER(Données!$T$2:$T$800),Données!$T$2:$T$800)))} -> 555.71075 | F8: {=IF(C8=0,"—",MEDIAN(IF((Données!$D$2:$D$800=$A8)*(Données!$E$2:$E$800="CAPEX")*(Données!$L$2:$L$800=$B8)*ISNUMBER(Données!$T$2:$T$800),Données!$T$2:$T$800)))} -> 1226.112 | G8: {=IF(C8=0,"—",MAX(IF((Données!$D$2:$D$800=$A8)*(Données!$E$2:$E$800="CAPEX")*(Données!$L$2:$L$800=$B8)*ISNUMBER(Données!$T$2:$T$800),Données!$T$2:$T$800)))} -> 2628.9969 | H8: {=IF(SUMPRODUCT((Données!$D$2:$D$800=$A8)*(Données!$E$2:$E$800="CAPEX")*(Données!$L$2:$L$800=$B8)*ISNUMBER(Données!$S$2:$S$800))=0,"—",MIN(IF((Données!$D$2:$D$800=$A8)*(Données!$E$2:$E$800="CAPEX")*(Données!$L$2:$L$800=$B8)*ISNUMBER(Données!$S$2:$S$800),Données!$S$2:$S$800)))} -> 357.72791 | I8: {=IF(SUMPRODUCT((Données!$D$2:$D$800=$A8)*(Données!$E$2:$E$800="CAPEX")*(Données!$L$2:$L$800=$B8)*ISNUMBER(Données!$U$2:$U$800))=0,"—",MAX(IF((Données!$D$2:$D$800=$A8)*(Données!$E$2:$E$800="CAPEX")*(Données!$L$2:$L$800=$B8)*ISNUMBER(Données!$U$2:$U$800),Données!$U$2:$U$800)))} -> 2769.876 | J8: =SUMPRODUCT((Données!$D$2:$D$800=$A8)*(Données!$E$2:$E$800="Rendement (PCI)")*(Données!$L$2:$L$800=$B8)*ISNUMBER(Données!$T$2:$T$800)) -> 1 | K8: =SUMPRODUCT(((Données!$D$2:$D$800=$A8)*(Données!$E$2:$E$800="Rendement (PCI)")*(Données!$L$2:$L$800=$B8)*ISNUMBER(Données!$T$2:$T$800))/(COUNTIFS(Données!$C$2:$C$800,Données!$C$2:$C$800,Données!$D$2:$D$800,Données!$D$2:$D$800,Données!$E$2:$E$800,Données!$E$2:$E$800,Données!$L$2:$L$800,Données!$L$2:$L$800)+(Données!$C$2:$C$800=""))) -> 1 | L8: {=IF(J8=0,"—",MIN(IF((Données!$D$2:$D$800=$A8)*(Données!$E$2:$E$800="Rendement (PCI)")*(Données!$L$2:$L$800=$B8)*ISNUMBER(Données!$T$2:$T$800),Données!$T$2:$T$800)))} -> 65 | M8: {=IF(J8=0,"—",MEDIAN(IF((Données!$D$2:$D$800=$A8)*(Données!$E$2:$E$800="Rendement (PCI)")*(Données!$L$2:$L$800=$B8)*ISNUMBER(Données!$T$2:$T$800),Données!$T$2:$T$800)))} -> 65 | N8: {=IF(J8=0,"—",MAX(IF((Données!$D$2:$D$800=$A8)*(Données!$E$2:$E$800="Rendement (PCI)")*(Données!$L$2:$L$800=$B8)*ISNUMBER(Données!$T$2:$T$800),Données!$T$2:$T$800)))} -> 65
A9: PEM | B9: 2030 | C9: =SUMPRODUCT((Données!$D$2:$D$800=$A9)*(Données!$E$2:$E$800="CAPEX")*(Données!$L$2:$L$800=$B9)*ISNUMBER(Données!$T$2:$T$800)) -> 16 | D9: =SUMPRODUCT(((Données!$D$2:$D$800=$A9)*(Données!$E$2:$E$800="CAPEX")*(Données!$L$2:$L$800=$B9)*ISNUMBER(Données!$T$2:$T$800))/(COUNTIFS(Données!$C$2:$C$800,Données!$C$2:$C$800,Données!$D$2:$D$800,Données!$D$2:$D$800,Données!$E$2:$E$800,Données!$E$2:$E$800,Données!$L$2:$L$800,Données!$L$2:$L$800)+(Données!$C$2:$C$800=""))) -> 16 | E9: {=IF(C9=0,"—",MIN(IF((Données!$D$2:$D$800=$A9)*(Données!$E$2:$E$800="CAPEX")*(Données!$L$2:$L$800=$B9)*ISNUMBER(Données!$T$2:$T$800),Données!$T$2:$T$800)))} -> 361.12691 | F9: {=IF(C9=0,"—",MEDIAN(IF((Données!$D$2:$D$800=$A9)*(Données!$E$2:$E$800="CAPEX")*(Données!$L$2:$L$800=$B9)*ISNUMBER(Données!$T$2:$T$800),Données!$T$2:$T$800)))} -> 645.875 | G9: {=IF(C9=0,"—",MAX(IF((Données!$D$2:$D$800=$A9)*(Données!$E$2:$E$800="CAPEX")*(Données!$L$2:$L$800=$B9)*ISNUMBER(Données!$T$2:$T$800),Données!$T$2:$T$800)))} -> 1181.6366 | H9: {=IF(SUMPRODUCT((Données!$D$2:$D$800=$A9)*(Données!$E$2:$E$800="CAPEX")*(Données!$L$2:$L$800=$B9)*ISNUMBER(Données!$S$2:$S$800))=0,"—",MIN(IF((Données!$D$2:$D$800=$A9)*(Données!$E$2:$E$800="CAPEX")*(Données!$L$2:$L$800=$B9)*ISNUMBER(Données!$S$2:$S$800),Données!$S$2:$S$800)))} -> 197.13309 | I9: {=IF(SUMPRODUCT((Données!$D$2:$D$800=$A9)*(Données!$E$2:$E$800="CAPEX")*(Données!$L$2:$L$800=$B9)*ISNUMBER(Données!$U$2:$U$800))=0,"—",MAX(IF((Données!$D$2:$D$800=$A9)*(Données!$E$2:$E$800="CAPEX")*(Données!$L$2:$L$800=$B9)*ISNUMBER(Données!$U$2:$U$800),Données!$U$2:$U$800)))} -> 1405.95 | J9: =SUMPRODUCT((Données!$D$2:$D$800=$A9)*(Données!$E$2:$E$800="Rendement (PCI)")*(Données!$L$2:$L$800=$B9)*ISNUMBER(Données!$T$2:$T$800)) -> 0 | K9: =SUMPRODUCT(((Données!$D$2:$D$800=$A9)*(Données!$E$2:$E$800="Rendement (PCI)")*(Données!$L$2:$L$800=$B9)*ISNUMBER(Données!$T$2:$T$800))/(COUNTIFS(Données!$C$2:$C$800,Données!$C$2:$C$800,Données!$D$2:$D$800,Données!$D$2:$D$800,Données!$E$2:$E$800,Données!$E$2:$E$800,Données!$L$2:$L$800,Données!$L$2:$L$800)+(Données!$C$2:$C$800=""))) -> 0 | L9: {=IF(J9=0,"—",MIN(IF((Données!$D$2:$D$800=$A9)*(Données!$E$2:$E$800="Rendement (PCI)")*(Données!$L$2:$L$800=$B9)*ISNUMBER(Données!$T$2:$T$800),Données!$T$2:$T$800)))} -> — | M9: {=IF(J9=0,"—",MEDIAN(IF((Données!$D$2:$D$800=$A9)*(Données!$E$2:$E$800="Rendement (PCI)")*(Données!$L$2:$L$800=$B9)*ISNUMBER(Données!$T$2:$T$800),Données!$T$2:$T$800)))} -> — | N9: {=IF(J9=0,"—",MAX(IF((Données!$D$2:$D$800=$A9)*(Données!$E$2:$E$800="Rendement (PCI)")*(Données!$L$2:$L$800=$B9)*ISNUMBER(Données!$T$2:$T$800),Données!$T$2:$T$800)))} -> —
A10: PEM | B10: 2050 | C10: =SUMPRODUCT((Données!$D$2:$D$800=$A10)*(Données!$E$2:$E$800="CAPEX")*(Données!$L$2:$L$800=$B10)*ISNUMBER(Données!$T$2:$T$800)) -> 14 | D10: =SUMPRODUCT(((Données!$D$2:$D$800=$A10)*(Données!$E$2:$E$800="CAPEX")*(Données!$L$2:$L$800=$B10)*ISNUMBER(Données!$T$2:$T$800))/(COUNTIFS(Données!$C$2:$C$800,Données!$C$2:$C$800,Données!$D$2:$D$800,Données!$D$2:$D$800,Données!$E$2:$E$800,Données!$E$2:$E$800,Données!$L$2:$L$800,Données!$L$2:$L$800)+(Données!$C$2:$C$800=""))) -> 14 | E10: {=IF(C10=0,"—",MIN(IF((Données!$D$2:$D$800=$A10)*(Données!$E$2:$E$800="CAPEX")*(Données!$L$2:$L$800=$B10)*ISNUMBER(Données!$T$2:$T$800),Données!$T$2:$T$800)))} -> 154.5 | F10: {=IF(C10=0,"—",MEDIAN(IF((Données!$D$2:$D$800=$A10)*(Données!$E$2:$E$800="CAPEX")*(Données!$L$2:$L$800=$B10)*ISNUMBER(Données!$T$2:$T$800),Données!$T$2:$T$800)))} -> 351.115 | G10: {=IF(C10=0,"—",MAX(IF((Données!$D$2:$D$800=$A10)*(Données!$E$2:$E$800="CAPEX")*(Données!$L$2:$L$800=$B10)*ISNUMBER(Données!$T$2:$T$800),Données!$T$2:$T$800)))} -> 731.01366 | H10: {=IF(SUMPRODUCT((Données!$D$2:$D$800=$A10)*(Données!$E$2:$E$800="CAPEX")*(Données!$L$2:$L$800=$B10)*ISNUMBER(Données!$S$2:$S$800))=0,"—",MIN(IF((Données!$D$2:$D$800=$A10)*(Données!$E$2:$E$800="CAPEX")*(Données!$L$2:$L$800=$B10)*ISNUMBER(Données!$S$2:$S$800),Données!$S$2:$S$800)))} -> 56.080925 | I10: {=IF(SUMPRODUCT((Données!$D$2:$D$800=$A10)*(Données!$E$2:$E$800="CAPEX")*(Données!$L$2:$L$800=$B10)*ISNUMBER(Données!$U$2:$U$800))=0,"—",MAX(IF((Données!$D$2:$D$800=$A10)*(Données!$E$2:$E$800="CAPEX")*(Données!$L$2:$L$800=$B10)*ISNUMBER(Données!$U$2:$U$800),Données!$U$2:$U$800)))} -> 1031.4317 | J10: =SUMPRODUCT((Données!$D$2:$D$800=$A10)*(Données!$E$2:$E$800="Rendement (PCI)")*(Données!$L$2:$L$800=$B10)*ISNUMBER(Données!$T$2:$T$800)) -> 0 | K10: =SUMPRODUCT(((Données!$D$2:$D$800=$A10)*(Données!$E$2:$E$800="Rendement (PCI)")*(Données!$L$2:$L$800=$B10)*ISNUMBER(Données!$T$2:$T$800))/(COUNTIFS(Données!$C$2:$C$800,Données!$C$2:$C$800,Données!$D$2:$D$800,Données!$D$2:$D$800,Données!$E$2:$E$800,Données!$E$2:$E$800,Données!$L$2:$L$800,Données!$L$2:$L$800)+(Données!$C$2:$C$800=""))) -> 0 | L10: {=IF(J10=0,"—",MIN(IF((Données!$D$2:$D$800=$A10)*(Données!$E$2:$E$800="Rendement (PCI)")*(Données!$L$2:$L$800=$B10)*ISNUMBER(Données!$T$2:$T$800),Données!$T$2:$T$800)))} -> — | M10: {=IF(J10=0,"—",MEDIAN(IF((Données!$D$2:$D$800=$A10)*(Données!$E$2:$E$800="Rendement (PCI)")*(Données!$L$2:$L$800=$B10)*ISNUMBER(Données!$T$2:$T$800),Données!$T$2:$T$800)))} -> — | N10: {=IF(J10=0,"—",MAX(IF((Données!$D$2:$D$800=$A10)*(Données!$E$2:$E$800="Rendement (PCI)")*(Données!$L$2:$L$800=$B10)*ISNUMBER(Données!$T$2:$T$800),Données!$T$2:$T$800)))} -> —
A11: SOEC | B11: actuel | C11: =SUMPRODUCT((Données!$D$2:$D$800=$A11)*(Données!$E$2:$E$800="CAPEX")*(Données!$L$2:$L$800=$B11)*ISNUMBER(Données!$T$2:$T$800)) -> 0 | D11: =SUMPRODUCT(((Données!$D$2:$D$800=$A11)*(Données!$E$2:$E$800="CAPEX")*(Données!$L$2:$L$800=$B11)*ISNUMBER(Données!$T$2:$T$800))/(COUNTIFS(Données!$C$2:$C$800,Données!$C$2:$C$800,Données!$D$2:$D$800,Données!$D$2:$D$800,Données!$E$2:$E$800,Données!$E$2:$E$800,Données!$L$2:$L$800,Données!$L$2:$L$800)+(Données!$C$2:$C$800=""))) -> 0 | E11: {=IF(C11=0,"—",MIN(IF((Données!$D$2:$D$800=$A11)*(Données!$E$2:$E$800="CAPEX")*(Données!$L$2:$L$800=$B11)*ISNUMBER(Données!$T$2:$T$800),Données!$T$2:$T$800)))} -> — | F11: {=IF(C11=0,"—",MEDIAN(IF((Données!$D$2:$D$800=$A11)*(Données!$E$2:$E$800="CAPEX")*(Données!$L$2:$L$800=$B11)*ISNUMBER(Données!$T$2:$T$800),Données!$T$2:$T$800)))} -> — | G11: {=IF(C11=0,"—",MAX(IF((Données!$D$2:$D$800=$A11)*(Données!$E$2:$E$800="CAPEX")*(Données!$L$2:$L$800=$B11)*ISNUMBER(Données!$T$2:$T$800),Données!$T$2:$T$800)))} -> — | H11: {=IF(SUMPRODUCT((Données!$D$2:$D$800=$A11)*(Données!$E$2:$E$800="CAPEX")*(Données!$L$2:$L$800=$B11)*ISNUMBER(Données!$S$2:$S$800))=0,"—",MIN(IF((Données!$D$2:$D$800=$A11)*(Données!$E$2:$E$800="CAPEX")*(Données!$L$2:$L$800=$B11)*ISNUMBER(Données!$S$2:$S$800),Données!$S$2:$S$800)))} -> — | I11: {=IF(SUMPRODUCT((Données!$D$2:$D$800=$A11)*(Données!$E$2:$E$800="CAPEX")*(Données!$L$2:$L$800=$B11)*ISNUMBER(Données!$U$2:$U$800))=0,"—",MAX(IF((Données!$D$2:$D$800=$A11)*(Données!$E$2:$E$800="CAPEX")*(Données!$L$2:$L$800=$B11)*ISNUMBER(Données!$U$2:$U$800),Données!$U$2:$U$800)))} -> — | J11: =SUMPRODUCT((Données!$D$2:$D$800=$A11)*(Données!$E$2:$E$800="Rendement (PCI)")*(Données!$L$2:$L$800=$B11)*ISNUMBER(Données!$T$2:$T$800)) -> 0 | K11: =SUMPRODUCT(((Données!$D$2:$D$800=$A11)*(Données!$E$2:$E$800="Rendement (PCI)")*(Données!$L$2:$L$800=$B11)*ISNUMBER(Données!$T$2:$T$800))/(COUNTIFS(Données!$C$2:$C$800,Données!$C$2:$C$800,Données!$D$2:$D$800,Données!$D$2:$D$800,Données!$E$2:$E$800,Données!$E$2:$E$800,Données!$L$2:$L$800,Données!$L$2:$L$800)+(Données!$C$2:$C$800=""))) -> 0 | L11: {=IF(J11=0,"—",MIN(IF((Données!$D$2:$D$800=$A11)*(Données!$E$2:$E$800="Rendement (PCI)")*(Données!$L$2:$L$800=$B11)*ISNUMBER(Données!$T$2:$T$800),Données!$T$2:$T$800)))} -> — | M11: {=IF(J11=0,"—",MEDIAN(IF((Données!$D$2:$D$800=$A11)*(Données!$E$2:$E$800="Rendement (PCI)")*(Données!$L$2:$L$800=$B11)*ISNUMBER(Données!$T$2:$T$800),Données!$T$2:$T$800)))} -> — | N11: {=IF(J11=0,"—",MAX(IF((Données!$D$2:$D$800=$A11)*(Données!$E$2:$E$800="Rendement (PCI)")*(Données!$L$2:$L$800=$B11)*ISNUMBER(Données!$T$2:$T$800),Données!$T$2:$T$800)))} -> —
A12: SOEC | B12: 2030 | C12: =SUMPRODUCT((Données!$D$2:$D$800=$A12)*(Données!$E$2:$E$800="CAPEX")*(Données!$L$2:$L$800=$B12)*ISNUMBER(Données!$T$2:$T$800)) -> 0 | D12: =SUMPRODUCT(((Données!$D$2:$D$800=$A12)*(Données!$E$2:$E$800="CAPEX")*(Données!$L$2:$L$800=$B12)*ISNUMBER(Données!$T$2:$T$800))/(COUNTIFS(Données!$C$2:$C$800,Données!$C$2:$C$800,Données!$D$2:$D$800,Données!$D$2:$D$800,Données!$E$2:$E$800,Données!$E$2:$E$800,Données!$L$2:$L$800,Données!$L$2:$L$800)+(Données!$C$2:$C$800=""))) -> 0 | E12: {=IF(C12=0,"—",MIN(IF((Données!$D$2:$D$800=$A12)*(Données!$E$2:$E$800="CAPEX")*(Données!$L$2:$L$800=$B12)*ISNUMBER(Données!$T$2:$T$800),Données!$T$2:$T$800)))} -> — | F12: {=IF(C12=0,"—",MEDIAN(IF((Données!$D$2:$D$800=$A12)*(Données!$E$2:$E$800="CAPEX")*(Données!$L$2:$L$800=$B12)*ISNUMBER(Données!$T$2:$T$800),Données!$T$2:$T$800)))} -> — | G12: {=IF(C12=0,"—",MAX(IF((Données!$D$2:$D$800=$A12)*(Données!$E$2:$E$800="CAPEX")*(Données!$L$2:$L$800=$B12)*ISNUMBER(Données!$T$2:$T$800),Données!$T$2:$T$800)))} -> — | H12: {=IF(SUMPRODUCT((Données!$D$2:$D$800=$A12)*(Données!$E$2:$E$800="CAPEX")*(Données!$L$2:$L$800=$B12)*ISNUMBER(Données!$S$2:$S$800))=0,"—",MIN(IF((Données!$D$2:$D$800=$A12)*(Données!$E$2:$E$800="CAPEX")*(Données!$L$2:$L$800=$B12)*ISNUMBER(Données!$S$2:$S$800),Données!$S$2:$S$800)))} -> — | I12: {=IF(SUMPRODUCT((Données!$D$2:$D$800=$A12)*(Données!$E$2:$E$800="CAPEX")*(Données!$L$2:$L$800=$B12)*ISNUMBER(Données!$U$2:$U$800))=0,"—",MAX(IF((Données!$D$2:$D$800=$A12)*(Données!$E$2:$E$800="CAPEX")*(Données!$L$2:$L$800=$B12)*ISNUMBER(Données!$U$2:$U$800),Données!$U$2:$U$800)))} -> — | J12: =SUMPRODUCT((Données!$D$2:$D$800=$A12)*(Données!$E$2:$E$800="Rendement (PCI)")*(Données!$L$2:$L$800=$B12)*ISNUMBER(Données!$T$2:$T$800)) -> 0 | K12: =SUMPRODUCT(((Données!$D$2:$D$800=$A12)*(Données!$E$2:$E$800="Rendement (PCI)")*(Données!$L$2:$L$800=$B12)*ISNUMBER(Données!$T$2:$T$800))/(COUNTIFS(Données!$C$2:$C$800,Données!$C$2:$C$800,Données!$D$2:$D$800,Données!$D$2:$D$800,Données!$E$2:$E$800,Données!$E$2:$E$800,Données!$L$2:$L$800,Données!$L$2:$L$800)+(Données!$C$2:$C$800=""))) -> 0 | L12: {=IF(J12=0,"—",MIN(IF((Données!$D$2:$D$800=$A12)*(Données!$E$2:$E$800="Rendement (PCI)")*(Données!$L$2:$L$800=$B12)*ISNUMBER(Données!$T$2:$T$800),Données!$T$2:$T$800)))} -> — | M12: {=IF(J12=0,"—",MEDIAN(IF((Données!$D$2:$D$800=$A12)*(Données!$E$2:$E$800="Rendement (PCI)")*(Données!$L$2:$L$800=$B12)*ISNUMBER(Données!$T$2:$T$800),Données!$T$2:$T$800)))} -> — | N12: {=IF(J12=0,"—",MAX(IF((Données!$D$2:$D$800=$A12)*(Données!$E$2:$E$800="Rendement (PCI)")*(Données!$L$2:$L$800=$B12)*ISNUMBER(Données!$T$2:$T$800),Données!$T$2:$T$800)))} -> —
