Workbook

Sheet Lisez-moi
A1: Base de données – Dessalement de l'eau au Maroc
A2: Projet : Modélisation systémique d'un écosystème énergétique décarboné – Sherpa Engineering × École Centrale Casablanca
A3: Version du 19 octobre 2026. Données collectées dans des documents officiels (ONEE, Ministère de l'Équipement et de l'Eau), un think tank marocain et la presse économique.
A5: Contenu des feuilles
A6: Stations_Dessalement : une ligne par station ou projet (capacité, statut, procédé, énergie, coût, CAPEX, salinité, source, niveau de confiance).
A7: PNAEPI_PolicyCenter : tableaux du programme national (17 + 9 stations) avec totaux recalculés et contrôle.
A8: Parametres_Techno_Eco : paramètres utilisables dans le modèle (kWh/m³, DH/m³, CAPEX, durées PPP, couplage EnR) et liste des données manquantes.
A9: Ecarts_Sources : chiffres nationaux contradictoires selon la date et le périmètre.
A10: Sources : 30 références avec lien.
A12: Légende des couleurs
A13: Bleu = donnée saisie issue d'une source. Noir = formule ou texte. Vert = lien vers une autre feuille. Jaune = donnée à compléter.
A14: Capacité : quand la source donne des m³/j, les Mm³/an sont calculés (×365) ; quand elle donne des Mm³/an, les m³/j sont calculés (÷365).
... A24: 5. Pour la base GWI DesalData (payante) ou des données ONEE plus détaillées, une demande directe à l'ONEE, à la DGIE ou à Sherpa est recommandée.

Sheet Stations_Dessalement
A1: ID | B1: Station / projet | C1: Région / localisation | D1: Type d'eau | E1: Statut | F1: Procédé | G1: Porteur / mode | H1: Année(s) de mise en service | I1: Capacité installée (m³/j) | J1: Capacité (Mm³/an) | K1: Capacité à terme (m³/j) | L1: Eau potable (Mm³/an) | M1: Irrigation (Mm³/an) | N1: Industrie (Mm³/an) | O1: Source d'énergie | P1: Conso. énergie (kWh/m³) | Q1: Coût de l'eau (DH/m³) | R1: CAPEX (MDH) | S1: Capacité de réf. CAPEX (m³/j) | T1: CAPEX (DH par m³/j) | U1: Salinité TDS (g/L) | V1: Sources | W1: Confiance | X1: Notes / écarts
A2: D01 | B2: Laâyoune (ONEE) | C2: Laâyoune-Sakia El Hamra | D2: Mer | E2: En service | F2: Osmose inverse | G2: ONEE – EPC | H2: 1995, 2005, 2010, 2022 | I2: 52000 | J2: =I2*365/1000000 -> 18.98 | L2: 19 | O2: n.d. | P2: 2.64 | Q2: 11 | T2: 14000 | U2: 39 | V2: S2; S3; S1 | W2: Élevée | X2: 26 000 m³/j en 2021, 52 000 m³/j selon l'ONEE (2025). Coût 11 DH/m³ = 6 (investissement) + 5 (exploitation) [2021]. 2,64 kWh/m³ avec récupération d'énergie ; 3,5 kWh/m³ après passage à la prise d'eau directe ; 4,54 sans récupération. CAPEX de 14 000 DH/(m³/j) fourni directement par l'ONEE (cas Laâyoune).
A3: D02 | B3: Laâyoune – Phosboucraa (OCP) | C3: Laâyoune-Sakia El Hamra | D3: Mer | E3: En service | F3: n.d. | G3: OCP | H3: n.d. | I3: =J3*1000000/365 -> 3287.6712 | J3: 1.2 | N3: 1.2 | O3: n.d. | T3: =IF(AND(ISNUMBER(R3),ISNUMBER(S3)),R3*1000000/S3,"") | V3: S2; S1; S17 | W3: Moyenne | X3: Classé 'industrie' par l'ONEE (2021) et 'irrigation' par le Policy Center. Extension de 7,5 Mm³/an prévue pour 2023 (ONEE 2021) ; l'OCP vise 60 Mm³/an sur le site de Laâyoune (EcoActu).
A4: D03 | B4: Boujdour (ONEE) | C4: Laâyoune-Sakia El Hamra | D4: Mer | E4: En service | F4: Osmose inverse | G4: ONEE | H4: 1977, 1995, 2005, 2011, 2016 | I4: 10800 | J4: =I4*365/1000000 -> 3.942 | L4: 3.9 | O4: n.d. | T4: =IF(AND(ISNUMBER(R4),ISNUMBER(S4)),R4*1000000/S4,"") | V4: S2; S1 | W4: Élevée | X4: Policy Center : 3,90 Mm³/an (≈ 10 685 m³/j).
A5: D04 | B5: Tarfaya – eau saumâtre | C5: Laâyoune-Sakia El Hamra | D5: Saumâtre | E5: En service | F5: Osmose inverse (déminéralisation) | G5: ONEE | H5: 1976, 1983, 2001 | I5: 860 | J5: =I5*365/1000000 -> 0.3139 | O5: n.d. | T5: =IF(AND(ISNUMBER(R5),ISNUMBER(S5)),R5*1000000/S5,"") | U5: 3 | V5: S2 | W5: Élevée | X5: TDS ≈ 3 g/L. Policy Center indique 0,16 Mm³/an pour Tarfaya en service (écart).
A6: D05 | B6: Tarfaya – eau de mer (nouvelle) | C6: Laâyoune-Sakia El Hamra | D6: Mer | E6: En construction | F6: Osmose inverse | G6: ONEE | H6: n.d. | I6: 1300 | J6: =I6*365/1000000 -> 0.4745 | L6: 0.47 | O6: n.d. | T6: =IF(AND(ISNUMBER(R6),ISNUMBER(S6)),R6*1000000/S6,"") | V6: S2; S1 | W6: Moyenne | X6: Statut 'travaux en cours' en 2021 – à confirmer. Une extension de 1 300 m³/j supplémentaires est prévue à moyen/long terme (ONEE 2021).
A7: D06 | B7: Tan-Tan – eau saumâtre | C7: Guelmim-Oued Noun | D7: Saumâtre | E7: En service | F7: Osmose inverse | G7: ONEE | H7: 2003, 2014 | I7: 12100 | J7: =I7*365/1000000 -> 4.4165 | O7: Réseau national (1re phase) | T7: =IF(AND(ISNUMBER(R7),ISNUMBER(S7)),R7*1000000/S7,"") | U7: 15–20 | V7: S2 | W7: Élevée | X7: 1re phase : 9 000 m³/j (2014), TDS 15–20 g/L. Consultation en cours (2021) pour +4 320 m³/j.
A8: D07 | B8: Sidi El Ghazi / Roc Chico | C8: Guelmim-Oued Noun | D8: Mer | E8: En service | F8: Osmose inverse | G8: ONEE | H8: 2008, 2009 | I8: 120 | J8: =I8*365/1000000 -> 0.0438 | L8: 0.03 | O8: n.d. | T8: =IF(AND(ISNUMBER(R8),ISNUMBER(S8)),R8*1000000/S8,"") | V8: S2; S1 | W8: Moyenne | X8: Une autre diapositive ONEE indique 90 m³/j (2009).
A9: D08 | B9: Daoura | C9: Drâa-Tafilalet | D9: Saumâtre | E9: En service | F9: Osmose inverse (déminéralisation) | G9: ONEE | H9: 2008 | I9: 240 | J9: =I9*365/1000000 -> 0.0876 | O9: n.d. | T9: =IF(AND(ISNUMBER(R9),ISNUMBER(S9)),R9*1000000/S9,"") | V9: S2 | W9: Élevée
A10: D09 | B10: Tagounite | C10: Drâa-Tafilalet | D10: Saumâtre | E10: En service | F10: Osmose inverse (déminéralisation) | G10: ONEE | H10: 2008 | I10: 430 | J10: =I10*365/1000000 -> 0.15695 | O10: n.d. | T10: =IF(AND(ISNUMBER(R10),ISNUMBER(S10)),R10*1000000/S10,"") | V10: S2 | W10: Moyenne | X10: Une autre diapositive ONEE indique 320 m³/j.
A11: D10 | B11: Akhfennir | C11: Laâyoune-Sakia El Hamra | D11: Mer | E11: En service | F11: Osmose inverse | G11: ONEE | H11: 2011 | I11: 860 | J11: =I11*365/1000000 -> 0.3139 | L11: 0.3 | O11: n.d. | T11: =IF(AND(ISNUMBER(R11),ISNUMBER(S11)),R11*1000000/S11,"") | V11: S2; S1 | W11: Élevée
A12: D11 | B12: Khénifra | C12: Béni Mellal-Khénifra | D12: Saumâtre | E12: En service | F12: Osmose inverse (déminéralisation) | G12: ONEE | H12: 2012 | I12: 27650 | J12: =I12*365/1000000 -> 10.09225 | O12: n.d. | T12: =IF(AND(ISNUMBER(R12),ISNUMBER(S12)),R12*1000000/S12,"") | V12: S2 | W12: Élevée | X12: Une autre diapositive ONEE indique 30 000 m³/j.
A13: D12 | B13: Dakhla – ONEE (forages) 1 | C13: Dakhla-Oued Ed-Dahab | D13: Saumâtre | E13: En service | F13: Osmose inverse | G13: ONEE | H13: 2015 | I13: 17280 | J13: =I13*365/1000000 -> 6.3072 | O13: n.d. | T13: =IF(AND(ISNUMBER(R13),ISNUMBER(S13)),R13*1000000/S13,"") | U13: 2.5 | V13: S2 | W13: Élevée | X13: Nappe fossile : traitement du H₂S, NH₄, Fe avant déminéralisation. Eau brute à ≈ 35 °C. Prise d'eau par forages.
A14: D13 | B14: Dakhla – ONEE (forages) 2 | C14: Dakhla-Oued Ed-Dahab | D14: Saumâtre | E14: En service | F14: Osmose inverse | G14: ONEE | H14: 2018 | I14: 8300 | J14: =I14*365/1000000 -> 3.0295 | O14: n.d. | T14: =IF(AND(ISNUMBER(R14),ISNUMBER(S14)),R14*1000000/S14,"") | U14: 2.5 | V14: S2 | W14: Élevée | X14: Nouvelle station de déminéralisation de 200 L/s (projet de renforcement AEP).
A15: D14 | B15: Zagora | C15: Drâa-Tafilalet | D15: Saumâtre | E15: En service | F15: Osmose inverse (déminéralisation) | G15: ONEE | H15: 2018 | I15: 5200 | J15: =I15*365/1000000 -> 1.898 | O15: n.d. | T15: =IF(AND(ISNUMBER(R15),ISNUMBER(S15)),R15*1000000/S15,"") | U15: 2.5 | V15: S2 | W15: Élevée | X15: Gestion de la saumure par évaporation : 5 bassins, ≈ 90 000 m² (attribution à Zagora probable d'après l'ordre des diapositives).
A16: D15 | B16: Al Hoceima | C16: Tanger-Tétouan-Al Hoceima | D16: Mer | E16: En service | F16: Osmose inverse | G16: ONEE – EPC | H16: 2020 | I16: 17280 | J16: =I16*365/1000000 -> 6.3072 | L16: 6.3 | O16: n.d. | T16: =IF(AND(ISNUMBER(R16),ISNUMBER(S16)),R16*1000000/S16,"") | U16: 36 | V16: S2; S3; S1 | W16: Élevée | X16: Prise d'eau de mer par forages côtiers.
A17: D16 | B17: Khouribga – plateau des phosphates | C17: Béni Mellal-Khénifra | D17: Saumâtre | E17: En service | F17: Osmose inverse (déminéralisation) | G17: ONEE | H17: 2020 | I17: 28500 | J17: =I17*365/1000000 -> 10.4025 | O17: n.d. | T17: =IF(AND(ISNUMBER(R17),ISNUMBER(S17)),R17*1000000/S17,"") | V17: S2 | W17: Élevée
A18: D17 | B18: Chtouka-Aït Baha (Douira, Grand Agadir) | C18: Souss-Massa | D18: Mer | E18: En service | F18: Osmose inverse | G18: PPP (Min. Agriculture / ONEE) – construction Abengoa | H18: 2022 | I18: 275000 | J18: =I18*365/1000000 -> 100.375 | K18: 400000 | L18: 54.75 | M18: 45.63 | O18: n.d. (extension : parc éolien 150 MW prévu) | Q18: 10 | R18: 3000 | S18: 275000 | T18: =IF(AND(ISNUMBER(R18),ISNUMBER(S18)),R18*1000000/S18,"") -> 10909.091 | V18: S10; S11; S12; S13; S9; S3 | W18: Moyenne | X18: Répartition 150 000 m³/j potable / 125 000 m³/j irrigation (converties en Mm³/an). Investissement : 3 000 MDH (2019, usine seule) ; 4 480 MDH (2021, projet complet) ; 4 410 MDH (2024 : 2 350 irrigation + 2 060 AEP). Coût de l'eau 10 DH/m³ (ministère via Le360, 2024) ; 5 DH/m³ promis aux agriculteurs. Extension à 400 000 m³/j (Cox, 250 M€, 2025-2027) avec parc éolien 150 MW ('Energy follows water'). Policy Center : 100,4 Mm³/an répartis 50/50. L'ONEE (2025) parle de 400 000 m³/j à terme et d'une 1re phase 2022.
A19: D18 | B19: Casablanca – Grand Casablanca (Lamharza Essahel, El Jadida) | C19: Casablanca-Settat (prov. El Jadida) | D19: Mer | E19: En construction | F19: Osmose inverse | G19: PPP – Acciona 50 % / Green of Africa 45 % / Afriquia Gaz 5 % | H19: Phase 1 : fin 2026 / févr. 2027 ; phase 2 : mi-2028 | I19: 548000 | J19: =I19*365/1000000 -> 200.02 | K19: 822000 | L19: 250 | M19: 50 | O19: Éolien – parc 360 MW de Bir Anzarane (Green of Africa Dakhla) – 100 % EnR | Q19: 4.48 | R19: 6500 | S19: 822000 | T19: =IF(AND(ISNUMBER(R19),ISNUMBER(S19)),R19*1000000/S19,"") -> 7907.5426 | V19: S3; S5; S6; S7; S8; S9 | W19: Élevée | X19: Phase 1 = 200 Mm³/an ; capacité à terme 300 Mm³/an (250 potable + 50 irrigation – répartition à terme). CAPEX 6 500 MDH pour l'usine (deux tranches) ; investissement privé total 11 000 MDH (S6). Contrat de 27 ans (S8) / 30 ans dont 3 de construction (S29). Réduction d'émissions de CO₂ : 3 200 t/j (ONEE 2025). Policy Center : 300 Mm³ répartis 270 potable / 30 irrigation (écart). Mise en service : fin 2026 (ONEE) ou févr. 2027 (ministre).
A20: D19 | B20: Dakhla – DAWEC (Engie-Nareva) | C20: Dakhla-Oued Ed-Dahab | D20: Mer | E20: En service (à confirmer) | F20: Osmose inverse | G20: PPP – DAWEC (Engie / Nareva), exploitation 20 ans | H20: 2025 | I20: 100000 | J20: =I20*365/1000000 -> 36.5 | L20: 7 | M20: 30 | O20: Éolien – parc dédié 60 MW (100 % EnR) | R20: 2500 | S20: 100000 | T20: =IF(AND(ISNUMBER(R20),ISNUMBER(S20)),R20*1000000/S20,"") -> 25000 | V20: S14; S15; S16; S1; S4 | W20: Moyenne | X20: ≈ 37 Mm³/an (100 000 m³/j = 36,5 Mm³/an). Irrigation de 5 000 ha. Investissement annoncé ≈ 2 000 MDH (S15), réalisé ≈ 2 500 MDH (S14). Parc éolien : 40 MW (S16) puis 60 MW (S14). Policy Center le classe 'en cours' avec répartition 18,5/18,5 Mm³ (données 2023). Hespress (2025) range Dakhla parmi les projets en cours.
A21: D20 | B21: Jorf Lasfar – OCP (existante) | C21: Casablanca-Settat (prov. El Jadida) | D21: Mer | E21: En service | F21: Osmose inverse | G21: OCP / OCP Green Water | H21: n.d. | I21: =J21*1000000/365 -> 109589.04 | J21: 40 | N21: 40 | O21: n.d. (récupération d'énergie : 40–50 % des besoins du procédé) | T21: =IF(AND(ISNUMBER(R21),ISNUMBER(S21)),R21*1000000/S21,"") | V21: S17; S1; S19; S26 | W21: Faible | X21: Valeurs contradictoires : 25 Mm³/an (ONEE 2021, S26) ; 40 Mm³/an (S17, S1) ; 200 Mm³/an pour le site (MAP, juillet 2025, probablement avec extensions). Prix de l'eau fixé par l'OCP : 5,88 DH/m³ (Le360, S9). Autonomie du site en eau non conventionnelle.
A22: D21 | B22: Jorf Lasfar – OCP (extension) | C22: Casablanca-Settat (prov. El Jadida) | D22: Mer | E22: En construction | F22: Osmose inverse | G22: OCP / OCP Green Water | H22: 2026 (plan d'urgence) | I22: =J22*1000000/365 -> 164383.56 | J22: 60 | L22: 45 | N22: 15 | O22: n.d. | T22: =IF(AND(ISNUMBER(R22),ISNUMBER(S22)),R22*1000000/S22,"") | V22: S1; S18; S20 | W22: Moyenne | X22: Plan d'urgence OCP-Etat : 85 Mm³/an (2023-2025) puis 110 Mm³/an dès 2026 (75 potable pour les régies de Safi et El Jadida + 35 industriel) via 4 unités (2 à Jorf Lasfar, 2 à Safi). BERD : prêt de 200 M€ pour 2 usines (≈ 35 Mm³).
A23: D22 | B23: Safi – OCP (existante) | C23: Marrakech-Safi | D23: Mer | E23: En service | F23: Osmose inverse | G23: OCP | H23: n.d. | I23: =J23*1000000/365 -> 21917.808 | J23: 8 | N23: 8 | O23: n.d. | T23: =IF(AND(ISNUMBER(R23),ISNUMBER(S23)),R23*1000000/S23,"") | V23: S1 | W23: Moyenne
A24: D23 | B24: Safi – OCP (extension) | C24: Marrakech-Safi | D24: Mer | E24: En construction | F24: Osmose inverse | G24: OCP / OCP Green Water | H24: 2026 (plan d'urgence) | I24: =J24*1000000/365 -> 115068.49 | J24: 42 | L24: 30 | N24: 12 | O24: n.d. | T24: =IF(AND(ISNUMBER(R24),ISNUMBER(S24)),R24*1000000/S24,"") | V24: S1; S18 | W24: Moyenne | X24: Voir D21 pour le plan d'urgence. ONEE 2021 mentionnait aussi un projet de 26 000 m³/j à Safi.
A25: D24 | B25: El Mhirriz | C25: n.d. | D25: Mer | E25: En service | F25: n.d. | G25: n.d. | H25: n.d. | I25: =J25*1000000/365 -> 27.39726 | J25: 0.01 | L25: 0.01 | O25: n.d. | T25: =IF(AND(ISNUMBER(R25),ISNUMBER(S25)),R25*1000000/S25,"") | V25: S1 | W25: Moyenne | X25: Village de pêche.
A26: D25 | B26: Amegrew | C26: n.d. | D26: Mer | E26: En construction | F26: n.d. | G26: n.d. | H26: n.d. | I26: =J26*1000000/365 -> 438.35616 | J26: 0.16 | L26: 0.16 | O26: n.d. | T26: =IF(AND(ISNUMBER(R26),ISNUMBER(S26)),R26*1000000/S26,"") | V26: S1 | W26: Moyenne | X26: Village de pêche.
A27: D26 | B27: Sidi Ifni | C27: Guelmim-Oued Noun | D27: Mer | E27: En construction | F27: Osmose inverse | G27: ONEE | H27: n.d. | I27: 8640 | J27: =I27*365/1000000 -> 3.1536 | L27: 3.15 | O27: n.d. | T27: =IF(AND(ISNUMBER(R27),ISNUMBER(S27)),R27*1000000/S27,"") | V27: S2; S1; S29 | W27: Moyenne | X27: FNH annonce 15 Mm³/an (écart avec 3,15 Mm³/an). Extension de 8 600 m³/j prévue (ONEE 2021). Le programme 'Tiznit – Sidi Ifni' (154,6 Mm³) est une autre station (D30).
A28: D27 | B28: Nador (programmée) | C28: Oriental | D28: Mer | E28: Programmée | F28: Osmose inverse | G28: PPP (envisagé) | H28: 2026 / 2035 | I28: =J28*1000000/365 -> 684931.51 | J28: 250 | L28: 140 | M28: 110 | O28: n.d. | T28: =IF(AND(ISNUMBER(R28),ISNUMBER(S28)),R28*1000000/S28,"") | V28: S1; S25 | W28: Faible | X28: Policy Center : 250 Mm³/an ; Le360 : 100 Mm³/an extensibles à 200 Mm³/an.
A29: D28 | B29: Essaouira (programmée) | C29: Marrakech-Safi | D29: Mer | E29: Programmée | F29: Osmose inverse | G29: ONEE | H29: 2027 / 2035 | I29: =J29*1000000/365 -> 117260.27 | J29: 42.8 | L29: 12.8 | M29: 30 | O29: n.d. | T29: =IF(AND(ISNUMBER(R29),ISNUMBER(S29)),R29*1000000/S29,"") | V29: S1; S27 | W29: Moyenne | X29: Études lancées par l'ONEE (23 MDH d'études).
A30: D29 | B30: Agadir – extension (programmée) | C30: Souss-Massa | D30: Mer | E30: Programmée | F30: Osmose inverse | G30: n.d. | H30: 2028 | I30: =J30*1000000/365 -> 124931.51 | J30: 45.6 | L30: 18.3 | M30: 27.3 | O30: n.d. | T30: =IF(AND(ISNUMBER(R30),ISNUMBER(S30)),R30*1000000/S30,"") | V30: S1 | W30: Moyenne | X30: À rapprocher de l'extension Cox de Chtouka (D17) : possible recouvrement.
A31: D30 | B31: Tiznit – Sidi Ifni (Aglou, programmée) | C31: Souss-Massa / Guelmim-Oued Noun | D31: Mer | E31: Programmée | F31: Osmose inverse | G31: ONEE | H31: 2028 / 2030 / 2035 | I31: =J31*1000000/365 -> 423561.64 | J31: 154.6 | L31: 114.6 | M31: 40 | O31: n.d. | R31: 2700 | T31: =IF(AND(ISNUMBER(R31),ISNUMBER(S31)),R31*1000000/S31,"") | V31: S1; S30 | W31: Moyenne | X31: Coût global de 2 700 MDH cité pour la station d'Aglou (Tiznit) – périmètre non précisé, donc CAPEX non rattaché à une capacité.
A32: D31 | B32: Guelmim (programmée) | C32: Guelmim-Oued Noun | D32: Mer | E32: Programmée | F32: Osmose inverse | G32: ONEE | H32: 2027 / 2030 / 2035 | I32: =J32*1000000/365 -> 94794.521 | J32: 34.6 | L32: 14.6 | M32: 20 | O32: n.d. | T32: =IF(AND(ISNUMBER(R32),ISNUMBER(S32)),R32*1000000/S32,"") | V32: S1; S27 | W32: Moyenne
A33: D32 | B33: Tan-Tan – mer (programmée) | C33: Guelmim-Oued Noun | D33: Mer | E33: Programmée | F33: Osmose inverse | G33: n.d. | H33: 2027 – 2040 | I33: =J33*1000000/365 -> 129315.07 | J33: 47.2 | L33: 3.2 | M33: 35 | N33: 9 | O33: n.d. | T33: =IF(AND(ISNUMBER(R33),ISNUMBER(S33)),R33*1000000/S33,"") | V33: S1 | W33: Moyenne | X33: Inclut 9 Mm³/an pour l'hydrogène vert : lien direct avec le projet.
A34: D33 | B34: Boujdour (programmée) | C34: Laâyoune-Sakia El Hamra | D34: Mer | E34: Programmée | F34: Osmose inverse | G34: n.d. | H34: 2030 / 2035 | I34: =J34*1000000/365 -> 164383.56 | J34: 60 | M34: 60 | O34: n.d. | T34: =IF(AND(ISNUMBER(R34),ISNUMBER(S34)),R34*1000000/S34,"") | V34: S1 | W34: Moyenne
B36: Total – eau de mer, en service (Mm³/an) | J36: =SUMIFS(J2:J34,D2:D34,"Mer",E2:E34,"En service") -> 179.1719
B37: Total – eau saumâtre, en service (Mm³/an) | J37: =SUMIFS(J2:J34,D2:D34,"Saumâtre",E2:E34,"En service") -> 36.7044
B38: Total – eau de mer, en construction (Mm³/an) | J38: =SUMIFS(J2:J34,D2:D34,"Mer",E2:E34,"En construction") -> 305.8081
B39: Total – programmées (Mm³/an) | J39: =SUMIFS(J2:J34,E2:E34,"Programmée") -> 634.8
B40: Note : ces totaux n'incluent que les stations de cette feuille (non exhaustif) et ne sont pas comparables aux chiffres nationaux officiels – voir feuille Ecarts_Sources.

Sheet PNAEPI_PolicyCenter
A1: Programme national – capacités de dessalement (Policy Center, mai 2025, données 2023 du Min. Équipement et Eau) – source S1
A3: Tableau 1 – 17 stations en service ou en cours de réalisation
A4: Station / localisation | B4: Statut | C4: Capacité (Mm³) | D4: Eau potable (Mm³) | E4: Irrigation (Mm³) | F4: Industrie (Mm³) | G4: Contrôle (cap. – somme usages)
A5: Al Hoceima | B5: En service | C5: 6.3 | D5: 6.3 | E5: 0 | F5: 0 | G5: =ROUND(C5-D5-E5-F5,2) -> 0
A6: Jorf Lasfar | B6: En service | C6: 40 | D6: 0 | E6: 0 | F6: 40 | G6: =ROUND(C6-D6-E6-F6,2) -> 0
A7: Jorf Lasfar | B7: En cours | C7: 60 | D7: 45 | E7: 0 | F7: 15 | G7: =ROUND(C7-D7-E7-F7,2) -> 0
A8: Safi | B8: En service | C8: 8 | D8: 0 | E8: 0 | F8: 8 | G8: =ROUND(C8-D8-E8-F8,2) -> 0
A9: Safi | B9: En cours | C9: 42 | D9: 30 | E9: 0 | F9: 12 | G9: =ROUND(C9-D9-E9-F9,2) -> 0
A10: Agadir | B10: En service | C10: 100.4 | D10: 50.2 | E10: 50.2 | F10: 0 | G10: =ROUND(C10-D10-E10-F10,2) -> 0
A11: Sidi Ifni | B11: En cours | C11: 3.15 | D11: 3.15 | E11: 0 | F11: 0 | G11: =ROUND(C11-D11-E11-F11,2) -> 0
A12: Akhfennir | B12: En service | C12: 0.3 | D12: 0.3 | E12: 0 | F12: 0 | G12: =ROUND(C12-D12-E12-F12,2) -> 0
A13: Tarfaya | B13: En service | C13: 0.16 | D13: 0.16 | E13: 0 | F13: 0 | G13: =ROUND(C13-D13-E13-F13,2) -> 0
A14: Tarfaya | B14: En cours | C14: 0.47 | D14: 0.47 | E14: 0 | F14: 0 | G14: =ROUND(C14-D14-E14-F14,2) -> 0
A15: Amegrew | B15: En cours | C15: 0.16 | D15: 0.16 | E15: 0 | F15: 0 | G15: =ROUND(C15-D15-E15-F15,2) -> 0
A16: Laâyoune | B16: En service | C16: 20.2 | D16: 19 | E16: 1.2 | F16: 0 | G16: =ROUND(C16-D16-E16-F16,2) -> 0
... A21: El Mhirriz | B21: En service | C21: 0.01 | D21: 0.01 | E21: 0 | F21: 0 | G21: =ROUND(C21-D21-E21-F21,2) -> 0
A22: Total calculé | C22: =SUM(C5:C21) -> 322.11 | D22: =SUM(D5:D21) -> 177.21 | E22: =SUM(E5:E21) -> 69.9 | F22: =SUM(F5:F21) -> 75
A23: Total publié (S1) | C23: 322.11 | D23: 177.21 | E23: 69.9 | F23: 75
A24: Écart (calculé – publié) | C24: =ROUND(C22-C23,2) -> 0 | D24: =ROUND(D22-D23,2) -> 0 | E24: =ROUND(E22-E23,2) -> 0 | F24: =ROUND(F22-F23,2) -> 0
A26: Tableau 2 – 9 stations programmées (horizon 2026–2040)
A27: Région / ville | B27: Mise en service | C27: Capacité (Mm³) | D27: Eau potable (Mm³) | E27: Irrigation (Mm³) | F27: Industrie – H₂ vert (Mm³) | G27: Contrôle (cap. – somme usages)
A28: Nador | B28: 2026 / 2035 | C28: 250 | D28: 140 | E28: 110 | F28: 0 | G28: =ROUND(C28-D28-E28-F28,2) -> 0
A29: Casablanca | B29: 2026 / 2030 | C29: 300 | D29: 270 | E29: 30 | F29: 0 | G29: =ROUND(C29-D29-E29-F29,2) -> 0
A30: Essaouira | B30: 2027 / 2035 | C30: 42.8 | D30: 12.8 | E30: 30 | F30: 0 | G30: =ROUND(C30-D30-E30-F30,2) -> 0
A31: Agadir | B31: 2028 | C31: 45.6 | D31: 18.3 | E31: 27.3 | F31: 0 | G31: =ROUND(C31-D31-E31-F31,2) -> 0
A32: Tiznit – Sidi Ifni | B32: 2028 / 2030 / 2035 | C32: 154.6 | D32: 114.6 | E32: 40 | F32: 0 | G32: =ROUND(C32-D32-E32-F32,2) -> 0
A33: Guelmim | B33: 2027 / 2030 / 2035 | C33: 34.6 | D33: 14.6 | E33: 20 | F33: 0 | G33: =ROUND(C33-D33-E33-F33,2) -> 0
A34: Tan-Tan | B34: 2027 / 2030 / 2035 / 2040 | C34: 47.2 | D34: 3.2 | E34: 35 | F34: 9 | G34: =ROUND(C34-D34-E34-F34,2) -> 0
A35: Boujdour | B35: 2030 / 2035 | C35: 60 | D35: 0 | E35: 60 | F35: 0 | G35: =ROUND(C35-D35-E35-F35,2) -> 0
A36: Tarfaya | B36: 2027 / 2030 / 2035 | C36: 0.47 | D36: 0.47 | E36: 0 | F36: 0 | G36: =ROUND(C36-D36-E36-F36,2) -> 0
A37: Total calculé | C37: =SUM(C28:C36) -> 935.27 | D37: =SUM(D28:D36) -> 573.97 | E37: =SUM(E28:E36) -> 352.3 | F37: =SUM(F28:F36) -> 9
A38: Total publié (S1, tableau 4) | C38: 935.27 | D38: 573.97 | E38: 352.3 | F38: 9
A39: Écart (calculé – publié) | C39: =ROUND(C37-C38,2) -> 0 | D39: =ROUND(D37-D38,2) -> 0 | E39: =ROUND(E37-E38,2) -> 0 | F39: =ROUND(F37-F38,2) -> 0
A41: Total général 26 stations (calculé) | C41: =C22+C37 -> 1257.38 | D41: =D22+D37 -> 751.18 | E41: =E22+E37 -> 422.2 | F41: =F22+F37 -> 84
A42: Remarques : (1) le texte de S1 donne tantôt 935,74 / 1 257,85 Mm³, tantôt 935,27 / 1 257,38 Mm³ ; la somme des lignes (935,27) confirme la seconde version. (2) Le tableau 3 de S1 publie 452,20 Mm³ d'irrigation et 751,65 Mm³ d'eau potable pour l'ensemble : c'est incohérent avec les lignes (69,90 + 352,30 = 422,20 ; 177,21 + 573,97 = 751,18). Les totaux calculés ci-dessus sont à utiliser.

Sheet Parametres_Techno_Eco
A1: Paramètres technico-économiques du dessalement au Maroc (pour le modèle systémique)
A3: Paramètre | B3: Valeur | C3: Unité | D3: Contexte / site | E3: Année | F3: Source(s) | G3: Confiance | H3: Remarque
A4: Procédé dominant | B4: Osmose inverse (SWRO) | C4: – | D4: Toutes les stations d'eau de mer existantes et en construction | E4: 2024-2025 | F4: S23; S2 | G4: Élevée | H4: Choix ONEE : coût compétitif, faible consommation spécifique, adaptée au mix énergétique marocain. Technologie 'éprouvée'.
A5: Consommation électrique spécifique – avec récupération d'énergie | B5: 2.64 | C5: kWh/m³ | D5: Laâyoune (ONEE) | E5: 2021 | F5: S2 | G5: Élevée | H5: Avec membranes basse énergie, échangeurs de pression, démarreurs à variateur MT.
A6: Consommation électrique – après prise d'eau directe | B6: 3.5 | C6: kWh/m³ | D6: Laâyoune (ONEE) | E6: 2021 | F6: S2 | G6: Élevée | H6: Augmentation due au pompage de la prise directe.
A7: Consommation électrique – sans récupération d'énergie | B7: 4.54 | C7: kWh/m³ | D7: Laâyoune (ONEE) | E7: 2021 | F7: S2 | G7: Élevée | H7: Gain de 1,9 kWh/m³ grâce à la récupération d'énergie.
A8: Plage de consommation citée par l'ONEE | B8: 3 à 5 | C8: kWh/m³ | D8: National | E8: 2025 | F8: S3 | G8: Élevée | H8: L'énergie représente jusqu'à 50 % des coûts totaux.
A9: Plage citée par un expert | B9: 3 à 3,5 | C9: kWh/m³ | D9: Technologie actuelle | E9: n.d. | F9: S24 | G9: Moyenne
A10: Part de l'énergie récupérée par ERD (OCP) | B10: 40 à 50 | C10: % des besoins énergétiques | D10: Jorf Lasfar (OCP) | E10: 2025 | F10: S19 | G10: Moyenne
A11: Part de l'énergie dans le coût total | B11: jusqu'à 50 | C11: % | D11: National | E11: 2025 | F11: S3 | G11: Moyenne
A12: Coût de l'eau dessalée – national (ordre de grandeur) | B12: 10 | C12: DH/m³ | D12: Stations existantes (petites) | E12: n.d. | F12: S28 | G12: Moyenne | H12: Dépend de la salinité, de la taille de la station et du coût de l'énergie.
A13: Fourchette de coût de production | B13: 5 à 12 | C13: DH/m³ | D13: National | E13: 2025 | F13: S3 | G13: Élevée
A14: Coût de l'eau – Laâyoune | B14: 11 | C14: DH/m³ | D14: Laâyoune | E14: 2021 | F14: S2 | G14: Élevée | H14: 6 DH investissement + 5 DH exploitation.
A15: Coût de l'eau – Agadir (Chtouka) | B15: 10 | C15: DH/m³ | D15: Chtouka-Aït Baha | E15: 2024 | F15: S9 | G15: Moyenne | H15: Chiffre ministère cité par la presse.
A16: Prix de l'eau dessalée fixé par l'OCP | B16: 5.88 | C16: DH/m³ | D16: OCP | E16: 2024 | F16: S9 | G16: Moyenne
A17: Coût de l'eau – Casablanca (prix PPP) | B17: 4.48 | C17: DH/m³ | D17: Casablanca | E17: 2024 | F17: S7; S9 | G17: Élevée | H17: Prix moyen inférieur à 4,50 DH/m³, 100 % renouvelable.
A18: Coût international (grandes usines → petites) | B18: 0,5 à 1,25 | C18: USD/m³ | D18: International | E18: n.d. | F18: S24 | G18: Moyenne
A19: CAPEX – Laâyoune | B19: 14000 | C19: DH par m³/j | D19: Laâyoune | E19: 2021 | F19: S2 | G19: Élevée
A20: CAPEX – référence internationale | B20: 1300 à 1400 | C20: USD par m³/j | D20: International (GWI DesalData, août 2020) | E20: 2020 | F20: S2 | G20: Moyenne
A21: CAPEX – Casablanca (calcul) | B21: =Stations_Dessalement!T19 -> 7907.5426 | C21: DH par m³/j | D21: Casablanca (6 500 MDH / capacité à terme) | E21: 2024 | F21: S5; S6 | G21: Moyenne | H21: Calcul à partir de la feuille Stations.
A22: CAPEX – Chtouka (calcul, usine seule) | B22: =Stations_Dessalement!T18 -> 10909.091 | C22: DH par m³/j | D22: Chtouka (3 000 MDH / 275 000 m³/j) | E22: 2019 | F22: S12 | G22: Moyenne
A23: CAPEX – Dakhla (calcul) | B23: =Stations_Dessalement!T20 -> 25000 | C23: DH par m³/j | D23: Dakhla (2 500 MDH / 100 000 m³/j) | E23: 2025 | F23: S14 | G23: Moyenne | H23: Inclut le parc éolien dédié 60 MW (périmètre PPP complet).
A24: Durée du contrat PPP – Casablanca | B24: 27 | C24: ans | D24: Casablanca | E24: 2024 | F24: S8 | G24: Élevée | H24: 30 ans dont 3 ans de construction selon S29.
A25: Durée d'exploitation PPP – Dakhla | B25: 20 | C25: ans | D25: Dakhla | E25: n.d. | F25: S15 | G25: Élevée
A26: Salinité de l'eau de mer | B26: 36 à 39 | C26: g/L | D26: Al Hoceima 36 ; Laâyoune 39 | E26: 2021 | F26: S2 | G26: Élevée
A27: Salinité des eaux saumâtres | B27: 2,5 à 20 | C27: g/L | D27: Dakhla/Zagora 2,5 ; Tarfaya 3 ; Tan-Tan 15–20 | E27: 2021 | F27: S2 | G27: Élevée
A28: Réduction d'émissions de CO₂ (Casablanca, vs alimentation fossile) | B28: 3200 | C28: t CO₂/jour | D28: Casablanca | E28: 2025 | F28: S3 | G28: Faible | H28: Valeur ONEE non recoupée – base de calcul non précisée.
A29: Part du dessalement dans le mix d'eau potable ONEE | B29: 5 | C29: % | D29: Fin 2024 | E29: 2024 | F29: S3 | G29: Élevée | H29: Cible : 63 % des besoins en eau potable en 2030 (13 % en 2025), 65 % en 2035.
A30: Objectif de capacité de dessalement d'eau potable | B30: 1.3 | C30: milliard m³/an | D30: 2030 | E30: 2025 | F30: S3 | G30: Élevée | H30: 1,0 à 1,4 milliard selon les sources (S22, S23, S26).
A31: Capacité du dessalement mobile (programme) | B31: 1563 | C31: L/s | D31: 244 stations (89 livrées au 31/07/2025) | E31: 2025 | F31: S4 | G31: Moyenne | H31: Unités de 360 à 3 600 m³/j (S1).
A33: Couplage énergies renouvelables – dessalement (ratios calculés)
A34: Site | B34: Puissance EnR dédiée (MW) | C34: Capacité de dessalement (m³/j) | D34: MW par 1 000 m³/j | E34: Source d'énergie | F34: Source(s) | G34: Confiance | H34: Remarque
A35: Dakhla (DAWEC) | B35: 60 | C35: =Stations_Dessalement!I20 -> 100000 | D35: =B35/(C35/1000) -> 0.6 | E35: Éolien | F35: S14 | G35: Moyenne | H35: Parc éolien dédié 100 % EnR.
A36: Casablanca (phase 2) | B36: 360 | C36: =Stations_Dessalement!K19 -> 822000 | D36: =B36/(C36/1000) -> 0.4379562 | E36: Éolien (Bir Anzarane) | F36: S5 | G36: Élevée | H36: Capacité à terme ; 100 % EnR via parc déporté.
A37: Chtouka – extension (Cox) | B37: 150 | C37: =Stations_Dessalement!K18 -> 400000 | D37: =B37/(C37/1000) -> 0.375 | E37: Éolien | F37: S13 | G37: Moyenne | H37: Capacité à terme (400 000 m³/j) ; le parc vise à couvrir l'alimentation énergétique.
A39: Données demandées par Sherpa NON trouvées dans les sources marocaines (à compléter par la littérature)
A40: Donnée manquante | B40: Pistes pour la compléter
A41: Durée de vie technique (membranes, pompes, usine) | B41: Littérature scientifique, IDA, rapports Banque mondiale 2019 – seules des durées de contrat PPP (20–30 ans) ont été trouvées
A42: Taux de récupération (recovery) et prélèvement d'eau de mer par m³ produit | B42: Fiches techniques des PPP (Acciona, Abengoa, Cox) ; littérature
A43: OPEX détaillé (énergie, produits chimiques, membranes, personnel) | B43: Seule la répartition globale de Laâyoune (6 DH invest. / 5 DH exploit.) est disponible
...

Sheet Ecarts_Sources
A1: Chiffres nationaux et écarts entre sources (à ne pas mélanger sans préciser la date et le périmètre)
A3: Indicateur | B3: Valeur | C3: Unité | D3: Date | E3: Source | F3: Explication probable
A4: Stations d'eau de mer en service – ministre | B4: 9 | C4: stations | D4: 31 oct. 2022 | E4: S21 | F4: Périmètre : stations d'eau de mer uniquement.
A5: Capacité correspondante | B5: 147 | C5: Mm³/an | D5: 31 oct. 2022 | E5: S21
A6: Stations d'eau de mer existantes – ministre | B6: 12 | C6: stations | D6: n.d. (≈ 2023) | E6: S22 | F6: Plus récent que 9 stations.
A7: Capacité correspondante (eau de mer) | B7: 179 | C7: Mm³/an | D7: n.d. (≈ 2023) | E7: S22 | F7: S'y ajoutent ≈ 37 Mm³/an d'eaux saumâtres.
A8: Capacité des 12 stations – CESE | B8: 179.3 | C8: Mm³/an | D8: juin 2024 | E8: S23 | F8: Environ 20 stations prévues d'ici 2030 ; 1,4 milliard de m³ visés.
A9: Stations d'eau de mer exploitées – DGIE | B9: 17 | C9: stations | D9: 2025 | E9: S4 | F9: Inclut probablement les unités OCP et les extensions.
A10: Capacité correspondante – DGIE | B10: 320 | C10: Mm³/an | D10: 2025 | E10: S4 | F10: 13 projets côtiers programmés ; 244 unités mobiles en acquisition.
A11: Stations de dessalement à fin 2024 – ONEE | B11: 12 | C11: stations | D11: 4 déc. 2025 | E11: S3 | F11: Périmètre ONEE.
A12: Capacité visée en 2030 (eau potable) | B12: 1300 | C12: Mm³/an | D12: 4 déc. 2025 | E12: S3 | F12: 63 % des besoins en eau potable en 2030 contre 13 % en 2025.
A13: Stations du PNAEPI (en service + en cours + programmées) | B13: 26 | C13: stations | D13: 2025 (données 2023) | E13: S1 | F13: Voir feuille PNAEPI_PolicyCenter.
A14: Capacité des 26 stations (somme des lignes) | B14: =PNAEPI_PolicyCenter!C41 -> 1257.38 | C14: Mm³/an | D14: 2025 (données 2023) | E14: S1 | F14: Recalculé ; le texte source donne 1 257,38 ou 1 257,85.
A15: Jorf Lasfar OCP – ONEE 2021 / FNH | B15: 25 | C15: Mm³/an | D15: 2021 / 2025 | E15: S2; S26 | F15: Capacité avant extension.
A16: Jorf Lasfar OCP – EcoActu / Policy Center | B16: 40 | C16: Mm³/an | D16: 2023-2025 | E16: S17; S1 | F16: Après extension.
A17: Jorf Lasfar OCP – MAP juillet 2025 | B17: 200 | C17: Mm³/an | D17: 16 juil. 2025 | E17: S19 | F17: Probablement capacité totale du site avec unités en construction ; à vérifier auprès de l'OCP.
A18: Parc ONEE – capacité installée toutes eaux | B18: 160000 | C18: m³/j | D18: 3 juin 2021 | E18: S2 | F18: Dont ≈ 55 000 m³/j de dessalement (eau de mer) ; le reste = déminéralisation d'eaux saumâtres.
A19: Parc ONEE – somme des lignes (feuille Stations, ONEE) | B19: =SUMIFS(Stations_Dessalement!I2:I34,Stations_Dessalement!G2:G34,"ONEE*",Stations_Dessalement!E2:E34,"En service") -> 181620 | C19: m³/j | D19: calcul | E19: S2 | F19: Somme des stations ONEE en service de la feuille Stations (Laâyoune compté à 52 000 m³/j, chiffre 2025). L'écart avec 160 000 m³/j (2021) vient de cette mise à jour et des stations non reprises.

Sheet Sources
A1: ID | B1: Titre | C1: Organisme / média | D1: Date | E1: URL | F1: Nature
A2: S1 | B2: Désalinisation, barrages et autoroutes de l'eau (Policy Paper 19/25), H.-L. Védie | C2: Policy Center for the New South (données 2023 du Min. Équipement et Eau) | D2: Mai 2025 | E2: https://www.policycenter.ma/sites/default/files/2025-05/PP_19-25%20%28Vedie%29.pdf | F2: Think tank / données ministère
A3: S2 | B3: Expérience de l'ONEE en matière de dessalement d'eau, M. Kharif | C3: ONEE – Direction technique et ingénierie | D3: 3 juin 2021 | E3: https://remoc.org/events/20210603-ime-webinar/Desalination_Morocco_ONEE.pdf | F3: Officiel (ONEE)
A4: S3 | B4: Situation actuelle du dessalement au Maroc, perspectives et défis, F. Essannouni | C4: ONEE – Branche Eau, Direction Planification | D4: 4 déc. 2025 | E4: https://www.eia.nl/fr/wp-content/uploads/sites/2/2026/01/1-Mme.-Fedwa-Essannouni-Dessalement-au-Maroc.pdf | F4: Officiel (ONEE)
A5: S4 | B5: Dakhla, Casablanca, El Jadida… le Maroc accélère ses projets de dessalement (données DGIE) | C5: Hespress | D5: 2025 | E5: https://fr.hespress.com/437711-dakhla-casablanca-el-jadida-le-maroc-accelere-ses-projets-de-dessalement.html | F5: Presse (données ministère)
A6: S5 | B6: Station de dessalement du Grand Casablanca : le financement bouclé | C6: Aujourd'hui le Maroc | D6: n.d. | E6: https://aujourdhui.ma/actualite/station-de-dessalement-du-grand-casablanca-le-financement-boucle | F6: Presse
A7: S6 | B7: Ce qu'il y a à savoir sur le projet de dessalement de Casablanca | C7: Médias24 | D7: 10 juin 2024 | E7: https://medias24.com/2024/06/10/ce-quil-y-a-a-savoir-sur-le-projet-de-dessalement-de-casablanca/ | F7: Presse
A8: S7 | B8: Moulay El Hassan lance la construction de la station de dessalement de Casablanca | C8: Le Desk | D8: juin 2024 | E8: https://ledesk.ma/encontinu/moulay-el-hassan-lance-la-construction-de-la-station-de-dessalement-de-casablanca/ | F8: Presse
A9: S8 | B9: Morocco tackling severe water scarcity with innovative solutions | C9: Société Générale | D9: n.d. | E9: https://wholesale.banking.societegenerale.com/en/news-insights/clients-successes/clients-successes-details/news/morocco-tackling-severe-water-scarcity-with-innovative-solutions/ | F9: Financeur
A10: S9 | B10: Station de dessalement de Casablanca : le premier coup de pioche | C10: Le360 | D10: 22 janv. 2024 | E10: https://fr.le360.ma/societe/station-de-dessalement-de-casablanca-le-premier-coup-de-pioche-ce-mardi-23-janvier_CPAGPOJTDZG4BGFOYO74QQYDVQ/ | F10: Presse
A11: S10 | B11: Station de dessalement Chtouka-Aït Baha : 275.000 m3 d'eau/jour | C11: Hespress | D11: 1 sept. 2024 | E11: https://fr.hespress.com/384157-384157.html | F11: Presse
A12: S11 | B12: La station de dessalement de Chtouka mise en exploitation début 2022 | C12: Aujourd'hui le Maroc | D12: 2021 | E12: https://aujourdhui.ma/?p=391128 | F12: Presse
... A31: S30 | B31: Station de dessalement Chtouka-Aït Baha (Aglou/Tiznit : 2,7 Md DH) | C31: EcoActu | D31: n.d. | E31: https://ecoactu.ma/?p=227209 | F31: Presse
